<?xml version="1.0" ?>
<!-- =================================================================================== -->
<!-- |    This document was autogenerated by xacro from multi_summit.xacro             | -->
<!-- |    EDITING THIS FILE BY HAND IS NOT RECOMMENDED                                 | -->
<!-- =================================================================================== -->
<robot name="multi_robot">
  <link name="world_frame"/>
  <joint name="world_joint_1" type="planar">
    <origin rpy="0 0 0" xyz="0 0 0"/>
    <parent link="world_frame"/>
    <child link="robot_1_base_footprint"/>
  </joint>
  <joint name="world_joint_2" type="planar">
    <origin rpy="0 0 0" xyz="2 0 0"/>
    <parent link="world_frame"/>
    <child link="robot_2_base_footprint"/>
  </joint>
  <joint name="world_joint_3" type="planar">
    <origin rpy="0 0 0" xyz="-2 0 0"/>
    <parent link="world_frame"/>
    <child link="robot_3_base_footprint"/>
  </joint>
  <gazebo reference="base_footprint">
    <material>Gazebo/Green</material>
  </gazebo>
  <!-- in kg 6.5 -->
  <!-- in kg-->
  <!-- Import all available sensors -->
  <!-- <xacro:include filename="$(find robotnik_sensors)/urdf/all_sensors.urdf.xacro" /> -->
  <!-- Flag to select the high or low quality model -->
  <!-- *************** -->
  <!-- Robots Elements -->
  <!-- *************** -->
  <!-- Here we create the robot elements using the xacro:macros imported at the beggining of this file -->
  <link name="robot_1_base_footprint">
    <visual>
      <origin rpy="0 0 0" xyz="0 0 0"/>
      <geometry>
        <box size="0.001 0.001 0.001"/>
      </geometry>
    </visual>
  </link>
  <joint name="robot_1_base_footprint_joint" type="fixed">
    <origin rpy="0 0 0" xyz="0 0 0.127"/>
    <!-- ${wheel_radius} property must be defined inside wheel description -->
    <parent link="robot_1_base_footprint"/>
    <child link="robot_1_base_link"/>
  </joint>
  <!-- BASE_LINK -->
  <link name="robot_1_base_link">
    <inertial>
      <mass value="125.0"/>
      <!-- origin : 125.0 -->
      <origin xyz="0 0 0"/>
      <inertia ixx="1.391" ixy="0.004" ixz="0.0" iyy="6.853" iyz="0.0" izz="6.125"/>
    </inertial>
    <visual>
      <origin rpy="0 0 0" xyz="0 0 0"/>
      <geometry>
        <mesh filename="package://summit_xl_description/meshes/bases/xls/summit_xls_chassis.stl"/>
      </geometry>
      <material name="black">
        <color rgba="0.0 0.0 0.0 1"/>
      </material>
    </visual>
    <collision>
      <origin rpy="0 0 0 " xyz="0 0 0"/>
      <geometry>
        <mesh filename="package://summit_xl_description/meshes/bases/xls/summit_xls_chassis.dae"/>
      </geometry>
    </collision>
  </link>
  <gazebo reference="robot_1_base_link">
    <material>Gazebo/Black</material>
  </gazebo>
  <!-- CHAPAS INOX TAPAS -->
  <link name="robot_1_base_chapa">
    <visual>
      <origin rpy="0 0 0" xyz="0 0 0"/>
      <geometry>
        <mesh filename="package://summit_xl_description/meshes/bases/xls/summit_xls_chapas_inox_tapas.stl"/>
      </geometry>
      <material name="darkgrey">
        <color rgba="0.5 0.5 0.5 1"/>
      </material>
    </visual>
  </link>
  <joint name="robot_1_base_tapa_joint" type="fixed">
    <origin rpy="0 0 0" xyz="0.0 0 0.38062"/>
    <parent link="robot_1_base_link"/>
    <child link="robot_1_base_chapa"/>
  </joint>
  <!-- LOGO ROBOTNIK IZQUIERDO -->
  <link name="robot_1_base_logo_left">
    <visual>
      <origin rpy="0 0 0" xyz="0 0 0"/>
      <geometry>
        <mesh filename="package://summit_xl_description/meshes/bases/xls/robotnik_logo_chasis.stl"/>
      </geometry>
      <material name="darkgrey">
        <color rgba="0.5 0.5 0.5 1"/>
      </material>
    </visual>
  </link>
  <joint name="robot_1_base_logo_left_joint" type="fixed">
    <origin rpy="0 0 0" xyz="0.0 0.28931 0.29062"/>
    <parent link="robot_1_base_link"/>
    <child link="robot_1_base_logo_left"/>
  </joint>
  <!-- LOGO ROBOTNIK DERECHO -->
  <link name="robot_1_base_logo_right">
    <visual>
      <origin rpy="0 0 0" xyz="0 0 0"/>
      <geometry>
        <mesh filename="package://summit_xl_description/meshes/bases/xls/robotnik_logo_chasis.stl"/>
      </geometry>
      <material name="darkgrey">
        <color rgba="0.5 0.5 0.5 1"/>
      </material>
    </visual>
  </link>
  <joint name="robot_1_base_logo_right_joint" type="fixed">
    <origin rpy="0 0 3.141592653589793" xyz="0.0 -0.28931 0.29062"/>
    <parent link="robot_1_base_link"/>
    <child link="robot_1_base_logo_right"/>
  </joint>
  <!-- LOGO ROBOTNIK FRONTAL -->
  <link name="robot_1_base_logo_front">
    <visual>
      <origin rpy="0 0 0" xyz="0 0 0"/>
      <geometry>
        <mesh filename="package://summit_xl_description/meshes/bases/xls/robotnik_logo_chasis.stl"/>
      </geometry>
      <material name="darkgrey">
        <color rgba="0.5 0.5 0.5 1"/>
      </material>
    </visual>
  </link>
  <joint name="robot_1_base_logo_front_joint" type="fixed">
    <origin rpy="0 0 -1.5707963267948966" xyz="0.345 0.0 0.0"/>
    <parent link="robot_1_base_link"/>
    <child link="robot_1_base_logo_front"/>
  </joint>
  <!-- LOGO ROBOTNIK TRASERO -->
  <link name="robot_1_base_logo_rear">
    <visual>
      <origin rpy="0 0 0" xyz="0 0 0"/>
      <geometry>
        <mesh filename="package://summit_xl_description/meshes/bases/xls/robotnik_logo_chasis.stl"/>
      </geometry>
      <material name="darkgrey">
        <color rgba="0.5 0.5 0.5 1"/>
      </material>
    </visual>
  </link>
  <joint name="robot_1_base_logo_rear_joint" type="fixed">
    <origin rpy="0 0 1.5707963267948966" xyz="-0.345 0.0 0.0"/>
    <parent link="robot_1_base_link"/>
    <child link="robot_1_base_logo_rear"/>
  </joint>
  <!-- DOCKING CONTACT -->
  <link name="robot_1_base_docking_contact">
    </link>
  <joint name="robot_1_base_docking_joint" type="fixed">
    <origin rpy="0 0 0" xyz="0.35 0 0.09"/>
    <parent link="robot_1_base_link"/>
    <child link="robot_1_base_docking_contact"/>
  </joint>
  <link name="robot_1_top_structure">
    <visual>
      <origin rpy="0 0 0" xyz="0 0 0"/>
      <geometry>
        <mesh filename="package://summit_xl_description/meshes/structures/top_structure_roas.STL"/>
      </geometry>
      <material name="silver">
        <color rgba="0.75 0.75 0.75 1"/>
      </material>
    </visual>
    <collision>
      <origin rpy="0 0 0" xyz="0 0 0"/>
      <geometry>
        <mesh filename="package://summit_xl_description/meshes/structures/top_structure_roas.STL"/>
      </geometry>
    </collision>
  </link>
  <!-- sub-link defining detailed meshes for collision with environment -->
  <link name="robot_1_fr3_link0">
    <visual>
      <geometry>
        <mesh filename="package://franka_description/meshes/visual/link0.dae"/>
      </geometry>
    </visual>
    <collision>
      <geometry>
        <mesh filename="package://franka_description/meshes/collision/link0.stl"/>
      </geometry>
    </collision>
    <inertial>
      <origin rpy="0 0 0" xyz="0 0 0"/>
      <mass value="0.629769"/>
      <inertia ixx="0.00315" ixy="8.2904e-07" ixz="0.00015" iyy="0.00388" iyz="8.2299e-06" izz="0.004285"/>
    </inertial>
  </link>
  <!-- sub-link defining coarse geometries of real robot's internal self-collision -->
  <link name="robot_1_fr3_link0_sc">
  </link>
  <!-- fixed joint between both sub-links -->
  <joint name="robot_1_fr3_link0_sc_joint" type="fixed">
    <origin rpy="0 0 0"/>
    <parent link="robot_1_fr3_link0"/>
    <child link="robot_1_fr3_link0_sc"/>
  </joint>
  <!-- sub-link defining detailed meshes for collision with environment -->
  <link name="robot_1_fr3_link1">
    <visual>
      <geometry>
        <mesh filename="package://franka_description/meshes/visual/link1.dae"/>
      </geometry>
    </visual>
    <collision>
      <geometry>
        <mesh filename="package://franka_description/meshes/collision/link1.stl"/>
      </geometry>
    </collision>
    <inertial>
      <origin rpy="0 0 0" xyz="0 0 0"/>
      <mass value="4.970684"/>
      <inertia ixx="0.70337" ixy="-0.000139" ixz="0.006772" iyy="0.70661" iyz="0.019169" izz="0.009117"/>
    </inertial>
  </link>
  <!-- sub-link defining coarse geometries of real robot's internal self-collision -->
  <link name="robot_1_fr3_link1_sc">
  </link>
  <!-- fixed joint between both sub-links -->
  <joint name="robot_1_fr3_link1_sc_joint" type="fixed">
    <origin rpy="0 0 0"/>
    <parent link="robot_1_fr3_link1"/>
    <child link="robot_1_fr3_link1_sc"/>
  </joint>
  <joint name="robot_1_fr3_joint1" type="revolute">
    <origin rpy="0 0 0" xyz="0 0 0.333"/>
    <parent link="robot_1_fr3_link0"/>
    <child link="robot_1_fr3_link1"/>
    <axis xyz="0 0 1"/>
    <limit effort="87.0" lower="-2.3093" upper="2.3093" velocity="2.0"/>
    <safety_controller k_position="100.0" k_velocity="40.0" soft_lower_limit="-2.3093" soft_upper_limit="2.3093"/>
    <dynamics D="1" K="7000" damping="0.003" friction="0.0" mu_coulomb="0" mu_viscous="16"/>
  </joint>
  <!-- sub-link defining detailed meshes for collision with environment -->
  <link name="robot_1_fr3_link2">
    <visual>
      <geometry>
        <mesh filename="package://franka_description/meshes/visual/link2.dae"/>
      </geometry>
    </visual>
    <collision>
      <geometry>
        <mesh filename="package://franka_description/meshes/collision/link2.stl"/>
      </geometry>
    </collision>
    <inertial>
      <origin rpy="0 0 0" xyz="0 0 0"/>
      <mass value="0.646926"/>
      <inertia ixx="0.007962" ixy="-0.003925" ixz="0.010254" iyy="0.02811" iyz="0.000704" izz="0.025995"/>
    </inertial>
  </link>
  <!-- sub-link defining coarse geometries of real robot's internal self-collision -->
  <link name="robot_1_fr3_link2_sc">
  </link>
  <!-- fixed joint between both sub-links -->
  <joint name="robot_1_fr3_link2_sc_joint" type="fixed">
    <origin rpy="0 0 0"/>
    <parent link="robot_1_fr3_link2"/>
    <child link="robot_1_fr3_link2_sc"/>
  </joint>
  <joint name="robot_1_fr3_joint2" type="revolute">
    <origin rpy="-1.5707963267948966 0 0" xyz="0 0 0"/>
    <parent link="robot_1_fr3_link1"/>
    <child link="robot_1_fr3_link2"/>
    <axis xyz="0 0 1"/>
    <limit effort="87.0" lower="-1.5133" upper="1.5133" velocity="1.0"/>
    <safety_controller k_position="100.0" k_velocity="40.0" soft_lower_limit="-1.5133" soft_upper_limit="1.5133"/>
    <dynamics D="1" K="7000" damping="0.003" friction="0.0" mu_coulomb="0" mu_viscous="16"/>
  </joint>
  <!-- sub-link defining detailed meshes for collision with environment -->
  <link name="robot_1_fr3_link3">
    <visual>
      <geometry>
        <mesh filename="package://franka_description/meshes/visual/link3.dae"/>
      </geometry>
    </visual>
    <collision>
      <geometry>
        <mesh filename="package://franka_description/meshes/collision/link3.stl"/>
      </geometry>
    </collision>
    <inertial>
      <origin rpy="0 0 0" xyz="0 0 0"/>
      <mass value="3.228604"/>
      <inertia ixx="0.037242" ixy="-0.004761" ixz="-0.011396" iyy="0.036155" iyz="-0.012805" izz="0.01083"/>
    </inertial>
  </link>
  <!-- sub-link defining coarse geometries of real robot's internal self-collision -->
  <link name="robot_1_fr3_link3_sc">
  </link>
  <!-- fixed joint between both sub-links -->
  <joint name="robot_1_fr3_link3_sc_joint" type="fixed">
    <origin rpy="0 0 0"/>
    <parent link="robot_1_fr3_link3"/>
    <child link="robot_1_fr3_link3_sc"/>
  </joint>
  <joint name="robot_1_fr3_joint3" type="revolute">
    <origin rpy="1.5707963267948966 0 0" xyz="0 -0.316 0"/>
    <parent link="robot_1_fr3_link2"/>
    <child link="robot_1_fr3_link3"/>
    <axis xyz="0 0 1"/>
    <limit effort="87.0" lower="-2.4937" upper="2.4937" velocity="1.5"/>
    <safety_controller k_position="100.0" k_velocity="40.0" soft_lower_limit="-2.4937" soft_upper_limit="2.4937"/>
    <dynamics D="1" K="7000" damping="0.003" friction="0.0" mu_coulomb="0" mu_viscous="16"/>
  </joint>
  <!-- sub-link defining detailed meshes for collision with environment -->
  <link name="robot_1_fr3_link4">
    <visual>
      <geometry>
        <mesh filename="package://franka_description/meshes/visual/link4.dae"/>
      </geometry>
    </visual>
    <collision>
      <geometry>
        <mesh filename="package://franka_description/meshes/collision/link4.stl"/>
      </geometry>
    </collision>
    <inertial>
      <origin rpy="0 0 0" xyz="0 0 0"/>
      <mass value="3.587895"/>
      <inertia ixx="0.025853" ixy="0.007796" ixz="-0.001332" iyy="0.019552" iyz="0.008641" izz="0.028323"/>
    </inertial>
  </link>
  <!-- sub-link defining coarse geometries of real robot's internal self-collision -->
  <link name="robot_1_fr3_link4_sc">
  </link>
  <!-- fixed joint between both sub-links -->
  <joint name="robot_1_fr3_link4_sc_joint" type="fixed">
    <origin rpy="0 0 0"/>
    <parent link="robot_1_fr3_link4"/>
    <child link="robot_1_fr3_link4_sc"/>
  </joint>
  <joint name="robot_1_fr3_joint4" type="revolute">
    <origin rpy="1.5707963267948966 0 0" xyz="0.0825 0 0"/>
    <parent link="robot_1_fr3_link3"/>
    <child link="robot_1_fr3_link4"/>
    <axis xyz="0 0 1"/>
    <limit effort="87.0" lower="-2.7478" upper="-0.4461" velocity="1.25"/>
    <safety_controller k_position="100.0" k_velocity="40.0" soft_lower_limit="-2.7478" soft_upper_limit="-0.4461"/>
    <dynamics D="1" K="7000" damping="0.003" friction="0.0" mu_coulomb="0" mu_viscous="16"/>
  </joint>
  <!-- sub-link defining detailed meshes for collision with environment -->
  <link name="robot_1_fr3_link5">
    <visual>
      <geometry>
        <mesh filename="package://franka_description/meshes/visual/link5.dae"/>
      </geometry>
    </visual>
    <collision>
      <geometry>
        <mesh filename="package://franka_description/meshes/collision/link5.stl"/>
      </geometry>
    </collision>
    <inertial>
      <origin rpy="0 0 0" xyz="0 0 0"/>
      <mass value="1.225946"/>
      <inertia ixx="0.035549" ixy="-0.002117" ixz="-0.004037" iyy="0.029474" iyz="0.000229" izz="0.008627"/>
    </inertial>
  </link>
  <!-- sub-link defining coarse geometries of real robot's internal self-collision -->
  <link name="robot_1_fr3_link5_sc">
  </link>
  <!-- fixed joint between both sub-links -->
  <joint name="robot_1_fr3_link5_sc_joint" type="fixed">
    <origin rpy="0 0 0"/>
    <parent link="robot_1_fr3_link5"/>
    <child link="robot_1_fr3_link5_sc"/>
  </joint>
  <joint name="robot_1_fr3_joint5" type="revolute">
    <origin rpy="-1.5707963267948966 0 0" xyz="-0.0825 0.384 0"/>
    <parent link="robot_1_fr3_link4"/>
    <child link="robot_1_fr3_link5"/>
    <axis xyz="0 0 1"/>
    <limit effort="12.0" lower="-2.48" upper="2.48" velocity="3.0"/>
    <safety_controller k_position="100.0" k_velocity="40.0" soft_lower_limit="-2.48" soft_upper_limit="2.48"/>
    <dynamics D="1" K="7000" damping="0.003" friction="0.0" mu_coulomb="0" mu_viscous="16"/>
  </joint>
  <!-- sub-link defining detailed meshes for collision with environment -->
  <link name="robot_1_fr3_link6">
    <visual>
      <geometry>
        <mesh filename="package://franka_description/meshes/visual/link6.dae"/>
      </geometry>
    </visual>
    <collision>
      <geometry>
        <mesh filename="package://franka_description/meshes/collision/link6.stl"/>
      </geometry>
    </collision>
    <inertial>
      <origin rpy="0 0 0" xyz="0 0 0"/>
      <mass value="1.666555"/>
      <inertia ixx="0.001964" ixy="0.000109" ixz="-0.001158" iyy="0.004354" iyz="0.000341" izz="0.005433"/>
    </inertial>
  </link>
  <!-- sub-link defining coarse geometries of real robot's internal self-collision -->
  <link name="robot_1_fr3_link6_sc">
  </link>
  <!-- fixed joint between both sub-links -->
  <joint name="robot_1_fr3_link6_sc_joint" type="fixed">
    <origin rpy="0 0 0"/>
    <parent link="robot_1_fr3_link6"/>
    <child link="robot_1_fr3_link6_sc"/>
  </joint>
  <joint name="robot_1_fr3_joint6" type="revolute">
    <origin rpy="1.5707963267948966 0 0" xyz="0 0 0"/>
    <parent link="robot_1_fr3_link5"/>
    <child link="robot_1_fr3_link6"/>
    <axis xyz="0 0 1"/>
    <limit effort="12.0" lower="0.8521" upper="4.2094" velocity="1.5"/>
    <safety_controller k_position="100.0" k_velocity="40.0" soft_lower_limit="0.8521" soft_upper_limit="4.2094"/>
    <dynamics D="1" K="7000" damping="0.003" friction="0.0" mu_coulomb="0" mu_viscous="16"/>
  </joint>
  <!-- sub-link defining detailed meshes for collision with environment -->
  <link name="robot_1_fr3_link7">
    <visual>
      <geometry>
        <mesh filename="package://franka_description/meshes/visual/link7.dae"/>
      </geometry>
    </visual>
    <collision>
      <geometry>
        <mesh filename="package://franka_description/meshes/collision/link7.stl"/>
      </geometry>
    </collision>
    <inertial>
      <origin rpy="0 0 0" xyz="0 0 0"/>
      <mass value="0.735522"/>
      <inertia ixx="0.012516" ixy="-0.000428" ixz="-0.001196" iyy="0.010027" iyz="-0.000741" izz="0.004815"/>
    </inertial>
  </link>
  <!-- sub-link defining coarse geometries of real robot's internal self-collision -->
  <link name="robot_1_fr3_link7_sc">
  </link>
  <!-- fixed joint between both sub-links -->
  <joint name="robot_1_fr3_link7_sc_joint" type="fixed">
    <origin rpy="0 0 0.7853981633974483"/>
    <parent link="robot_1_fr3_link7"/>
    <child link="robot_1_fr3_link7_sc"/>
  </joint>
  <joint name="robot_1_fr3_joint7" type="revolute">
    <origin rpy="1.5707963267948966 0 0" xyz="0.088 0 0"/>
    <parent link="robot_1_fr3_link6"/>
    <child link="robot_1_fr3_link7"/>
    <axis xyz="0 0 1"/>
    <limit effort="12.0" lower="-2.6895" upper="2.6895" velocity="3.0"/>
    <safety_controller k_position="100.0" k_velocity="40.0" soft_lower_limit="-2.6895" soft_upper_limit="2.6895"/>
    <dynamics D="1" K="7000" damping="0.003" friction="0.0" mu_coulomb="0" mu_viscous="16"/>
  </joint>
  <link name="robot_1_fr3_link8"/>
  <joint name="robot_1_fr3_joint8" type="fixed">
    <origin rpy="0 0 0" xyz="0 0 0.107"/>
    <parent link="robot_1_fr3_link7"/>
    <child link="robot_1_fr3_link8"/>
  </joint>
  <joint name="robot_1_fr3_hand_joint" type="fixed">
    <parent link="robot_1_fr3_link8"/>
    <child link="robot_1_fr3_hand"/>
    <origin rpy="0 0 -0.7853981633974483" xyz="0 0 0.003"/>
  </joint>
  <!-- sub-link defining detailed meshes for collision with environment -->
  <link name="robot_1_fr3_hand">
    <visual>
      <geometry>
        <mesh filename="package://franka_description/meshes/visual/hand.dae"/>
      </geometry>
    </visual>
    <collision>
      <geometry>
        <mesh filename="package://franka_description/meshes/collision/hand.stl"/>
      </geometry>
    </collision>
    <inertial>
      <origin rpy="0 0 0" xyz="0 0 0"/>
      <mass value="0.73"/>
      <inertia ixx="0.001" ixy="0" ixz="0" iyy="0.0025" iyz="0" izz="0.0017"/>
    </inertial>
  </link>
  <!-- sub-link defining coarse geometries of real robot's internal self-collision -->
  <link name="robot_1_fr3_hand_sc">
  </link>
  <!-- fixed joint between both sub-links -->
  <joint name="robot_1_fr3_hand_sc_joint" type="fixed">
    <origin rpy="0 0 0"/>
    <parent link="robot_1_fr3_hand"/>
    <child link="robot_1_fr3_hand_sc"/>
  </joint>
  <!-- Define the hand_tcp frame -->
  <link name="robot_1_fr3_hand_tcp"/>
  <joint name="robot_1_fr3_hand_tcp_joint" type="fixed">
    <origin rpy="0 0 0" xyz="0 0 0.1034"/>
    <parent link="robot_1_fr3_hand"/>
    <child link="robot_1_fr3_hand_tcp"/>
  </joint>
  <link name="robot_1_fr3_leftfinger">
    <visual>
      <geometry>
        <mesh filename="package://franka_description/meshes/visual/finger.dae"/>
      </geometry>
    </visual>
    <!-- screw mount -->
    <collision>
      <origin rpy="0 0 0" xyz="0 18.5e-3 11e-3"/>
      <geometry>
        <box size="22e-3 15e-3 20e-3"/>
      </geometry>
    </collision>
    <!-- cartriage sledge -->
    <collision>
      <origin rpy="0 0 0" xyz="0 6.8e-3 2.2e-3"/>
      <geometry>
        <box size="22e-3 8.8e-3 3.8e-3"/>
      </geometry>
    </collision>
    <!-- diagonal finger -->
    <collision>
      <origin rpy="0.5235987755982988 0 0" xyz="0 15.9e-3 28.35e-3"/>
      <geometry>
        <box size="17.5e-3 7e-3 23.5e-3"/>
      </geometry>
    </collision>
    <!-- rubber tip with which to grasp -->
    <collision>
      <origin rpy="0 0 0" xyz="0 7.58e-3 45.25e-3"/>
      <geometry>
        <box size="17.5e-3 15.2e-3 18.5e-3"/>
      </geometry>
    </collision>
    <inertial>
      <origin rpy="0 0 0" xyz="0 0 0"/>
      <mass value="0.015"/>
      <inertia ixx="2.3749999999999997e-06" ixy="0" ixz="0" iyy="2.3749999999999997e-06" iyz="0" izz="7.5e-07"/>
    </inertial>
  </link>
  <link name="robot_1_fr3_rightfinger">
    <visual>
      <origin rpy="0 0 3.141592653589793" xyz="0 0 0"/>
      <geometry>
        <mesh filename="package://franka_description/meshes/visual/finger.dae"/>
      </geometry>
    </visual>
    <!-- screw mount -->
    <collision>
      <origin rpy="0 0 0" xyz="0 -18.5e-3 11e-3"/>
      <geometry>
        <box size="22e-3 15e-3 20e-3"/>
      </geometry>
    </collision>
    <!-- cartriage sledge -->
    <collision>
      <origin rpy="0 0 0" xyz="0 -6.8e-3 2.2e-3"/>
      <geometry>
        <box size="22e-3 8.8e-3 3.8e-3"/>
      </geometry>
    </collision>
    <!-- diagonal finger -->
    <collision>
      <origin rpy="-0.5235987755982988 0 0" xyz="0 -15.9e-3 28.35e-3"/>
      <geometry>
        <box size="17.5e-3 7e-3 23.5e-3"/>
      </geometry>
    </collision>
    <!-- rubber tip with which to grasp -->
    <collision>
      <origin rpy="0 0 0" xyz="0 -7.58e-3 45.25e-3"/>
      <geometry>
        <box size="17.5e-3 15.2e-3 18.5e-3"/>
      </geometry>
    </collision>
    <inertial>
      <origin rpy="0 0 0" xyz="0 0 0"/>
      <mass value="0.015"/>
      <inertia ixx="2.3749999999999997e-06" ixy="0" ixz="0" iyy="2.3749999999999997e-06" iyz="0" izz="7.5e-07"/>
    </inertial>
  </link>
  <joint name="robot_1_fr3_finger_joint1" type="prismatic">
    <parent link="robot_1_fr3_hand"/>
    <child link="robot_1_fr3_leftfinger"/>
    <origin rpy="0 0 0" xyz="0 0 0.0584"/>
    <axis xyz="0 1 0"/>
    <limit effort="100" lower="0.0" upper="0.04" velocity="0.2"/>
    <dynamics damping="0.3"/>
  </joint>
  <joint name="robot_1_fr3_finger_joint2" type="prismatic">
    <parent link="robot_1_fr3_hand"/>
    <child link="robot_1_fr3_rightfinger"/>
    <origin rpy="0 0 0" xyz="0 0 0.0584"/>
    <axis xyz="0 -1 0"/>
    <limit effort="100" lower="0.0" upper="0.04" velocity="0.2"/>
    <!-- <mimic joint="${arm_id}_finger_joint1" /> -->
    <dynamics damping="0.3"/>
  </joint>
  <gazebo reference="robot_1_fr3_joint1">
    <!-- Needed for ODE to output external wrenches on joints -->
    <provideFeedback>true</provideFeedback>
  </gazebo>
  <transmission name="robot_1_fr3_joint1_transmission">
    <type>transmission_interface/SimpleTransmission</type>
    <joint name="robot_1_fr3_joint1">
      <hardwareInterface>hardware_interface/EffortJointInterface</hardwareInterface>
    </joint>
    <actuator name="robot_1_fr3_joint1_motor">
      <hardwareInterface>hardware_interface/EffortJointInterface</hardwareInterface>
    </actuator>
  </transmission>
  <gazebo reference="robot_1_fr3_joint2">
    <!-- Needed for ODE to output external wrenches on joints -->
    <provideFeedback>true</provideFeedback>
  </gazebo>
  <transmission name="robot_1_fr3_joint2_transmission">
    <type>transmission_interface/SimpleTransmission</type>
    <joint name="robot_1_fr3_joint2">
      <hardwareInterface>hardware_interface/EffortJointInterface</hardwareInterface>
    </joint>
    <actuator name="robot_1_fr3_joint2_motor">
      <hardwareInterface>hardware_interface/EffortJointInterface</hardwareInterface>
    </actuator>
  </transmission>
  <gazebo reference="robot_1_fr3_joint3">
    <!-- Needed for ODE to output external wrenches on joints -->
    <provideFeedback>true</provideFeedback>
  </gazebo>
  <transmission name="robot_1_fr3_joint3_transmission">
    <type>transmission_interface/SimpleTransmission</type>
    <joint name="robot_1_fr3_joint3">
      <hardwareInterface>hardware_interface/EffortJointInterface</hardwareInterface>
    </joint>
    <actuator name="robot_1_fr3_joint3_motor">
      <hardwareInterface>hardware_interface/EffortJointInterface</hardwareInterface>
    </actuator>
  </transmission>
  <gazebo reference="robot_1_fr3_joint4">
    <!-- Needed for ODE to output external wrenches on joints -->
    <provideFeedback>true</provideFeedback>
  </gazebo>
  <transmission name="robot_1_fr3_joint4_transmission">
    <type>transmission_interface/SimpleTransmission</type>
    <joint name="robot_1_fr3_joint4">
      <hardwareInterface>hardware_interface/EffortJointInterface</hardwareInterface>
    </joint>
    <actuator name="robot_1_fr3_joint4_motor">
      <hardwareInterface>hardware_interface/EffortJointInterface</hardwareInterface>
    </actuator>
  </transmission>
  <gazebo reference="robot_1_fr3_joint5">
    <!-- Needed for ODE to output external wrenches on joints -->
    <provideFeedback>true</provideFeedback>
  </gazebo>
  <transmission name="robot_1_fr3_joint5_transmission">
    <type>transmission_interface/SimpleTransmission</type>
    <joint name="robot_1_fr3_joint5">
      <hardwareInterface>hardware_interface/EffortJointInterface</hardwareInterface>
    </joint>
    <actuator name="robot_1_fr3_joint5_motor">
      <hardwareInterface>hardware_interface/EffortJointInterface</hardwareInterface>
    </actuator>
  </transmission>
  <gazebo reference="robot_1_fr3_joint6">
    <!-- Needed for ODE to output external wrenches on joints -->
    <provideFeedback>true</provideFeedback>
  </gazebo>
  <transmission name="robot_1_fr3_joint6_transmission">
    <type>transmission_interface/SimpleTransmission</type>
    <joint name="robot_1_fr3_joint6">
      <hardwareInterface>hardware_interface/EffortJointInterface</hardwareInterface>
    </joint>
    <actuator name="robot_1_fr3_joint6_motor">
      <hardwareInterface>hardware_interface/EffortJointInterface</hardwareInterface>
    </actuator>
  </transmission>
  <gazebo reference="robot_1_fr3_joint7">
    <!-- Needed for ODE to output external wrenches on joints -->
    <provideFeedback>true</provideFeedback>
  </gazebo>
  <transmission name="robot_1_fr3_joint7_transmission">
    <type>transmission_interface/SimpleTransmission</type>
    <joint name="robot_1_fr3_joint7">
      <hardwareInterface>hardware_interface/EffortJointInterface</hardwareInterface>
    </joint>
    <actuator name="robot_1_fr3_joint7_motor">
      <hardwareInterface>hardware_interface/EffortJointInterface</hardwareInterface>
    </actuator>
  </transmission>
  <gazebo reference="robot_1_fr3_finger_joint1">
    <!-- Needed for ODE to output external wrenches on joints -->
    <provideFeedback>true</provideFeedback>
  </gazebo>
  <transmission name="robot_1_fr3_finger_joint1_transmission">
    <type>transmission_interface/SimpleTransmission</type>
    <joint name="robot_1_fr3_finger_joint1">
      <hardwareInterface>hardware_interface/EffortJointInterface</hardwareInterface>
    </joint>
    <actuator name="robot_1_fr3_finger_joint1_motor">
      <hardwareInterface>hardware_interface/EffortJointInterface</hardwareInterface>
    </actuator>
  </transmission>
  <gazebo reference="robot_1_fr3_finger_joint2">
    <!-- Needed for ODE to output external wrenches on joints -->
    <provideFeedback>true</provideFeedback>
  </gazebo>
  <transmission name="robot_1_fr3_finger_joint2_transmission">
    <type>transmission_interface/SimpleTransmission</type>
    <joint name="robot_1_fr3_finger_joint2">
      <hardwareInterface>hardware_interface/EffortJointInterface</hardwareInterface>
    </joint>
    <actuator name="robot_1_fr3_finger_joint2_motor">
      <hardwareInterface>hardware_interface/EffortJointInterface</hardwareInterface>
    </actuator>
  </transmission>
  <gazebo reference="robot_1_fr3_leftfinger">
    <collision>
      <max_contacts>10</max_contacts>
      <surface>
        <contact>
          <ode>
            <!-- These two parameter need application specific tuning. -->
            <!-- Usually you want no "snap out" velocity and a generous -->
            <!-- penetration depth to keep the grasping stable -->
            <max_vel>0</max_vel>
            <min_depth>0.001</min_depth>
          </ode>
        </contact>
        <friction>
          <ode>
            <mu>1.13</mu>
            <mu2>1.13</mu2>
          </ode>
        </friction>
        <bounce/>
      </surface>
    </collision>
  </gazebo>
  <gazebo reference="robot_1_fr3_rightfinger">
    <collision>
      <max_contacts>10</max_contacts>
      <surface>
        <contact>
          <ode>
            <!-- These two parameter need application specific tuning. -->
            <!-- Usually you want no "snap out" velocity and a generous -->
            <!-- penetration depth to keep the grasping stable -->
            <max_vel>0</max_vel>
            <min_depth>0.001</min_depth>
          </ode>
        </contact>
        <friction>
          <ode>
            <mu>1.13</mu>
            <mu2>1.13</mu2>
          </ode>
        </friction>
        <bounce/>
      </surface>
    </collision>
  </gazebo>
  <joint name="robot_1_fr3_base_joint" type="fixed">
    <origin rpy="0 0 0" xyz="0.23 0 0.66"/>
    <parent link="robot_1_top_structure"/>
    <child link="robot_1_fr3_link0"/>
  </joint>
  <link name="robot_1_ee_link"/>
  <joint name="robot_1_ee_joint" type="fixed">
    <parent link="robot_1_fr3_link8"/>
    <child link="robot_1_ee_link"/>
    <origin rpy="0 0 0" xyz="0 0 0"/>
  </joint>
  <!-- <material name="aluminum">
      <color rgba="0.5 0.5 0.5 1"/>
    </material> -->
  <!-- camera body, with origin at bottom screw mount -->
  <joint name="robot_1_camera_joint" type="fixed">
    <origin rpy="0 -1.57 3.14" xyz="0.0377 0 0.0105"/>
    <parent link="robot_1_camera_bracket"/>
    <child link="robot_1_camera_bottom_screw_frame"/>
  </joint>
  <link name="robot_1_camera_bottom_screw_frame"/>
  <joint name="robot_1_camera_link_joint" type="fixed">
    <origin rpy="0 0 0" xyz="0.010600000000000002 0.0175 0.0125"/>
    <parent link="robot_1_camera_bottom_screw_frame"/>
    <child link="robot_1_camera_link"/>
  </joint>
  <link name="robot_1_camera_link">
    <visual>
      <origin rpy="1.5707963267948966 0 1.5707963267948966" xyz="0.0043 -0.0175 0"/>
      <geometry>
        <mesh filename="package://summit_xl_description/meshes/structures/d435.dae"/>
      </geometry>
    </visual>
    <collision>
      <origin rpy="0 0 0" xyz="0 -0.0175 0"/>
      <geometry>
        <box size="0.02505 0.09 0.025"/>
      </geometry>
    </collision>
    <inertial>
      <mass value="0.564"/>
      <origin xyz="0 0 0"/>
      <inertia ixx="0.003881243" ixy="0.0" ixz="0.0" iyy="0.000498940" iyz="0.0" izz="0.003879257"/>
    </inertial>
  </link>
  <!-- Use the nominal extrinsics between camera frames if the calibrated extrinsics aren't being published. e.g. running the device in simulation  -->
  <!--xacro:if value="$(arg use_nominal_extrinsics)"-->
  <!-- camera depth joints and links -->
  <joint name="robot_1_camera_depth_joint" type="fixed">
    <origin rpy="0 0 0" xyz="0 0 0"/>
    <parent link="robot_1_camera_link"/>
    <child link="robot_1_camera_depth_frame"/>
  </joint>
  <link name="robot_1_camera_depth_frame"/>
  <joint name="robot_1_camera_depth_optical_joint" type="fixed">
    <origin rpy="-1.5707963267948966 0 -1.5707963267948966" xyz="0 0 0"/>
    <parent link="robot_1_camera_depth_frame"/>
    <child link="robot_1_camera_depth_optical_frame"/>
  </joint>
  <link name="robot_1_camera_depth_optical_frame"/>
  <!-- camera left IR joints and links -->
  <joint name="robot_1_camera_infra1_joint" type="fixed">
    <origin rpy="0 0 0" xyz="0 0.0 0"/>
    <parent link="robot_1_camera_link"/>
    <child link="robot_1_camera_infra1_frame"/>
  </joint>
  <link name="robot_1_camera_infra1_frame"/>
  <joint name="robot_1_camera_infra1_optical_joint" type="fixed">
    <origin rpy="-1.5707963267948966 0 -1.5707963267948966" xyz="0 0 0"/>
    <parent link="robot_1_camera_infra1_frame"/>
    <child link="robot_1_camera_infra1_optical_frame"/>
  </joint>
  <link name="robot_1_camera_infra1_optical_frame"/>
  <!-- camera right IR joints and links -->
  <joint name="robot_1_camera_infra2_joint" type="fixed">
    <origin rpy="0 0 0" xyz="0 -0.05 0"/>
    <parent link="robot_1_camera_link"/>
    <child link="robot_1_camera_infra2_frame"/>
  </joint>
  <link name="robot_1_camera_infra2_frame"/>
  <joint name="robot_1_camera_infra2_optical_joint" type="fixed">
    <origin rpy="-1.5707963267948966 0 -1.5707963267948966" xyz="0 0 0"/>
    <parent link="robot_1_camera_infra2_frame"/>
    <child link="robot_1_camera_infra2_optical_frame"/>
  </joint>
  <link name="robot_1_camera_infra2_optical_frame"/>
  <!-- camera color joints and links -->
  <joint name="robot_1_camera_color_joint" type="fixed">
    <origin rpy="0 0 0" xyz="0 0.015 0"/>
    <parent link="robot_1_camera_link"/>
    <child link="robot_1_camera_color_frame"/>
  </joint>
  <link name="robot_1_camera_color_frame"/>
  <joint name="robot_1_camera_color_optical_joint" type="fixed">
    <origin rpy="-1.5707963267948966 0 -1.5707963267948966" xyz="0 0 0"/>
    <parent link="robot_1_camera_color_frame"/>
    <child link="robot_1_camera_color_optical_frame"/>
  </joint>
  <link name="robot_1_camera_color_optical_frame"/>
  <!--/xacro:if-->
  <!-- Gazebo part -->
  <!-- D435 Gazebo -->
  <gazebo reference="robot_1_camera_link">
    <sensor name="robot_1_camera" type="depth">
      <update_rate>30</update_rate>
      <visualize>true</visualize>
      <camera>
        <horizontal_fov>1.047198</horizontal_fov>
        <image>
          <width>640</width>
          <height>480</height>
          <format>R8G8B8</format>
        </image>
        <clip>
          <near>0.05</near>
          <far>3</far>
        </clip>
      </camera>
      <plugin filename="libgazebo_ros_openni_kinect.so" name="camera_controller">
        <baseline>0.2</baseline>
        <alwaysOn>true</alwaysOn>
        <updateRate>1.0</updateRate>
        <cameraName>camera</cameraName>
        <imageTopicName>/camera/color/image_raw</imageTopicName>
        <cameraInfoTopicName>/camera/color/camera_info</cameraInfoTopicName>
        <depthImageTopicName>/camera/depth/image_raw</depthImageTopicName>
        <depthImageInfoTopicName>/camera/depth/camera_info</depthImageInfoTopicName>
        <pointCloudTopicName>/camera/depth/points</pointCloudTopicName>
        <frameName>d435_link</frameName>
        <pointCloudCutoff>0.5</pointCloudCutoff>
        <pointCloudCutoffMax>3.0</pointCloudCutoffMax>
        <distortionK1>0.00000001</distortionK1>
        <distortionK2>0.00000001</distortionK2>
        <distortionK3>0.00000001</distortionK3>
        <distortionT1>0.00000001</distortionT1>
        <distortionT2>0.00000001</distortionT2>
        <CxPrime>0</CxPrime>
        <Cx>0</Cx>
        <Cy>0</Cy>
        <focalLength>0</focalLength>
        <hackBaseline>0</hackBaseline>
      </plugin>
    </sensor>
  </gazebo>
  <link name="robot_1_d435_link"/>
  <joint name="robot_1_d435_joint" type="fixed">
    <parent link="robot_1_camera_link"/>
    <child link="robot_1_d435_link"/>
    <origin rpy="-1.5707963267948966 0 -1.5707963267948966" xyz="0.0 0.0 0.0"/>
  </joint>
  <link name="robot_1_camera_bracket">
    <visual>
      <origin rpy="0 0 0" xyz="0 0 0"/>
      <geometry>
        <mesh filename="package://summit_xl_description/meshes/structures/hand_camera.STL"/>
      </geometry>
      <material name="silver">
        <color rgba="0.75 0.75 0.75 1"/>
      </material>
    </visual>
    <collision>
      <origin rpy="0 0 0" xyz="0 0 0"/>
      <geometry>
        <mesh filename="package://summit_xl_description/meshes/structures/hand_camera.STL"/>
      </geometry>
      <material name="silver">
        <color rgba="0.75 0.75 0.75 1"/>
      </material>
    </collision>
  </link>
  <joint name="robot_1_camera_bracket_joint" type="fixed">
    <parent link="robot_1_ee_link"/>
    <child link="robot_1_camera_bracket"/>
    <origin rpy="0 0 -0.785" xyz="0 0 0.003"/>
  </joint>
  <joint name="robot_1_top_structure_joint" type="fixed">
    <origin rpy="0 0 0" xyz="0 0 0"/>
    <parent link="robot_1_base_footprint"/>
    <child link="robot_1_top_structure"/>
  </joint>
  <joint name="robot_1_front_right_wheel_joint" type="continuous">
    <parent link="robot_1_base_link"/>
    <child link="robot_1_front_right_wheel_link"/>
    <origin rpy="0 0 0" xyz="0.2225 -0.2045 0.0"/>
    <axis rpy="0 0 0" xyz="0 1 0"/>
    <limit effort="100" velocity="100"/>
    <joint_properties damping="0.0" friction="0.0"/>
  </joint>
  <link name="robot_1_front_right_wheel_link">
    <visual>
      <origin rpy="0 0 0" xyz="0 0 0"/>
      <geometry>
        <mesh filename="package://summit_xl_description/meshes/wheels/omni_wheel_2.dae"/>
      </geometry>
      <material name="darkgrey">
        <color rgba="0.2 0.2 0.2 1"/>
      </material>
    </visual>
    <collision>
      <origin rpy="1.5707963267948966 0 0" xyz="0 0 0"/>
      <geometry>
        <!--sphere radius="${omni_wheel_radius}" /-->
        <!--
          <xacro:if value="${reflect}">
              <mesh filename="package://summit_xl_description/meshes/wheels/omni_wheel_1.dae" />
          </xacro:if>
          <xacro:unless value="${reflect}">
              <mesh filename="package://summit_xl_description/meshes/wheels/omni_wheel_2.dae" />
					</xacro:unless>
-->
        <cylinder length="0.087" radius="0.127"/>
        <!-- sphere radius="${omni_wheel_radius}"/-->
      </geometry>
    </collision>
    <inertial>
      <mass value="6.5"/>
      <origin xyz="0 0 0"/>
      <inertia ixx="0.0303095" ixy="0" ixz="0" iyy="0.05241925" iyz="0" izz="0.0303095"/>
    </inertial>
  </link>
  <!-- Transmission is important to link the joints and the controller (see summit_xl_control/config/summit_xl_control.yaml)-->
  <transmission name="robot_1_front_right_wheel_joint_trans">
    <type>transmission_interface/SimpleTransmission</type>
    <joint name="robot_1_front_right_wheel_joint">
      <hardwareInterface>hardware_interface/VelocityJointInterface</hardwareInterface>
    </joint>
    <actuator name="robot_1_front_right_wheel_joint_motor">
      <mechanicalReduction>1</mechanicalReduction>
      <motorTorqueConstant>20</motorTorqueConstant>
    </actuator>
  </transmission>
  <gazebo reference="robot_1_front_right_wheel_link">
    <mu1 value="0.01"/>
    <mu2 value="0.01"/>
    <kp value="10000000.0"/>
    <kd value="1.0"/>
    <fdir1 value="1 0 0"/>
    <turnGravityOff>false</turnGravityOff>
  </gazebo>
  <joint name="robot_1_front_left_wheel_joint" type="continuous">
    <parent link="robot_1_base_link"/>
    <child link="robot_1_front_left_wheel_link"/>
    <origin rpy="0 0 0" xyz="0.2225 0.2045 0.0"/>
    <axis rpy="0 0 0" xyz="0 1 0"/>
    <limit effort="100" velocity="100"/>
    <joint_properties damping="0.0" friction="0.0"/>
  </joint>
  <link name="robot_1_front_left_wheel_link">
    <visual>
      <origin rpy="0 0 0" xyz="0 0 0"/>
      <geometry>
        <mesh filename="package://summit_xl_description/meshes/wheels/omni_wheel_1.dae"/>
      </geometry>
      <material name="darkgrey">
        <color rgba="0.2 0.2 0.2 1"/>
      </material>
    </visual>
    <collision>
      <origin rpy="1.5707963267948966 0 0" xyz="0 0 0"/>
      <geometry>
        <!--sphere radius="${omni_wheel_radius}" /-->
        <!--
          <xacro:if value="${reflect}">
              <mesh filename="package://summit_xl_description/meshes/wheels/omni_wheel_1.dae" />
          </xacro:if>
          <xacro:unless value="${reflect}">
              <mesh filename="package://summit_xl_description/meshes/wheels/omni_wheel_2.dae" />
					</xacro:unless>
-->
        <cylinder length="0.087" radius="0.127"/>
        <!-- sphere radius="${omni_wheel_radius}"/-->
      </geometry>
    </collision>
    <inertial>
      <mass value="6.5"/>
      <origin xyz="0 0 0"/>
      <inertia ixx="0.0303095" ixy="0" ixz="0" iyy="0.05241925" iyz="0" izz="0.0303095"/>
    </inertial>
  </link>
  <!-- Transmission is important to link the joints and the controller (see summit_xl_control/config/summit_xl_control.yaml)-->
  <transmission name="robot_1_front_left_wheel_joint_trans">
    <type>transmission_interface/SimpleTransmission</type>
    <joint name="robot_1_front_left_wheel_joint">
      <hardwareInterface>hardware_interface/VelocityJointInterface</hardwareInterface>
    </joint>
    <actuator name="robot_1_front_left_wheel_joint_motor">
      <mechanicalReduction>1</mechanicalReduction>
      <motorTorqueConstant>20</motorTorqueConstant>
    </actuator>
  </transmission>
  <gazebo reference="robot_1_front_left_wheel_link">
    <mu1 value="0.01"/>
    <mu2 value="0.01"/>
    <kp value="10000000.0"/>
    <kd value="1.0"/>
    <fdir1 value="1 0 0"/>
    <turnGravityOff>false</turnGravityOff>
  </gazebo>
  <joint name="robot_1_back_left_wheel_joint" type="continuous">
    <parent link="robot_1_base_link"/>
    <child link="robot_1_back_left_wheel_link"/>
    <origin rpy="0 0 0" xyz="-0.2225 0.2045 0.0"/>
    <axis rpy="0 0 0" xyz="0 1 0"/>
    <limit effort="100" velocity="100"/>
    <joint_properties damping="0.0" friction="0.0"/>
  </joint>
  <link name="robot_1_back_left_wheel_link">
    <visual>
      <origin rpy="0 0 0" xyz="0 0 0"/>
      <geometry>
        <mesh filename="package://summit_xl_description/meshes/wheels/omni_wheel_1.dae"/>
      </geometry>
      <material name="darkgrey">
        <color rgba="0.2 0.2 0.2 1"/>
      </material>
    </visual>
    <collision>
      <origin rpy="1.5707963267948966 0 0" xyz="0 0 0"/>
      <geometry>
        <!--sphere radius="${omni_wheel_radius}" /-->
        <!--
          <xacro:if value="${reflect}">
              <mesh filename="package://summit_xl_description/meshes/wheels/omni_wheel_1.dae" />
          </xacro:if>
          <xacro:unless value="${reflect}">
              <mesh filename="package://summit_xl_description/meshes/wheels/omni_wheel_2.dae" />
					</xacro:unless>
-->
        <cylinder length="0.087" radius="0.127"/>
        <!-- sphere radius="${omni_wheel_radius}"/-->
      </geometry>
    </collision>
    <inertial>
      <mass value="6.5"/>
      <origin xyz="0 0 0"/>
      <inertia ixx="0.0303095" ixy="0" ixz="0" iyy="0.05241925" iyz="0" izz="0.0303095"/>
    </inertial>
  </link>
  <!-- Transmission is important to link the joints and the controller (see summit_xl_control/config/summit_xl_control.yaml)-->
  <transmission name="robot_1_back_left_wheel_joint_trans">
    <type>transmission_interface/SimpleTransmission</type>
    <joint name="robot_1_back_left_wheel_joint">
      <hardwareInterface>hardware_interface/VelocityJointInterface</hardwareInterface>
    </joint>
    <actuator name="robot_1_back_left_wheel_joint_motor">
      <mechanicalReduction>1</mechanicalReduction>
      <motorTorqueConstant>20</motorTorqueConstant>
    </actuator>
  </transmission>
  <gazebo reference="robot_1_back_left_wheel_link">
    <mu1 value="0.01"/>
    <mu2 value="0.01"/>
    <kp value="10000000.0"/>
    <kd value="1.0"/>
    <fdir1 value="1 0 0"/>
    <turnGravityOff>false</turnGravityOff>
  </gazebo>
  <joint name="robot_1_back_right_wheel_joint" type="continuous">
    <parent link="robot_1_base_link"/>
    <child link="robot_1_back_right_wheel_link"/>
    <origin rpy="0 0 0" xyz="-0.2225 -0.2045 0.0"/>
    <axis rpy="0 0 0" xyz="0 1 0"/>
    <limit effort="100" velocity="100"/>
    <joint_properties damping="0.0" friction="0.0"/>
  </joint>
  <link name="robot_1_back_right_wheel_link">
    <visual>
      <origin rpy="0 0 0" xyz="0 0 0"/>
      <geometry>
        <mesh filename="package://summit_xl_description/meshes/wheels/omni_wheel_2.dae"/>
      </geometry>
      <material name="darkgrey">
        <color rgba="0.2 0.2 0.2 1"/>
      </material>
    </visual>
    <collision>
      <origin rpy="1.5707963267948966 0 0" xyz="0 0 0"/>
      <geometry>
        <!--sphere radius="${omni_wheel_radius}" /-->
        <!--
          <xacro:if value="${reflect}">
              <mesh filename="package://summit_xl_description/meshes/wheels/omni_wheel_1.dae" />
          </xacro:if>
          <xacro:unless value="${reflect}">
              <mesh filename="package://summit_xl_description/meshes/wheels/omni_wheel_2.dae" />
					</xacro:unless>
-->
        <cylinder length="0.087" radius="0.127"/>
        <!-- sphere radius="${omni_wheel_radius}"/-->
      </geometry>
    </collision>
    <inertial>
      <mass value="6.5"/>
      <origin xyz="0 0 0"/>
      <inertia ixx="0.0303095" ixy="0" ixz="0" iyy="0.05241925" iyz="0" izz="0.0303095"/>
    </inertial>
  </link>
  <!-- Transmission is important to link the joints and the controller (see summit_xl_control/config/summit_xl_control.yaml)-->
  <transmission name="robot_1_back_right_wheel_joint_trans">
    <type>transmission_interface/SimpleTransmission</type>
    <joint name="robot_1_back_right_wheel_joint">
      <hardwareInterface>hardware_interface/VelocityJointInterface</hardwareInterface>
    </joint>
    <actuator name="robot_1_back_right_wheel_joint_motor">
      <mechanicalReduction>1</mechanicalReduction>
      <motorTorqueConstant>20</motorTorqueConstant>
    </actuator>
  </transmission>
  <gazebo reference="robot_1_back_right_wheel_link">
    <mu1 value="0.01"/>
    <mu2 value="0.01"/>
    <kp value="10000000.0"/>
    <kd value="1.0"/>
    <fdir1 value="1 0 0"/>
    <turnGravityOff>false</turnGravityOff>
  </gazebo>
  <!-- IMU -->
  <!-- <xacro:sensor_imu prefix="${prefix}_imu" parent="${prefix}_base_link" topic="imu/data_raw">
			<origin xyz="${imu_offset_x} ${imu_offset_y} ${imu_offset_z}" rpy="0 0 0"/>
		</xacro:sensor_imu> -->
  <!-- SENSORS -->
  <!-- <xacro:sensor_sick_tim571 prefix="${prefix}_front_laser" parent="${prefix}_base_link" prefix_topic="front_laser" gpu="$(arg gpu)">
			<origin xyz="${front_laser_offset_x} ${front_laser_offset_y} ${front_laser_offset_z}" rpy="0 ${-PI} ${3/4*PI}" />
		</xacro:sensor_sick_tim571>
		<xacro:sensor_sick_tim571 prefix="${prefix}_rear_laser" parent="${prefix}_base_link" prefix_topic="rear_laser" gpu="$(arg gpu)">
			<origin xyz="${rear_laser_offset_x} ${rear_laser_offset_y} ${rear_laser_offset_z}" rpy="0 ${-PI} ${-1/4*PI}" />
		</xacro:sensor_sick_tim571> -->
  <!--xacro:sensor_axis_m5013 prefix="${prefix}_front_ptz_camera" parent="${prefix}_base_link">
			<origin xyz="${front_ptz_camera_offset_x} ${front_ptz_camera_offset_y} ${front_ptz_camera_offset_z}" rpy="${-PI/2} 0 0"/>
		</xacro:sensor_axis_m5013-->
  <!--xacro:sensor_axis_m5013 prefix="${prefix}_rear_ptz_camera" parent="${prefix}_base_link">
			<origin xyz="${rear_ptz_camera_offset_x} ${rear_ptz_camera_offset_y} ${rear_ptz_camera_offset_z}" rpy="${-PI/2} 0 ${PI}"/>
		</xacro:sensor_axis_m5013-->
  <!-- <xacro:sensor_orbbec_astra prefix="${prefix}_front_rgbd_camera" parent="${prefix}_base_link" prefix_topic="front_rgbd_camera">
			<origin xyz="${front_rgbd_camera_offset_x} ${front_rgbd_camera_offset_y} ${front_rgbd_camera_offset_z}" rpy="0 0 0"/>
		</xacro:sensor_orbbec_astra> -->
  <gazebo>
    <plugin filename="libgazebo_ros_control.so" name="ros_control">
      <controlPeriod>0.001</controlPeriod>
      <robotSimType>gazebo_ros_control/DefaultRobotHWSim</robotSimType>
      <legacyModeNS>true</legacyModeNS>
    </plugin>
  </gazebo>
  <gazebo reference="base_footprint">
    <material>Gazebo/Green</material>
  </gazebo>
  <!-- in kg 6.5 -->
  <!-- in kg-->
  <!-- Import all available sensors -->
  <!-- <xacro:include filename="$(find robotnik_sensors)/urdf/all_sensors.urdf.xacro" /> -->
  <!-- Flag to select the high or low quality model -->
  <!-- *************** -->
  <!-- Robots Elements -->
  <!-- *************** -->
  <!-- Here we create the robot elements using the xacro:macros imported at the beggining of this file -->
  <link name="robot_2_base_footprint">
    <visual>
      <origin rpy="0 0 0" xyz="0 0 0"/>
      <geometry>
        <box size="0.001 0.001 0.001"/>
      </geometry>
    </visual>
  </link>
  <joint name="robot_2_base_footprint_joint" type="fixed">
    <origin rpy="0 0 0" xyz="0 0 0.127"/>
    <!-- ${wheel_radius} property must be defined inside wheel description -->
    <parent link="robot_2_base_footprint"/>
    <child link="robot_2_base_link"/>
  </joint>
  <!-- BASE_LINK -->
  <link name="robot_2_base_link">
    <inertial>
      <mass value="125.0"/>
      <!-- origin : 125.0 -->
      <origin xyz="0 0 0"/>
      <inertia ixx="1.391" ixy="0.004" ixz="0.0" iyy="6.853" iyz="0.0" izz="6.125"/>
    </inertial>
    <visual>
      <origin rpy="0 0 0" xyz="0 0 0"/>
      <geometry>
        <mesh filename="package://summit_xl_description/meshes/bases/xls/summit_xls_chassis.stl"/>
      </geometry>
      <material name="black">
        <color rgba="0.0 0.0 0.0 1"/>
      </material>
    </visual>
    <collision>
      <origin rpy="0 0 0 " xyz="0 0 0"/>
      <geometry>
        <mesh filename="package://summit_xl_description/meshes/bases/xls/summit_xls_chassis.dae"/>
      </geometry>
    </collision>
  </link>
  <gazebo reference="robot_2_base_link">
    <material>Gazebo/Black</material>
  </gazebo>
  <!-- CHAPAS INOX TAPAS -->
  <link name="robot_2_base_chapa">
    <visual>
      <origin rpy="0 0 0" xyz="0 0 0"/>
      <geometry>
        <mesh filename="package://summit_xl_description/meshes/bases/xls/summit_xls_chapas_inox_tapas.stl"/>
      </geometry>
      <material name="darkgrey">
        <color rgba="0.5 0.5 0.5 1"/>
      </material>
    </visual>
  </link>
  <joint name="robot_2_base_tapa_joint" type="fixed">
    <origin rpy="0 0 0" xyz="0.0 0 0.38062"/>
    <parent link="robot_2_base_link"/>
    <child link="robot_2_base_chapa"/>
  </joint>
  <!-- LOGO ROBOTNIK IZQUIERDO -->
  <link name="robot_2_base_logo_left">
    <visual>
      <origin rpy="0 0 0" xyz="0 0 0"/>
      <geometry>
        <mesh filename="package://summit_xl_description/meshes/bases/xls/robotnik_logo_chasis.stl"/>
      </geometry>
      <material name="darkgrey">
        <color rgba="0.5 0.5 0.5 1"/>
      </material>
    </visual>
  </link>
  <joint name="robot_2_base_logo_left_joint" type="fixed">
    <origin rpy="0 0 0" xyz="0.0 0.28931 0.29062"/>
    <parent link="robot_2_base_link"/>
    <child link="robot_2_base_logo_left"/>
  </joint>
  <!-- LOGO ROBOTNIK DERECHO -->
  <link name="robot_2_base_logo_right">
    <visual>
      <origin rpy="0 0 0" xyz="0 0 0"/>
      <geometry>
        <mesh filename="package://summit_xl_description/meshes/bases/xls/robotnik_logo_chasis.stl"/>
      </geometry>
      <material name="darkgrey">
        <color rgba="0.5 0.5 0.5 1"/>
      </material>
    </visual>
  </link>
  <joint name="robot_2_base_logo_right_joint" type="fixed">
    <origin rpy="0 0 3.141592653589793" xyz="0.0 -0.28931 0.29062"/>
    <parent link="robot_2_base_link"/>
    <child link="robot_2_base_logo_right"/>
  </joint>
  <!-- LOGO ROBOTNIK FRONTAL -->
  <link name="robot_2_base_logo_front">
    <visual>
      <origin rpy="0 0 0" xyz="0 0 0"/>
      <geometry>
        <mesh filename="package://summit_xl_description/meshes/bases/xls/robotnik_logo_chasis.stl"/>
      </geometry>
      <material name="darkgrey">
        <color rgba="0.5 0.5 0.5 1"/>
      </material>
    </visual>
  </link>
  <joint name="robot_2_base_logo_front_joint" type="fixed">
    <origin rpy="0 0 -1.5707963267948966" xyz="0.345 0.0 0.0"/>
    <parent link="robot_2_base_link"/>
    <child link="robot_2_base_logo_front"/>
  </joint>
  <!-- LOGO ROBOTNIK TRASERO -->
  <link name="robot_2_base_logo_rear">
    <visual>
      <origin rpy="0 0 0" xyz="0 0 0"/>
      <geometry>
        <mesh filename="package://summit_xl_description/meshes/bases/xls/robotnik_logo_chasis.stl"/>
      </geometry>
      <material name="darkgrey">
        <color rgba="0.5 0.5 0.5 1"/>
      </material>
    </visual>
  </link>
  <joint name="robot_2_base_logo_rear_joint" type="fixed">
    <origin rpy="0 0 1.5707963267948966" xyz="-0.345 0.0 0.0"/>
    <parent link="robot_2_base_link"/>
    <child link="robot_2_base_logo_rear"/>
  </joint>
  <!-- DOCKING CONTACT -->
  <link name="robot_2_base_docking_contact">
    </link>
  <joint name="robot_2_base_docking_joint" type="fixed">
    <origin rpy="0 0 0" xyz="0.35 0 0.09"/>
    <parent link="robot_2_base_link"/>
    <child link="robot_2_base_docking_contact"/>
  </joint>
  <link name="robot_2_top_structure">
    <visual>
      <origin rpy="0 0 0" xyz="0 0 0"/>
      <geometry>
        <mesh filename="package://summit_xl_description/meshes/structures/top_structure_roas.STL"/>
      </geometry>
      <material name="silver">
        <color rgba="0.75 0.75 0.75 1"/>
      </material>
    </visual>
    <collision>
      <origin rpy="0 0 0" xyz="0 0 0"/>
      <geometry>
        <mesh filename="package://summit_xl_description/meshes/structures/top_structure_roas.STL"/>
      </geometry>
    </collision>
  </link>
  <!-- sub-link defining detailed meshes for collision with environment -->
  <link name="robot_2_fr3_link0">
    <visual>
      <geometry>
        <mesh filename="package://franka_description/meshes/visual/link0.dae"/>
      </geometry>
    </visual>
    <collision>
      <geometry>
        <mesh filename="package://franka_description/meshes/collision/link0.stl"/>
      </geometry>
    </collision>
    <inertial>
      <origin rpy="0 0 0" xyz="0 0 0"/>
      <mass value="0.629769"/>
      <inertia ixx="0.00315" ixy="8.2904e-07" ixz="0.00015" iyy="0.00388" iyz="8.2299e-06" izz="0.004285"/>
    </inertial>
  </link>
  <!-- sub-link defining coarse geometries of real robot's internal self-collision -->
  <link name="robot_2_fr3_link0_sc">
  </link>
  <!-- fixed joint between both sub-links -->
  <joint name="robot_2_fr3_link0_sc_joint" type="fixed">
    <origin rpy="0 0 0"/>
    <parent link="robot_2_fr3_link0"/>
    <child link="robot_2_fr3_link0_sc"/>
  </joint>
  <!-- sub-link defining detailed meshes for collision with environment -->
  <link name="robot_2_fr3_link1">
    <visual>
      <geometry>
        <mesh filename="package://franka_description/meshes/visual/link1.dae"/>
      </geometry>
    </visual>
    <collision>
      <geometry>
        <mesh filename="package://franka_description/meshes/collision/link1.stl"/>
      </geometry>
    </collision>
    <inertial>
      <origin rpy="0 0 0" xyz="0 0 0"/>
      <mass value="4.970684"/>
      <inertia ixx="0.70337" ixy="-0.000139" ixz="0.006772" iyy="0.70661" iyz="0.019169" izz="0.009117"/>
    </inertial>
  </link>
  <!-- sub-link defining coarse geometries of real robot's internal self-collision -->
  <link name="robot_2_fr3_link1_sc">
  </link>
  <!-- fixed joint between both sub-links -->
  <joint name="robot_2_fr3_link1_sc_joint" type="fixed">
    <origin rpy="0 0 0"/>
    <parent link="robot_2_fr3_link1"/>
    <child link="robot_2_fr3_link1_sc"/>
  </joint>
  <joint name="robot_2_fr3_joint1" type="revolute">
    <origin rpy="0 0 0" xyz="0 0 0.333"/>
    <parent link="robot_2_fr3_link0"/>
    <child link="robot_2_fr3_link1"/>
    <axis xyz="0 0 1"/>
    <limit effort="87.0" lower="-2.3093" upper="2.3093" velocity="2.0"/>
    <safety_controller k_position="100.0" k_velocity="40.0" soft_lower_limit="-2.3093" soft_upper_limit="2.3093"/>
    <dynamics D="1" K="7000" damping="0.003" friction="0.0" mu_coulomb="0" mu_viscous="16"/>
  </joint>
  <!-- sub-link defining detailed meshes for collision with environment -->
  <link name="robot_2_fr3_link2">
    <visual>
      <geometry>
        <mesh filename="package://franka_description/meshes/visual/link2.dae"/>
      </geometry>
    </visual>
    <collision>
      <geometry>
        <mesh filename="package://franka_description/meshes/collision/link2.stl"/>
      </geometry>
    </collision>
    <inertial>
      <origin rpy="0 0 0" xyz="0 0 0"/>
      <mass value="0.646926"/>
      <inertia ixx="0.007962" ixy="-0.003925" ixz="0.010254" iyy="0.02811" iyz="0.000704" izz="0.025995"/>
    </inertial>
  </link>
  <!-- sub-link defining coarse geometries of real robot's internal self-collision -->
  <link name="robot_2_fr3_link2_sc">
  </link>
  <!-- fixed joint between both sub-links -->
  <joint name="robot_2_fr3_link2_sc_joint" type="fixed">
    <origin rpy="0 0 0"/>
    <parent link="robot_2_fr3_link2"/>
    <child link="robot_2_fr3_link2_sc"/>
  </joint>
  <joint name="robot_2_fr3_joint2" type="revolute">
    <origin rpy="-1.5707963267948966 0 0" xyz="0 0 0"/>
    <parent link="robot_2_fr3_link1"/>
    <child link="robot_2_fr3_link2"/>
    <axis xyz="0 0 1"/>
    <limit effort="87.0" lower="-1.5133" upper="1.5133" velocity="1.0"/>
    <safety_controller k_position="100.0" k_velocity="40.0" soft_lower_limit="-1.5133" soft_upper_limit="1.5133"/>
    <dynamics D="1" K="7000" damping="0.003" friction="0.0" mu_coulomb="0" mu_viscous="16"/>
  </joint>
  <!-- sub-link defining detailed meshes for collision with environment -->
  <link name="robot_2_fr3_link3">
    <visual>
      <geometry>
        <mesh filename="package://franka_description/meshes/visual/link3.dae"/>
      </geometry>
    </visual>
    <collision>
      <geometry>
        <mesh filename="package://franka_description/meshes/collision/link3.stl"/>
      </geometry>
    </collision>
    <inertial>
      <origin rpy="0 0 0" xyz="0 0 0"/>
      <mass value="3.228604"/>
      <inertia ixx="0.037242" ixy="-0.004761" ixz="-0.011396" iyy="0.036155" iyz="-0.012805" izz="0.01083"/>
    </inertial>
  </link>
  <!-- sub-link defining coarse geometries of real robot's internal self-collision -->
  <link name="robot_2_fr3_link3_sc">
  </link>
  <!-- fixed joint between both sub-links -->
  <joint name="robot_2_fr3_link3_sc_joint" type="fixed">
    <origin rpy="0 0 0"/>
    <parent link="robot_2_fr3_link3"/>
    <child link="robot_2_fr3_link3_sc"/>
  </joint>
  <joint name="robot_2_fr3_joint3" type="revolute">
    <origin rpy="1.5707963267948966 0 0" xyz="0 -0.316 0"/>
    <parent link="robot_2_fr3_link2"/>
    <child link="robot_2_fr3_link3"/>
    <axis xyz="0 0 1"/>
    <limit effort="87.0" lower="-2.4937" upper="2.4937" velocity="1.5"/>
    <safety_controller k_position="100.0" k_velocity="40.0" soft_lower_limit="-2.4937" soft_upper_limit="2.4937"/>
    <dynamics D="1" K="7000" damping="0.003" friction="0.0" mu_coulomb="0" mu_viscous="16"/>
  </joint>
  <!-- sub-link defining detailed meshes for collision with environment -->
  <link name="robot_2_fr3_link4">
    <visual>
      <geometry>
        <mesh filename="package://franka_description/meshes/visual/link4.dae"/>
      </geometry>
    </visual>
    <collision>
      <geometry>
        <mesh filename="package://franka_description/meshes/collision/link4.stl"/>
      </geometry>
    </collision>
    <inertial>
      <origin rpy="0 0 0" xyz="0 0 0"/>
      <mass value="3.587895"/>
      <inertia ixx="0.025853" ixy="0.007796" ixz="-0.001332" iyy="0.019552" iyz="0.008641" izz="0.028323"/>
    </inertial>
  </link>
  <!-- sub-link defining coarse geometries of real robot's internal self-collision -->
  <link name="robot_2_fr3_link4_sc">
  </link>
  <!-- fixed joint between both sub-links -->
  <joint name="robot_2_fr3_link4_sc_joint" type="fixed">
    <origin rpy="0 0 0"/>
    <parent link="robot_2_fr3_link4"/>
    <child link="robot_2_fr3_link4_sc"/>
  </joint>
  <joint name="robot_2_fr3_joint4" type="revolute">
    <origin rpy="1.5707963267948966 0 0" xyz="0.0825 0 0"/>
    <parent link="robot_2_fr3_link3"/>
    <child link="robot_2_fr3_link4"/>
    <axis xyz="0 0 1"/>
    <limit effort="87.0" lower="-2.7478" upper="-0.4461" velocity="1.25"/>
    <safety_controller k_position="100.0" k_velocity="40.0" soft_lower_limit="-2.7478" soft_upper_limit="-0.4461"/>
    <dynamics D="1" K="7000" damping="0.003" friction="0.0" mu_coulomb="0" mu_viscous="16"/>
  </joint>
  <!-- sub-link defining detailed meshes for collision with environment -->
  <link name="robot_2_fr3_link5">
    <visual>
      <geometry>
        <mesh filename="package://franka_description/meshes/visual/link5.dae"/>
      </geometry>
    </visual>
    <collision>
      <geometry>
        <mesh filename="package://franka_description/meshes/collision/link5.stl"/>
      </geometry>
    </collision>
    <inertial>
      <origin rpy="0 0 0" xyz="0 0 0"/>
      <mass value="1.225946"/>
      <inertia ixx="0.035549" ixy="-0.002117" ixz="-0.004037" iyy="0.029474" iyz="0.000229" izz="0.008627"/>
    </inertial>
  </link>
  <!-- sub-link defining coarse geometries of real robot's internal self-collision -->
  <link name="robot_2_fr3_link5_sc">
  </link>
  <!-- fixed joint between both sub-links -->
  <joint name="robot_2_fr3_link5_sc_joint" type="fixed">
    <origin rpy="0 0 0"/>
    <parent link="robot_2_fr3_link5"/>
    <child link="robot_2_fr3_link5_sc"/>
  </joint>
  <joint name="robot_2_fr3_joint5" type="revolute">
    <origin rpy="-1.5707963267948966 0 0" xyz="-0.0825 0.384 0"/>
    <parent link="robot_2_fr3_link4"/>
    <child link="robot_2_fr3_link5"/>
    <axis xyz="0 0 1"/>
    <limit effort="12.0" lower="-2.48" upper="2.48" velocity="3.0"/>
    <safety_controller k_position="100.0" k_velocity="40.0" soft_lower_limit="-2.48" soft_upper_limit="2.48"/>
    <dynamics D="1" K="7000" damping="0.003" friction="0.0" mu_coulomb="0" mu_viscous="16"/>
  </joint>
  <!-- sub-link defining detailed meshes for collision with environment -->
  <link name="robot_2_fr3_link6">
    <visual>
      <geometry>
        <mesh filename="package://franka_description/meshes/visual/link6.dae"/>
      </geometry>
    </visual>
    <collision>
      <geometry>
        <mesh filename="package://franka_description/meshes/collision/link6.stl"/>
      </geometry>
    </collision>
    <inertial>
      <origin rpy="0 0 0" xyz="0 0 0"/>
      <mass value="1.666555"/>
      <inertia ixx="0.001964" ixy="0.000109" ixz="-0.001158" iyy="0.004354" iyz="0.000341" izz="0.005433"/>
    </inertial>
  </link>
  <!-- sub-link defining coarse geometries of real robot's internal self-collision -->
  <link name="robot_2_fr3_link6_sc">
  </link>
  <!-- fixed joint between both sub-links -->
  <joint name="robot_2_fr3_link6_sc_joint" type="fixed">
    <origin rpy="0 0 0"/>
    <parent link="robot_2_fr3_link6"/>
    <child link="robot_2_fr3_link6_sc"/>
  </joint>
  <joint name="robot_2_fr3_joint6" type="revolute">
    <origin rpy="1.5707963267948966 0 0" xyz="0 0 0"/>
    <parent link="robot_2_fr3_link5"/>
    <child link="robot_2_fr3_link6"/>
    <axis xyz="0 0 1"/>
    <limit effort="12.0" lower="0.8521" upper="4.2094" velocity="1.5"/>
    <safety_controller k_position="100.0" k_velocity="40.0" soft_lower_limit="0.8521" soft_upper_limit="4.2094"/>
    <dynamics D="1" K="7000" damping="0.003" friction="0.0" mu_coulomb="0" mu_viscous="16"/>
  </joint>
  <!-- sub-link defining detailed meshes for collision with environment -->
  <link name="robot_2_fr3_link7">
    <visual>
      <geometry>
        <mesh filename="package://franka_description/meshes/visual/link7.dae"/>
      </geometry>
    </visual>
    <collision>
      <geometry>
        <mesh filename="package://franka_description/meshes/collision/link7.stl"/>
      </geometry>
    </collision>
    <inertial>
      <origin rpy="0 0 0" xyz="0 0 0"/>
      <mass value="0.735522"/>
      <inertia ixx="0.012516" ixy="-0.000428" ixz="-0.001196" iyy="0.010027" iyz="-0.000741" izz="0.004815"/>
    </inertial>
  </link>
  <!-- sub-link defining coarse geometries of real robot's internal self-collision -->
  <link name="robot_2_fr3_link7_sc">
  </link>
  <!-- fixed joint between both sub-links -->
  <joint name="robot_2_fr3_link7_sc_joint" type="fixed">
    <origin rpy="0 0 0.7853981633974483"/>
    <parent link="robot_2_fr3_link7"/>
    <child link="robot_2_fr3_link7_sc"/>
  </joint>
  <joint name="robot_2_fr3_joint7" type="revolute">
    <origin rpy="1.5707963267948966 0 0" xyz="0.088 0 0"/>
    <parent link="robot_2_fr3_link6"/>
    <child link="robot_2_fr3_link7"/>
    <axis xyz="0 0 1"/>
    <limit effort="12.0" lower="-2.6895" upper="2.6895" velocity="3.0"/>
    <safety_controller k_position="100.0" k_velocity="40.0" soft_lower_limit="-2.6895" soft_upper_limit="2.6895"/>
    <dynamics D="1" K="7000" damping="0.003" friction="0.0" mu_coulomb="0" mu_viscous="16"/>
  </joint>
  <link name="robot_2_fr3_link8"/>
  <joint name="robot_2_fr3_joint8" type="fixed">
    <origin rpy="0 0 0" xyz="0 0 0.107"/>
    <parent link="robot_2_fr3_link7"/>
    <child link="robot_2_fr3_link8"/>
  </joint>
  <joint name="robot_2_fr3_hand_joint" type="fixed">
    <parent link="robot_2_fr3_link8"/>
    <child link="robot_2_fr3_hand"/>
    <origin rpy="0 0 -0.7853981633974483" xyz="0 0 0.003"/>
  </joint>
  <!-- sub-link defining detailed meshes for collision with environment -->
  <link name="robot_2_fr3_hand">
    <visual>
      <geometry>
        <mesh filename="package://franka_description/meshes/visual/hand.dae"/>
      </geometry>
    </visual>
    <collision>
      <geometry>
        <mesh filename="package://franka_description/meshes/collision/hand.stl"/>
      </geometry>
    </collision>
    <inertial>
      <origin rpy="0 0 0" xyz="0 0 0"/>
      <mass value="0.73"/>
      <inertia ixx="0.001" ixy="0" ixz="0" iyy="0.0025" iyz="0" izz="0.0017"/>
    </inertial>
  </link>
  <!-- sub-link defining coarse geometries of real robot's internal self-collision -->
  <link name="robot_2_fr3_hand_sc">
  </link>
  <!-- fixed joint between both sub-links -->
  <joint name="robot_2_fr3_hand_sc_joint" type="fixed">
    <origin rpy="0 0 0"/>
    <parent link="robot_2_fr3_hand"/>
    <child link="robot_2_fr3_hand_sc"/>
  </joint>
  <!-- Define the hand_tcp frame -->
  <link name="robot_2_fr3_hand_tcp"/>
  <joint name="robot_2_fr3_hand_tcp_joint" type="fixed">
    <origin rpy="0 0 0" xyz="0 0 0.1034"/>
    <parent link="robot_2_fr3_hand"/>
    <child link="robot_2_fr3_hand_tcp"/>
  </joint>
  <link name="robot_2_fr3_leftfinger">
    <visual>
      <geometry>
        <mesh filename="package://franka_description/meshes/visual/finger.dae"/>
      </geometry>
    </visual>
    <!-- screw mount -->
    <collision>
      <origin rpy="0 0 0" xyz="0 18.5e-3 11e-3"/>
      <geometry>
        <box size="22e-3 15e-3 20e-3"/>
      </geometry>
    </collision>
    <!-- cartriage sledge -->
    <collision>
      <origin rpy="0 0 0" xyz="0 6.8e-3 2.2e-3"/>
      <geometry>
        <box size="22e-3 8.8e-3 3.8e-3"/>
      </geometry>
    </collision>
    <!-- diagonal finger -->
    <collision>
      <origin rpy="0.5235987755982988 0 0" xyz="0 15.9e-3 28.35e-3"/>
      <geometry>
        <box size="17.5e-3 7e-3 23.5e-3"/>
      </geometry>
    </collision>
    <!-- rubber tip with which to grasp -->
    <collision>
      <origin rpy="0 0 0" xyz="0 7.58e-3 45.25e-3"/>
      <geometry>
        <box size="17.5e-3 15.2e-3 18.5e-3"/>
      </geometry>
    </collision>
    <inertial>
      <origin rpy="0 0 0" xyz="0 0 0"/>
      <mass value="0.015"/>
      <inertia ixx="2.3749999999999997e-06" ixy="0" ixz="0" iyy="2.3749999999999997e-06" iyz="0" izz="7.5e-07"/>
    </inertial>
  </link>
  <link name="robot_2_fr3_rightfinger">
    <visual>
      <origin rpy="0 0 3.141592653589793" xyz="0 0 0"/>
      <geometry>
        <mesh filename="package://franka_description/meshes/visual/finger.dae"/>
      </geometry>
    </visual>
    <!-- screw mount -->
    <collision>
      <origin rpy="0 0 0" xyz="0 -18.5e-3 11e-3"/>
      <geometry>
        <box size="22e-3 15e-3 20e-3"/>
      </geometry>
    </collision>
    <!-- cartriage sledge -->
    <collision>
      <origin rpy="0 0 0" xyz="0 -6.8e-3 2.2e-3"/>
      <geometry>
        <box size="22e-3 8.8e-3 3.8e-3"/>
      </geometry>
    </collision>
    <!-- diagonal finger -->
    <collision>
      <origin rpy="-0.5235987755982988 0 0" xyz="0 -15.9e-3 28.35e-3"/>
      <geometry>
        <box size="17.5e-3 7e-3 23.5e-3"/>
      </geometry>
    </collision>
    <!-- rubber tip with which to grasp -->
    <collision>
      <origin rpy="0 0 0" xyz="0 -7.58e-3 45.25e-3"/>
      <geometry>
        <box size="17.5e-3 15.2e-3 18.5e-3"/>
      </geometry>
    </collision>
    <inertial>
      <origin rpy="0 0 0" xyz="0 0 0"/>
      <mass value="0.015"/>
      <inertia ixx="2.3749999999999997e-06" ixy="0" ixz="0" iyy="2.3749999999999997e-06" iyz="0" izz="7.5e-07"/>
    </inertial>
  </link>
  <joint name="robot_2_fr3_finger_joint1" type="prismatic">
    <parent link="robot_2_fr3_hand"/>
    <child link="robot_2_fr3_leftfinger"/>
    <origin rpy="0 0 0" xyz="0 0 0.0584"/>
    <axis xyz="0 1 0"/>
    <limit effort="100" lower="0.0" upper="0.04" velocity="0.2"/>
    <dynamics damping="0.3"/>
  </joint>
  <joint name="robot_2_fr3_finger_joint2" type="prismatic">
    <parent link="robot_2_fr3_hand"/>
    <child link="robot_2_fr3_rightfinger"/>
    <origin rpy="0 0 0" xyz="0 0 0.0584"/>
    <axis xyz="0 -1 0"/>
    <limit effort="100" lower="0.0" upper="0.04" velocity="0.2"/>
    <!-- <mimic joint="${arm_id}_finger_joint1" /> -->
    <dynamics damping="0.3"/>
  </joint>
  <gazebo reference="robot_2_fr3_joint1">
    <!-- Needed for ODE to output external wrenches on joints -->
    <provideFeedback>true</provideFeedback>
  </gazebo>
  <transmission name="robot_2_fr3_joint1_transmission">
    <type>transmission_interface/SimpleTransmission</type>
    <joint name="robot_2_fr3_joint1">
      <hardwareInterface>hardware_interface/EffortJointInterface</hardwareInterface>
    </joint>
    <actuator name="robot_2_fr3_joint1_motor">
      <hardwareInterface>hardware_interface/EffortJointInterface</hardwareInterface>
    </actuator>
  </transmission>
  <gazebo reference="robot_2_fr3_joint2">
    <!-- Needed for ODE to output external wrenches on joints -->
    <provideFeedback>true</provideFeedback>
  </gazebo>
  <transmission name="robot_2_fr3_joint2_transmission">
    <type>transmission_interface/SimpleTransmission</type>
    <joint name="robot_2_fr3_joint2">
      <hardwareInterface>hardware_interface/EffortJointInterface</hardwareInterface>
    </joint>
    <actuator name="robot_2_fr3_joint2_motor">
      <hardwareInterface>hardware_interface/EffortJointInterface</hardwareInterface>
    </actuator>
  </transmission>
  <gazebo reference="robot_2_fr3_joint3">
    <!-- Needed for ODE to output external wrenches on joints -->
    <provideFeedback>true</provideFeedback>
  </gazebo>
  <transmission name="robot_2_fr3_joint3_transmission">
    <type>transmission_interface/SimpleTransmission</type>
    <joint name="robot_2_fr3_joint3">
      <hardwareInterface>hardware_interface/EffortJointInterface</hardwareInterface>
    </joint>
    <actuator name="robot_2_fr3_joint3_motor">
      <hardwareInterface>hardware_interface/EffortJointInterface</hardwareInterface>
    </actuator>
  </transmission>
  <gazebo reference="robot_2_fr3_joint4">
    <!-- Needed for ODE to output external wrenches on joints -->
    <provideFeedback>true</provideFeedback>
  </gazebo>
  <transmission name="robot_2_fr3_joint4_transmission">
    <type>transmission_interface/SimpleTransmission</type>
    <joint name="robot_2_fr3_joint4">
      <hardwareInterface>hardware_interface/EffortJointInterface</hardwareInterface>
    </joint>
    <actuator name="robot_2_fr3_joint4_motor">
      <hardwareInterface>hardware_interface/EffortJointInterface</hardwareInterface>
    </actuator>
  </transmission>
  <gazebo reference="robot_2_fr3_joint5">
    <!-- Needed for ODE to output external wrenches on joints -->
    <provideFeedback>true</provideFeedback>
  </gazebo>
  <transmission name="robot_2_fr3_joint5_transmission">
    <type>transmission_interface/SimpleTransmission</type>
    <joint name="robot_2_fr3_joint5">
      <hardwareInterface>hardware_interface/EffortJointInterface</hardwareInterface>
    </joint>
    <actuator name="robot_2_fr3_joint5_motor">
      <hardwareInterface>hardware_interface/EffortJointInterface</hardwareInterface>
    </actuator>
  </transmission>
  <gazebo reference="robot_2_fr3_joint6">
    <!-- Needed for ODE to output external wrenches on joints -->
    <provideFeedback>true</provideFeedback>
  </gazebo>
  <transmission name="robot_2_fr3_joint6_transmission">
    <type>transmission_interface/SimpleTransmission</type>
    <joint name="robot_2_fr3_joint6">
      <hardwareInterface>hardware_interface/EffortJointInterface</hardwareInterface>
    </joint>
    <actuator name="robot_2_fr3_joint6_motor">
      <hardwareInterface>hardware_interface/EffortJointInterface</hardwareInterface>
    </actuator>
  </transmission>
  <gazebo reference="robot_2_fr3_joint7">
    <!-- Needed for ODE to output external wrenches on joints -->
    <provideFeedback>true</provideFeedback>
  </gazebo>
  <transmission name="robot_2_fr3_joint7_transmission">
    <type>transmission_interface/SimpleTransmission</type>
    <joint name="robot_2_fr3_joint7">
      <hardwareInterface>hardware_interface/EffortJointInterface</hardwareInterface>
    </joint>
    <actuator name="robot_2_fr3_joint7_motor">
      <hardwareInterface>hardware_interface/EffortJointInterface</hardwareInterface>
    </actuator>
  </transmission>
  <gazebo reference="robot_2_fr3_finger_joint1">
    <!-- Needed for ODE to output external wrenches on joints -->
    <provideFeedback>true</provideFeedback>
  </gazebo>
  <transmission name="robot_2_fr3_finger_joint1_transmission">
    <type>transmission_interface/SimpleTransmission</type>
    <joint name="robot_2_fr3_finger_joint1">
      <hardwareInterface>hardware_interface/EffortJointInterface</hardwareInterface>
    </joint>
    <actuator name="robot_2_fr3_finger_joint1_motor">
      <hardwareInterface>hardware_interface/EffortJointInterface</hardwareInterface>
    </actuator>
  </transmission>
  <gazebo reference="robot_2_fr3_finger_joint2">
    <!-- Needed for ODE to output external wrenches on joints -->
    <provideFeedback>true</provideFeedback>
  </gazebo>
  <transmission name="robot_2_fr3_finger_joint2_transmission">
    <type>transmission_interface/SimpleTransmission</type>
    <joint name="robot_2_fr3_finger_joint2">
      <hardwareInterface>hardware_interface/EffortJointInterface</hardwareInterface>
    </joint>
    <actuator name="robot_2_fr3_finger_joint2_motor">
      <hardwareInterface>hardware_interface/EffortJointInterface</hardwareInterface>
    </actuator>
  </transmission>
  <gazebo reference="robot_2_fr3_leftfinger">
    <collision>
      <max_contacts>10</max_contacts>
      <surface>
        <contact>
          <ode>
            <!-- These two parameter need application specific tuning. -->
            <!-- Usually you want no "snap out" velocity and a generous -->
            <!-- penetration depth to keep the grasping stable -->
            <max_vel>0</max_vel>
            <min_depth>0.001</min_depth>
          </ode>
        </contact>
        <friction>
          <ode>
            <mu>1.13</mu>
            <mu2>1.13</mu2>
          </ode>
        </friction>
        <bounce/>
      </surface>
    </collision>
  </gazebo>
  <gazebo reference="robot_2_fr3_rightfinger">
    <collision>
      <max_contacts>10</max_contacts>
      <surface>
        <contact>
          <ode>
            <!-- These two parameter need application specific tuning. -->
            <!-- Usually you want no "snap out" velocity and a generous -->
            <!-- penetration depth to keep the grasping stable -->
            <max_vel>0</max_vel>
            <min_depth>0.001</min_depth>
          </ode>
        </contact>
        <friction>
          <ode>
            <mu>1.13</mu>
            <mu2>1.13</mu2>
          </ode>
        </friction>
        <bounce/>
      </surface>
    </collision>
  </gazebo>
  <joint name="robot_2_fr3_base_joint" type="fixed">
    <origin rpy="0 0 0" xyz="0.23 0 0.66"/>
    <parent link="robot_2_top_structure"/>
    <child link="robot_2_fr3_link0"/>
  </joint>
  <link name="robot_2_ee_link"/>
  <joint name="robot_2_ee_joint" type="fixed">
    <parent link="robot_2_fr3_link8"/>
    <child link="robot_2_ee_link"/>
    <origin rpy="0 0 0" xyz="0 0 0"/>
  </joint>
  <!-- <material name="aluminum">
      <color rgba="0.5 0.5 0.5 1"/>
    </material> -->
  <!-- camera body, with origin at bottom screw mount -->
  <joint name="robot_2_camera_joint" type="fixed">
    <origin rpy="0 -1.57 3.14" xyz="0.0377 0 0.0105"/>
    <parent link="robot_2_camera_bracket"/>
    <child link="robot_2_camera_bottom_screw_frame"/>
  </joint>
  <link name="robot_2_camera_bottom_screw_frame"/>
  <joint name="robot_2_camera_link_joint" type="fixed">
    <origin rpy="0 0 0" xyz="0.010600000000000002 0.0175 0.0125"/>
    <parent link="robot_2_camera_bottom_screw_frame"/>
    <child link="robot_2_camera_link"/>
  </joint>
  <link name="robot_2_camera_link">
    <visual>
      <origin rpy="1.5707963267948966 0 1.5707963267948966" xyz="0.0043 -0.0175 0"/>
      <geometry>
        <mesh filename="package://summit_xl_description/meshes/structures/d435.dae"/>
      </geometry>
    </visual>
    <collision>
      <origin rpy="0 0 0" xyz="0 -0.0175 0"/>
      <geometry>
        <box size="0.02505 0.09 0.025"/>
      </geometry>
    </collision>
    <inertial>
      <mass value="0.564"/>
      <origin xyz="0 0 0"/>
      <inertia ixx="0.003881243" ixy="0.0" ixz="0.0" iyy="0.000498940" iyz="0.0" izz="0.003879257"/>
    </inertial>
  </link>
  <!-- Use the nominal extrinsics between camera frames if the calibrated extrinsics aren't being published. e.g. running the device in simulation  -->
  <!--xacro:if value="$(arg use_nominal_extrinsics)"-->
  <!-- camera depth joints and links -->
  <joint name="robot_2_camera_depth_joint" type="fixed">
    <origin rpy="0 0 0" xyz="0 0 0"/>
    <parent link="robot_2_camera_link"/>
    <child link="robot_2_camera_depth_frame"/>
  </joint>
  <link name="robot_2_camera_depth_frame"/>
  <joint name="robot_2_camera_depth_optical_joint" type="fixed">
    <origin rpy="-1.5707963267948966 0 -1.5707963267948966" xyz="0 0 0"/>
    <parent link="robot_2_camera_depth_frame"/>
    <child link="robot_2_camera_depth_optical_frame"/>
  </joint>
  <link name="robot_2_camera_depth_optical_frame"/>
  <!-- camera left IR joints and links -->
  <joint name="robot_2_camera_infra1_joint" type="fixed">
    <origin rpy="0 0 0" xyz="0 0.0 0"/>
    <parent link="robot_2_camera_link"/>
    <child link="robot_2_camera_infra1_frame"/>
  </joint>
  <link name="robot_2_camera_infra1_frame"/>
  <joint name="robot_2_camera_infra1_optical_joint" type="fixed">
    <origin rpy="-1.5707963267948966 0 -1.5707963267948966" xyz="0 0 0"/>
    <parent link="robot_2_camera_infra1_frame"/>
    <child link="robot_2_camera_infra1_optical_frame"/>
  </joint>
  <link name="robot_2_camera_infra1_optical_frame"/>
  <!-- camera right IR joints and links -->
  <joint name="robot_2_camera_infra2_joint" type="fixed">
    <origin rpy="0 0 0" xyz="0 -0.05 0"/>
    <parent link="robot_2_camera_link"/>
    <child link="robot_2_camera_infra2_frame"/>
  </joint>
  <link name="robot_2_camera_infra2_frame"/>
  <joint name="robot_2_camera_infra2_optical_joint" type="fixed">
    <origin rpy="-1.5707963267948966 0 -1.5707963267948966" xyz="0 0 0"/>
    <parent link="robot_2_camera_infra2_frame"/>
    <child link="robot_2_camera_infra2_optical_frame"/>
  </joint>
  <link name="robot_2_camera_infra2_optical_frame"/>
  <!-- camera color joints and links -->
  <joint name="robot_2_camera_color_joint" type="fixed">
    <origin rpy="0 0 0" xyz="0 0.015 0"/>
    <parent link="robot_2_camera_link"/>
    <child link="robot_2_camera_color_frame"/>
  </joint>
  <link name="robot_2_camera_color_frame"/>
  <joint name="robot_2_camera_color_optical_joint" type="fixed">
    <origin rpy="-1.5707963267948966 0 -1.5707963267948966" xyz="0 0 0"/>
    <parent link="robot_2_camera_color_frame"/>
    <child link="robot_2_camera_color_optical_frame"/>
  </joint>
  <link name="robot_2_camera_color_optical_frame"/>
  <!--/xacro:if-->
  <!-- Gazebo part -->
  <!-- D435 Gazebo -->
  <gazebo reference="robot_2_camera_link">
    <sensor name="robot_2_camera" type="depth">
      <update_rate>30</update_rate>
      <visualize>true</visualize>
      <camera>
        <horizontal_fov>1.047198</horizontal_fov>
        <image>
          <width>640</width>
          <height>480</height>
          <format>R8G8B8</format>
        </image>
        <clip>
          <near>0.05</near>
          <far>3</far>
        </clip>
      </camera>
      <plugin filename="libgazebo_ros_openni_kinect.so" name="camera_controller">
        <baseline>0.2</baseline>
        <alwaysOn>true</alwaysOn>
        <updateRate>1.0</updateRate>
        <cameraName>camera</cameraName>
        <imageTopicName>/camera/color/image_raw</imageTopicName>
        <cameraInfoTopicName>/camera/color/camera_info</cameraInfoTopicName>
        <depthImageTopicName>/camera/depth/image_raw</depthImageTopicName>
        <depthImageInfoTopicName>/camera/depth/camera_info</depthImageInfoTopicName>
        <pointCloudTopicName>/camera/depth/points</pointCloudTopicName>
        <frameName>d435_link</frameName>
        <pointCloudCutoff>0.5</pointCloudCutoff>
        <pointCloudCutoffMax>3.0</pointCloudCutoffMax>
        <distortionK1>0.00000001</distortionK1>
        <distortionK2>0.00000001</distortionK2>
        <distortionK3>0.00000001</distortionK3>
        <distortionT1>0.00000001</distortionT1>
        <distortionT2>0.00000001</distortionT2>
        <CxPrime>0</CxPrime>
        <Cx>0</Cx>
        <Cy>0</Cy>
        <focalLength>0</focalLength>
        <hackBaseline>0</hackBaseline>
      </plugin>
    </sensor>
  </gazebo>
  <link name="robot_2_d435_link"/>
  <joint name="robot_2_d435_joint" type="fixed">
    <parent link="robot_2_camera_link"/>
    <child link="robot_2_d435_link"/>
    <origin rpy="-1.5707963267948966 0 -1.5707963267948966" xyz="0.0 0.0 0.0"/>
  </joint>
  <link name="robot_2_camera_bracket">
    <visual>
      <origin rpy="0 0 0" xyz="0 0 0"/>
      <geometry>
        <mesh filename="package://summit_xl_description/meshes/structures/hand_camera.STL"/>
      </geometry>
      <material name="silver">
        <color rgba="0.75 0.75 0.75 1"/>
      </material>
    </visual>
    <collision>
      <origin rpy="0 0 0" xyz="0 0 0"/>
      <geometry>
        <mesh filename="package://summit_xl_description/meshes/structures/hand_camera.STL"/>
      </geometry>
      <material name="silver">
        <color rgba="0.75 0.75 0.75 1"/>
      </material>
    </collision>
  </link>
  <joint name="robot_2_camera_bracket_joint" type="fixed">
    <parent link="robot_2_ee_link"/>
    <child link="robot_2_camera_bracket"/>
    <origin rpy="0 0 -0.785" xyz="0 0 0.003"/>
  </joint>
  <joint name="robot_2_top_structure_joint" type="fixed">
    <origin rpy="0 0 0" xyz="0 0 0"/>
    <parent link="robot_2_base_footprint"/>
    <child link="robot_2_top_structure"/>
  </joint>
  <joint name="robot_2_front_right_wheel_joint" type="continuous">
    <parent link="robot_2_base_link"/>
    <child link="robot_2_front_right_wheel_link"/>
    <origin rpy="0 0 0" xyz="0.2225 -0.2045 0.0"/>
    <axis rpy="0 0 0" xyz="0 1 0"/>
    <limit effort="100" velocity="100"/>
    <joint_properties damping="0.0" friction="0.0"/>
  </joint>
  <link name="robot_2_front_right_wheel_link">
    <visual>
      <origin rpy="0 0 0" xyz="0 0 0"/>
      <geometry>
        <mesh filename="package://summit_xl_description/meshes/wheels/omni_wheel_2.dae"/>
      </geometry>
      <material name="darkgrey">
        <color rgba="0.2 0.2 0.2 1"/>
      </material>
    </visual>
    <collision>
      <origin rpy="1.5707963267948966 0 0" xyz="0 0 0"/>
      <geometry>
        <!--sphere radius="${omni_wheel_radius}" /-->
        <!--
          <xacro:if value="${reflect}">
              <mesh filename="package://summit_xl_description/meshes/wheels/omni_wheel_1.dae" />
          </xacro:if>
          <xacro:unless value="${reflect}">
              <mesh filename="package://summit_xl_description/meshes/wheels/omni_wheel_2.dae" />
					</xacro:unless>
-->
        <cylinder length="0.087" radius="0.127"/>
        <!-- sphere radius="${omni_wheel_radius}"/-->
      </geometry>
    </collision>
    <inertial>
      <mass value="6.5"/>
      <origin xyz="0 0 0"/>
      <inertia ixx="0.0303095" ixy="0" ixz="0" iyy="0.05241925" iyz="0" izz="0.0303095"/>
    </inertial>
  </link>
  <!-- Transmission is important to link the joints and the controller (see summit_xl_control/config/summit_xl_control.yaml)-->
  <transmission name="robot_2_front_right_wheel_joint_trans">
    <type>transmission_interface/SimpleTransmission</type>
    <joint name="robot_2_front_right_wheel_joint">
      <hardwareInterface>hardware_interface/VelocityJointInterface</hardwareInterface>
    </joint>
    <actuator name="robot_2_front_right_wheel_joint_motor">
      <mechanicalReduction>1</mechanicalReduction>
      <motorTorqueConstant>20</motorTorqueConstant>
    </actuator>
  </transmission>
  <gazebo reference="robot_2_front_right_wheel_link">
    <mu1 value="0.01"/>
    <mu2 value="0.01"/>
    <kp value="10000000.0"/>
    <kd value="1.0"/>
    <fdir1 value="1 0 0"/>
    <turnGravityOff>false</turnGravityOff>
  </gazebo>
  <joint name="robot_2_front_left_wheel_joint" type="continuous">
    <parent link="robot_2_base_link"/>
    <child link="robot_2_front_left_wheel_link"/>
    <origin rpy="0 0 0" xyz="0.2225 0.2045 0.0"/>
    <axis rpy="0 0 0" xyz="0 1 0"/>
    <limit effort="100" velocity="100"/>
    <joint_properties damping="0.0" friction="0.0"/>
  </joint>
  <link name="robot_2_front_left_wheel_link">
    <visual>
      <origin rpy="0 0 0" xyz="0 0 0"/>
      <geometry>
        <mesh filename="package://summit_xl_description/meshes/wheels/omni_wheel_1.dae"/>
      </geometry>
      <material name="darkgrey">
        <color rgba="0.2 0.2 0.2 1"/>
      </material>
    </visual>
    <collision>
      <origin rpy="1.5707963267948966 0 0" xyz="0 0 0"/>
      <geometry>
        <!--sphere radius="${omni_wheel_radius}" /-->
        <!--
          <xacro:if value="${reflect}">
              <mesh filename="package://summit_xl_description/meshes/wheels/omni_wheel_1.dae" />
          </xacro:if>
          <xacro:unless value="${reflect}">
              <mesh filename="package://summit_xl_description/meshes/wheels/omni_wheel_2.dae" />
					</xacro:unless>
-->
        <cylinder length="0.087" radius="0.127"/>
        <!-- sphere radius="${omni_wheel_radius}"/-->
      </geometry>
    </collision>
    <inertial>
      <mass value="6.5"/>
      <origin xyz="0 0 0"/>
      <inertia ixx="0.0303095" ixy="0" ixz="0" iyy="0.05241925" iyz="0" izz="0.0303095"/>
    </inertial>
  </link>
  <!-- Transmission is important to link the joints and the controller (see summit_xl_control/config/summit_xl_control.yaml)-->
  <transmission name="robot_2_front_left_wheel_joint_trans">
    <type>transmission_interface/SimpleTransmission</type>
    <joint name="robot_2_front_left_wheel_joint">
      <hardwareInterface>hardware_interface/VelocityJointInterface</hardwareInterface>
    </joint>
    <actuator name="robot_2_front_left_wheel_joint_motor">
      <mechanicalReduction>1</mechanicalReduction>
      <motorTorqueConstant>20</motorTorqueConstant>
    </actuator>
  </transmission>
  <gazebo reference="robot_2_front_left_wheel_link">
    <mu1 value="0.01"/>
    <mu2 value="0.01"/>
    <kp value="10000000.0"/>
    <kd value="1.0"/>
    <fdir1 value="1 0 0"/>
    <turnGravityOff>false</turnGravityOff>
  </gazebo>
  <joint name="robot_2_back_left_wheel_joint" type="continuous">
    <parent link="robot_2_base_link"/>
    <child link="robot_2_back_left_wheel_link"/>
    <origin rpy="0 0 0" xyz="-0.2225 0.2045 0.0"/>
    <axis rpy="0 0 0" xyz="0 1 0"/>
    <limit effort="100" velocity="100"/>
    <joint_properties damping="0.0" friction="0.0"/>
  </joint>
  <link name="robot_2_back_left_wheel_link">
    <visual>
      <origin rpy="0 0 0" xyz="0 0 0"/>
      <geometry>
        <mesh filename="package://summit_xl_description/meshes/wheels/omni_wheel_1.dae"/>
      </geometry>
      <material name="darkgrey">
        <color rgba="0.2 0.2 0.2 1"/>
      </material>
    </visual>
    <collision>
      <origin rpy="1.5707963267948966 0 0" xyz="0 0 0"/>
      <geometry>
        <!--sphere radius="${omni_wheel_radius}" /-->
        <!--
          <xacro:if value="${reflect}">
              <mesh filename="package://summit_xl_description/meshes/wheels/omni_wheel_1.dae" />
          </xacro:if>
          <xacro:unless value="${reflect}">
              <mesh filename="package://summit_xl_description/meshes/wheels/omni_wheel_2.dae" />
					</xacro:unless>
-->
        <cylinder length="0.087" radius="0.127"/>
        <!-- sphere radius="${omni_wheel_radius}"/-->
      </geometry>
    </collision>
    <inertial>
      <mass value="6.5"/>
      <origin xyz="0 0 0"/>
      <inertia ixx="0.0303095" ixy="0" ixz="0" iyy="0.05241925" iyz="0" izz="0.0303095"/>
    </inertial>
  </link>
  <!-- Transmission is important to link the joints and the controller (see summit_xl_control/config/summit_xl_control.yaml)-->
  <transmission name="robot_2_back_left_wheel_joint_trans">
    <type>transmission_interface/SimpleTransmission</type>
    <joint name="robot_2_back_left_wheel_joint">
      <hardwareInterface>hardware_interface/VelocityJointInterface</hardwareInterface>
    </joint>
    <actuator name="robot_2_back_left_wheel_joint_motor">
      <mechanicalReduction>1</mechanicalReduction>
      <motorTorqueConstant>20</motorTorqueConstant>
    </actuator>
  </transmission>
  <gazebo reference="robot_2_back_left_wheel_link">
    <mu1 value="0.01"/>
    <mu2 value="0.01"/>
    <kp value="10000000.0"/>
    <kd value="1.0"/>
    <fdir1 value="1 0 0"/>
    <turnGravityOff>false</turnGravityOff>
  </gazebo>
  <joint name="robot_2_back_right_wheel_joint" type="continuous">
    <parent link="robot_2_base_link"/>
    <child link="robot_2_back_right_wheel_link"/>
    <origin rpy="0 0 0" xyz="-0.2225 -0.2045 0.0"/>
    <axis rpy="0 0 0" xyz="0 1 0"/>
    <limit effort="100" velocity="100"/>
    <joint_properties damping="0.0" friction="0.0"/>
  </joint>
  <link name="robot_2_back_right_wheel_link">
    <visual>
      <origin rpy="0 0 0" xyz="0 0 0"/>
      <geometry>
        <mesh filename="package://summit_xl_description/meshes/wheels/omni_wheel_2.dae"/>
      </geometry>
      <material name="darkgrey">
        <color rgba="0.2 0.2 0.2 1"/>
      </material>
    </visual>
    <collision>
      <origin rpy="1.5707963267948966 0 0" xyz="0 0 0"/>
      <geometry>
        <!--sphere radius="${omni_wheel_radius}" /-->
        <!--
          <xacro:if value="${reflect}">
              <mesh filename="package://summit_xl_description/meshes/wheels/omni_wheel_1.dae" />
          </xacro:if>
          <xacro:unless value="${reflect}">
              <mesh filename="package://summit_xl_description/meshes/wheels/omni_wheel_2.dae" />
					</xacro:unless>
-->
        <cylinder length="0.087" radius="0.127"/>
        <!-- sphere radius="${omni_wheel_radius}"/-->
      </geometry>
    </collision>
    <inertial>
      <mass value="6.5"/>
      <origin xyz="0 0 0"/>
      <inertia ixx="0.0303095" ixy="0" ixz="0" iyy="0.05241925" iyz="0" izz="0.0303095"/>
    </inertial>
  </link>
  <!-- Transmission is important to link the joints and the controller (see summit_xl_control/config/summit_xl_control.yaml)-->
  <transmission name="robot_2_back_right_wheel_joint_trans">
    <type>transmission_interface/SimpleTransmission</type>
    <joint name="robot_2_back_right_wheel_joint">
      <hardwareInterface>hardware_interface/VelocityJointInterface</hardwareInterface>
    </joint>
    <actuator name="robot_2_back_right_wheel_joint_motor">
      <mechanicalReduction>1</mechanicalReduction>
      <motorTorqueConstant>20</motorTorqueConstant>
    </actuator>
  </transmission>
  <gazebo reference="robot_2_back_right_wheel_link">
    <mu1 value="0.01"/>
    <mu2 value="0.01"/>
    <kp value="10000000.0"/>
    <kd value="1.0"/>
    <fdir1 value="1 0 0"/>
    <turnGravityOff>false</turnGravityOff>
  </gazebo>
  <!-- IMU -->
  <!-- <xacro:sensor_imu prefix="${prefix}_imu" parent="${prefix}_base_link" topic="imu/data_raw">
			<origin xyz="${imu_offset_x} ${imu_offset_y} ${imu_offset_z}" rpy="0 0 0"/>
		</xacro:sensor_imu> -->
  <!-- SENSORS -->
  <!-- <xacro:sensor_sick_tim571 prefix="${prefix}_front_laser" parent="${prefix}_base_link" prefix_topic="front_laser" gpu="$(arg gpu)">
			<origin xyz="${front_laser_offset_x} ${front_laser_offset_y} ${front_laser_offset_z}" rpy="0 ${-PI} ${3/4*PI}" />
		</xacro:sensor_sick_tim571>
		<xacro:sensor_sick_tim571 prefix="${prefix}_rear_laser" parent="${prefix}_base_link" prefix_topic="rear_laser" gpu="$(arg gpu)">
			<origin xyz="${rear_laser_offset_x} ${rear_laser_offset_y} ${rear_laser_offset_z}" rpy="0 ${-PI} ${-1/4*PI}" />
		</xacro:sensor_sick_tim571> -->
  <!--xacro:sensor_axis_m5013 prefix="${prefix}_front_ptz_camera" parent="${prefix}_base_link">
			<origin xyz="${front_ptz_camera_offset_x} ${front_ptz_camera_offset_y} ${front_ptz_camera_offset_z}" rpy="${-PI/2} 0 0"/>
		</xacro:sensor_axis_m5013-->
  <!--xacro:sensor_axis_m5013 prefix="${prefix}_rear_ptz_camera" parent="${prefix}_base_link">
			<origin xyz="${rear_ptz_camera_offset_x} ${rear_ptz_camera_offset_y} ${rear_ptz_camera_offset_z}" rpy="${-PI/2} 0 ${PI}"/>
		</xacro:sensor_axis_m5013-->
  <!-- <xacro:sensor_orbbec_astra prefix="${prefix}_front_rgbd_camera" parent="${prefix}_base_link" prefix_topic="front_rgbd_camera">
			<origin xyz="${front_rgbd_camera_offset_x} ${front_rgbd_camera_offset_y} ${front_rgbd_camera_offset_z}" rpy="0 0 0"/>
		</xacro:sensor_orbbec_astra> -->
  <gazebo>
    <plugin filename="libgazebo_ros_control.so" name="ros_control">
      <controlPeriod>0.001</controlPeriod>
      <robotSimType>gazebo_ros_control/DefaultRobotHWSim</robotSimType>
      <legacyModeNS>true</legacyModeNS>
    </plugin>
  </gazebo>
  <gazebo reference="base_footprint">
    <material>Gazebo/Green</material>
  </gazebo>
  <!-- in kg 6.5 -->
  <!-- in kg-->
  <!-- Import all available sensors -->
  <!-- <xacro:include filename="$(find robotnik_sensors)/urdf/all_sensors.urdf.xacro" /> -->
  <!-- Flag to select the high or low quality model -->
  <!-- *************** -->
  <!-- Robots Elements -->
  <!-- *************** -->
  <!-- Here we create the robot elements using the xacro:macros imported at the beggining of this file -->
  <link name="robot_3_base_footprint">
    <visual>
      <origin rpy="0 0 0" xyz="0 0 0"/>
      <geometry>
        <box size="0.001 0.001 0.001"/>
      </geometry>
    </visual>
  </link>
  <joint name="robot_3_base_footprint_joint" type="fixed">
    <origin rpy="0 0 0" xyz="0 0 0.127"/>
    <!-- ${wheel_radius} property must be defined inside wheel description -->
    <parent link="robot_3_base_footprint"/>
    <child link="robot_3_base_link"/>
  </joint>
  <!-- BASE_LINK -->
  <link name="robot_3_base_link">
    <inertial>
      <mass value="125.0"/>
      <!-- origin : 125.0 -->
      <origin xyz="0 0 0"/>
      <inertia ixx="1.391" ixy="0.004" ixz="0.0" iyy="6.853" iyz="0.0" izz="6.125"/>
    </inertial>
    <visual>
      <origin rpy="0 0 0" xyz="0 0 0"/>
      <geometry>
        <mesh filename="package://summit_xl_description/meshes/bases/xls/summit_xls_chassis.stl"/>
      </geometry>
      <material name="black">
        <color rgba="0.0 0.0 0.0 1"/>
      </material>
    </visual>
    <collision>
      <origin rpy="0 0 0 " xyz="0 0 0"/>
      <geometry>
        <mesh filename="package://summit_xl_description/meshes/bases/xls/summit_xls_chassis.dae"/>
      </geometry>
    </collision>
  </link>
  <gazebo reference="robot_3_base_link">
    <material>Gazebo/Black</material>
  </gazebo>
  <!-- CHAPAS INOX TAPAS -->
  <link name="robot_3_base_chapa">
    <visual>
      <origin rpy="0 0 0" xyz="0 0 0"/>
      <geometry>
        <mesh filename="package://summit_xl_description/meshes/bases/xls/summit_xls_chapas_inox_tapas.stl"/>
      </geometry>
      <material name="darkgrey">
        <color rgba="0.5 0.5 0.5 1"/>
      </material>
    </visual>
  </link>
  <joint name="robot_3_base_tapa_joint" type="fixed">
    <origin rpy="0 0 0" xyz="0.0 0 0.38062"/>
    <parent link="robot_3_base_link"/>
    <child link="robot_3_base_chapa"/>
  </joint>
  <!-- LOGO ROBOTNIK IZQUIERDO -->
  <link name="robot_3_base_logo_left">
    <visual>
      <origin rpy="0 0 0" xyz="0 0 0"/>
      <geometry>
        <mesh filename="package://summit_xl_description/meshes/bases/xls/robotnik_logo_chasis.stl"/>
      </geometry>
      <material name="darkgrey">
        <color rgba="0.5 0.5 0.5 1"/>
      </material>
    </visual>
  </link>
  <joint name="robot_3_base_logo_left_joint" type="fixed">
    <origin rpy="0 0 0" xyz="0.0 0.28931 0.29062"/>
    <parent link="robot_3_base_link"/>
    <child link="robot_3_base_logo_left"/>
  </joint>
  <!-- LOGO ROBOTNIK DERECHO -->
  <link name="robot_3_base_logo_right">
    <visual>
      <origin rpy="0 0 0" xyz="0 0 0"/>
      <geometry>
        <mesh filename="package://summit_xl_description/meshes/bases/xls/robotnik_logo_chasis.stl"/>
      </geometry>
      <material name="darkgrey">
        <color rgba="0.5 0.5 0.5 1"/>
      </material>
    </visual>
  </link>
  <joint name="robot_3_base_logo_right_joint" type="fixed">
    <origin rpy="0 0 3.141592653589793" xyz="0.0 -0.28931 0.29062"/>
    <parent link="robot_3_base_link"/>
    <child link="robot_3_base_logo_right"/>
  </joint>
  <!-- LOGO ROBOTNIK FRONTAL -->
  <link name="robot_3_base_logo_front">
    <visual>
      <origin rpy="0 0 0" xyz="0 0 0"/>
      <geometry>
        <mesh filename="package://summit_xl_description/meshes/bases/xls/robotnik_logo_chasis.stl"/>
      </geometry>
      <material name="darkgrey">
        <color rgba="0.5 0.5 0.5 1"/>
      </material>
    </visual>
  </link>
  <joint name="robot_3_base_logo_front_joint" type="fixed">
    <origin rpy="0 0 -1.5707963267948966" xyz="0.345 0.0 0.0"/>
    <parent link="robot_3_base_link"/>
    <child link="robot_3_base_logo_front"/>
  </joint>
  <!-- LOGO ROBOTNIK TRASERO -->
  <link name="robot_3_base_logo_rear">
    <visual>
      <origin rpy="0 0 0" xyz="0 0 0"/>
      <geometry>
        <mesh filename="package://summit_xl_description/meshes/bases/xls/robotnik_logo_chasis.stl"/>
      </geometry>
      <material name="darkgrey">
        <color rgba="0.5 0.5 0.5 1"/>
      </material>
    </visual>
  </link>
  <joint name="robot_3_base_logo_rear_joint" type="fixed">
    <origin rpy="0 0 1.5707963267948966" xyz="-0.345 0.0 0.0"/>
    <parent link="robot_3_base_link"/>
    <child link="robot_3_base_logo_rear"/>
  </joint>
  <!-- DOCKING CONTACT -->
  <link name="robot_3_base_docking_contact">
    </link>
  <joint name="robot_3_base_docking_joint" type="fixed">
    <origin rpy="0 0 0" xyz="0.35 0 0.09"/>
    <parent link="robot_3_base_link"/>
    <child link="robot_3_base_docking_contact"/>
  </joint>
  <link name="robot_3_top_structure">
    <visual>
      <origin rpy="0 0 0" xyz="0 0 0"/>
      <geometry>
        <mesh filename="package://summit_xl_description/meshes/structures/top_structure_roas.STL"/>
      </geometry>
      <material name="silver">
        <color rgba="0.75 0.75 0.75 1"/>
      </material>
    </visual>
    <collision>
      <origin rpy="0 0 0" xyz="0 0 0"/>
      <geometry>
        <mesh filename="package://summit_xl_description/meshes/structures/top_structure_roas.STL"/>
      </geometry>
    </collision>
  </link>
  <!-- sub-link defining detailed meshes for collision with environment -->
  <link name="robot_3_fr3_link0">
    <visual>
      <geometry>
        <mesh filename="package://franka_description/meshes/visual/link0.dae"/>
      </geometry>
    </visual>
    <collision>
      <geometry>
        <mesh filename="package://franka_description/meshes/collision/link0.stl"/>
      </geometry>
    </collision>
    <inertial>
      <origin rpy="0 0 0" xyz="0 0 0"/>
      <mass value="0.629769"/>
      <inertia ixx="0.00315" ixy="8.2904e-07" ixz="0.00015" iyy="0.00388" iyz="8.2299e-06" izz="0.004285"/>
    </inertial>
  </link>
  <!-- sub-link defining coarse geometries of real robot's internal self-collision -->
  <link name="robot_3_fr3_link0_sc">
  </link>
  <!-- fixed joint between both sub-links -->
  <joint name="robot_3_fr3_link0_sc_joint" type="fixed">
    <origin rpy="0 0 0"/>
    <parent link="robot_3_fr3_link0"/>
    <child link="robot_3_fr3_link0_sc"/>
  </joint>
  <!-- sub-link defining detailed meshes for collision with environment -->
  <link name="robot_3_fr3_link1">
    <visual>
      <geometry>
        <mesh filename="package://franka_description/meshes/visual/link1.dae"/>
      </geometry>
    </visual>
    <collision>
      <geometry>
        <mesh filename="package://franka_description/meshes/collision/link1.stl"/>
      </geometry>
    </collision>
    <inertial>
      <origin rpy="0 0 0" xyz="0 0 0"/>
      <mass value="4.970684"/>
      <inertia ixx="0.70337" ixy="-0.000139" ixz="0.006772" iyy="0.70661" iyz="0.019169" izz="0.009117"/>
    </inertial>
  </link>
  <!-- sub-link defining coarse geometries of real robot's internal self-collision -->
  <link name="robot_3_fr3_link1_sc">
  </link>
  <!-- fixed joint between both sub-links -->
  <joint name="robot_3_fr3_link1_sc_joint" type="fixed">
    <origin rpy="0 0 0"/>
    <parent link="robot_3_fr3_link1"/>
    <child link="robot_3_fr3_link1_sc"/>
  </joint>
  <joint name="robot_3_fr3_joint1" type="revolute">
    <origin rpy="0 0 0" xyz="0 0 0.333"/>
    <parent link="robot_3_fr3_link0"/>
    <child link="robot_3_fr3_link1"/>
    <axis xyz="0 0 1"/>
    <limit effort="87.0" lower="-2.3093" upper="2.3093" velocity="2.0"/>
    <safety_controller k_position="100.0" k_velocity="40.0" soft_lower_limit="-2.3093" soft_upper_limit="2.3093"/>
    <dynamics D="1" K="7000" damping="0.003" friction="0.0" mu_coulomb="0" mu_viscous="16"/>
  </joint>
  <!-- sub-link defining detailed meshes for collision with environment -->
  <link name="robot_3_fr3_link2">
    <visual>
      <geometry>
        <mesh filename="package://franka_description/meshes/visual/link2.dae"/>
      </geometry>
    </visual>
    <collision>
      <geometry>
        <mesh filename="package://franka_description/meshes/collision/link2.stl"/>
      </geometry>
    </collision>
    <inertial>
      <origin rpy="0 0 0" xyz="0 0 0"/>
      <mass value="0.646926"/>
      <inertia ixx="0.007962" ixy="-0.003925" ixz="0.010254" iyy="0.02811" iyz="0.000704" izz="0.025995"/>
    </inertial>
  </link>
  <!-- sub-link defining coarse geometries of real robot's internal self-collision -->
  <link name="robot_3_fr3_link2_sc">
  </link>
  <!-- fixed joint between both sub-links -->
  <joint name="robot_3_fr3_link2_sc_joint" type="fixed">
    <origin rpy="0 0 0"/>
    <parent link="robot_3_fr3_link2"/>
    <child link="robot_3_fr3_link2_sc"/>
  </joint>
  <joint name="robot_3_fr3_joint2" type="revolute">
    <origin rpy="-1.5707963267948966 0 0" xyz="0 0 0"/>
    <parent link="robot_3_fr3_link1"/>
    <child link="robot_3_fr3_link2"/>
    <axis xyz="0 0 1"/>
    <limit effort="87.0" lower="-1.5133" upper="1.5133" velocity="1.0"/>
    <safety_controller k_position="100.0" k_velocity="40.0" soft_lower_limit="-1.5133" soft_upper_limit="1.5133"/>
    <dynamics D="1" K="7000" damping="0.003" friction="0.0" mu_coulomb="0" mu_viscous="16"/>
  </joint>
  <!-- sub-link defining detailed meshes for collision with environment -->
  <link name="robot_3_fr3_link3">
    <visual>
      <geometry>
        <mesh filename="package://franka_description/meshes/visual/link3.dae"/>
      </geometry>
    </visual>
    <collision>
      <geometry>
        <mesh filename="package://franka_description/meshes/collision/link3.stl"/>
      </geometry>
    </collision>
    <inertial>
      <origin rpy="0 0 0" xyz="0 0 0"/>
      <mass value="3.228604"/>
      <inertia ixx="0.037242" ixy="-0.004761" ixz="-0.011396" iyy="0.036155" iyz="-0.012805" izz="0.01083"/>
    </inertial>
  </link>
  <!-- sub-link defining coarse geometries of real robot's internal self-collision -->
  <link name="robot_3_fr3_link3_sc">
  </link>
  <!-- fixed joint between both sub-links -->
  <joint name="robot_3_fr3_link3_sc_joint" type="fixed">
    <origin rpy="0 0 0"/>
    <parent link="robot_3_fr3_link3"/>
    <child link="robot_3_fr3_link3_sc"/>
  </joint>
  <joint name="robot_3_fr3_joint3" type="revolute">
    <origin rpy="1.5707963267948966 0 0" xyz="0 -0.316 0"/>
    <parent link="robot_3_fr3_link2"/>
    <child link="robot_3_fr3_link3"/>
    <axis xyz="0 0 1"/>
    <limit effort="87.0" lower="-2.4937" upper="2.4937" velocity="1.5"/>
    <safety_controller k_position="100.0" k_velocity="40.0" soft_lower_limit="-2.4937" soft_upper_limit="2.4937"/>
    <dynamics D="1" K="7000" damping="0.003" friction="0.0" mu_coulomb="0" mu_viscous="16"/>
  </joint>
  <!-- sub-link defining detailed meshes for collision with environment -->
  <link name="robot_3_fr3_link4">
    <visual>
      <geometry>
        <mesh filename="package://franka_description/meshes/visual/link4.dae"/>
      </geometry>
    </visual>
    <collision>
      <geometry>
        <mesh filename="package://franka_description/meshes/collision/link4.stl"/>
      </geometry>
    </collision>
    <inertial>
      <origin rpy="0 0 0" xyz="0 0 0"/>
      <mass value="3.587895"/>
      <inertia ixx="0.025853" ixy="0.007796" ixz="-0.001332" iyy="0.019552" iyz="0.008641" izz="0.028323"/>
    </inertial>
  </link>
  <!-- sub-link defining coarse geometries of real robot's internal self-collision -->
  <link name="robot_3_fr3_link4_sc">
  </link>
  <!-- fixed joint between both sub-links -->
  <joint name="robot_3_fr3_link4_sc_joint" type="fixed">
    <origin rpy="0 0 0"/>
    <parent link="robot_3_fr3_link4"/>
    <child link="robot_3_fr3_link4_sc"/>
  </joint>
  <joint name="robot_3_fr3_joint4" type="revolute">
    <origin rpy="1.5707963267948966 0 0" xyz="0.0825 0 0"/>
    <parent link="robot_3_fr3_link3"/>
    <child link="robot_3_fr3_link4"/>
    <axis xyz="0 0 1"/>
    <limit effort="87.0" lower="-2.7478" upper="-0.4461" velocity="1.25"/>
    <safety_controller k_position="100.0" k_velocity="40.0" soft_lower_limit="-2.7478" soft_upper_limit="-0.4461"/>
    <dynamics D="1" K="7000" damping="0.003" friction="0.0" mu_coulomb="0" mu_viscous="16"/>
  </joint>
  <!-- sub-link defining detailed meshes for collision with environment -->
  <link name="robot_3_fr3_link5">
    <visual>
      <geometry>
        <mesh filename="package://franka_description/meshes/visual/link5.dae"/>
      </geometry>
    </visual>
    <collision>
      <geometry>
        <mesh filename="package://franka_description/meshes/collision/link5.stl"/>
      </geometry>
    </collision>
    <inertial>
      <origin rpy="0 0 0" xyz="0 0 0"/>
      <mass value="1.225946"/>
      <inertia ixx="0.035549" ixy="-0.002117" ixz="-0.004037" iyy="0.029474" iyz="0.000229" izz="0.008627"/>
    </inertial>
  </link>
  <!-- sub-link defining coarse geometries of real robot's internal self-collision -->
  <link name="robot_3_fr3_link5_sc">
  </link>
  <!-- fixed joint between both sub-links -->
  <joint name="robot_3_fr3_link5_sc_joint" type="fixed">
    <origin rpy="0 0 0"/>
    <parent link="robot_3_fr3_link5"/>
    <child link="robot_3_fr3_link5_sc"/>
  </joint>
  <joint name="robot_3_fr3_joint5" type="revolute">
    <origin rpy="-1.5707963267948966 0 0" xyz="-0.0825 0.384 0"/>
    <parent link="robot_3_fr3_link4"/>
    <child link="robot_3_fr3_link5"/>
    <axis xyz="0 0 1"/>
    <limit effort="12.0" lower="-2.48" upper="2.48" velocity="3.0"/>
    <safety_controller k_position="100.0" k_velocity="40.0" soft_lower_limit="-2.48" soft_upper_limit="2.48"/>
    <dynamics D="1" K="7000" damping="0.003" friction="0.0" mu_coulomb="0" mu_viscous="16"/>
  </joint>
  <!-- sub-link defining detailed meshes for collision with environment -->
  <link name="robot_3_fr3_link6">
    <visual>
      <geometry>
        <mesh filename="package://franka_description/meshes/visual/link6.dae"/>
      </geometry>
    </visual>
    <collision>
      <geometry>
        <mesh filename="package://franka_description/meshes/collision/link6.stl"/>
      </geometry>
    </collision>
    <inertial>
      <origin rpy="0 0 0" xyz="0 0 0"/>
      <mass value="1.666555"/>
      <inertia ixx="0.001964" ixy="0.000109" ixz="-0.001158" iyy="0.004354" iyz="0.000341" izz="0.005433"/>
    </inertial>
  </link>
  <!-- sub-link defining coarse geometries of real robot's internal self-collision -->
  <link name="robot_3_fr3_link6_sc">
  </link>
  <!-- fixed joint between both sub-links -->
  <joint name="robot_3_fr3_link6_sc_joint" type="fixed">
    <origin rpy="0 0 0"/>
    <parent link="robot_3_fr3_link6"/>
    <child link="robot_3_fr3_link6_sc"/>
  </joint>
  <joint name="robot_3_fr3_joint6" type="revolute">
    <origin rpy="1.5707963267948966 0 0" xyz="0 0 0"/>
    <parent link="robot_3_fr3_link5"/>
    <child link="robot_3_fr3_link6"/>
    <axis xyz="0 0 1"/>
    <limit effort="12.0" lower="0.8521" upper="4.2094" velocity="1.5"/>
    <safety_controller k_position="100.0" k_velocity="40.0" soft_lower_limit="0.8521" soft_upper_limit="4.2094"/>
    <dynamics D="1" K="7000" damping="0.003" friction="0.0" mu_coulomb="0" mu_viscous="16"/>
  </joint>
  <!-- sub-link defining detailed meshes for collision with environment -->
  <link name="robot_3_fr3_link7">
    <visual>
      <geometry>
        <mesh filename="package://franka_description/meshes/visual/link7.dae"/>
      </geometry>
    </visual>
    <collision>
      <geometry>
        <mesh filename="package://franka_description/meshes/collision/link7.stl"/>
      </geometry>
    </collision>
    <inertial>
      <origin rpy="0 0 0" xyz="0 0 0"/>
      <mass value="0.735522"/>
      <inertia ixx="0.012516" ixy="-0.000428" ixz="-0.001196" iyy="0.010027" iyz="-0.000741" izz="0.004815"/>
    </inertial>
  </link>
  <!-- sub-link defining coarse geometries of real robot's internal self-collision -->
  <link name="robot_3_fr3_link7_sc">
  </link>
  <!-- fixed joint between both sub-links -->
  <joint name="robot_3_fr3_link7_sc_joint" type="fixed">
    <origin rpy="0 0 0.7853981633974483"/>
    <parent link="robot_3_fr3_link7"/>
    <child link="robot_3_fr3_link7_sc"/>
  </joint>
  <joint name="robot_3_fr3_joint7" type="revolute">
    <origin rpy="1.5707963267948966 0 0" xyz="0.088 0 0"/>
    <parent link="robot_3_fr3_link6"/>
    <child link="robot_3_fr3_link7"/>
    <axis xyz="0 0 1"/>
    <limit effort="12.0" lower="-2.6895" upper="2.6895" velocity="3.0"/>
    <safety_controller k_position="100.0" k_velocity="40.0" soft_lower_limit="-2.6895" soft_upper_limit="2.6895"/>
    <dynamics D="1" K="7000" damping="0.003" friction="0.0" mu_coulomb="0" mu_viscous="16"/>
  </joint>
  <link name="robot_3_fr3_link8"/>
  <joint name="robot_3_fr3_joint8" type="fixed">
    <origin rpy="0 0 0" xyz="0 0 0.107"/>
    <parent link="robot_3_fr3_link7"/>
    <child link="robot_3_fr3_link8"/>
  </joint>
  <joint name="robot_3_fr3_hand_joint" type="fixed">
    <parent link="robot_3_fr3_link8"/>
    <child link="robot_3_fr3_hand"/>
    <origin rpy="0 0 -0.7853981633974483" xyz="0 0 0.003"/>
  </joint>
  <!-- sub-link defining detailed meshes for collision with environment -->
  <link name="robot_3_fr3_hand">
    <visual>
      <geometry>
        <mesh filename="package://franka_description/meshes/visual/hand.dae"/>
      </geometry>
    </visual>
    <collision>
      <geometry>
        <mesh filename="package://franka_description/meshes/collision/hand.stl"/>
      </geometry>
    </collision>
    <inertial>
      <origin rpy="0 0 0" xyz="0 0 0"/>
      <mass value="0.73"/>
      <inertia ixx="0.001" ixy="0" ixz="0" iyy="0.0025" iyz="0" izz="0.0017"/>
    </inertial>
  </link>
  <!-- sub-link defining coarse geometries of real robot's internal self-collision -->
  <link name="robot_3_fr3_hand_sc">
  </link>
  <!-- fixed joint between both sub-links -->
  <joint name="robot_3_fr3_hand_sc_joint" type="fixed">
    <origin rpy="0 0 0"/>
    <parent link="robot_3_fr3_hand"/>
    <child link="robot_3_fr3_hand_sc"/>
  </joint>
  <!-- Define the hand_tcp frame -->
  <link name="robot_3_fr3_hand_tcp"/>
  <joint name="robot_3_fr3_hand_tcp_joint" type="fixed">
    <origin rpy="0 0 0" xyz="0 0 0.1034"/>
    <parent link="robot_3_fr3_hand"/>
    <child link="robot_3_fr3_hand_tcp"/>
  </joint>
  <link name="robot_3_fr3_leftfinger">
    <visual>
      <geometry>
        <mesh filename="package://franka_description/meshes/visual/finger.dae"/>
      </geometry>
    </visual>
    <!-- screw mount -->
    <collision>
      <origin rpy="0 0 0" xyz="0 18.5e-3 11e-3"/>
      <geometry>
        <box size="22e-3 15e-3 20e-3"/>
      </geometry>
    </collision>
    <!-- cartriage sledge -->
    <collision>
      <origin rpy="0 0 0" xyz="0 6.8e-3 2.2e-3"/>
      <geometry>
        <box size="22e-3 8.8e-3 3.8e-3"/>
      </geometry>
    </collision>
    <!-- diagonal finger -->
    <collision>
      <origin rpy="0.5235987755982988 0 0" xyz="0 15.9e-3 28.35e-3"/>
      <geometry>
        <box size="17.5e-3 7e-3 23.5e-3"/>
      </geometry>
    </collision>
    <!-- rubber tip with which to grasp -->
    <collision>
      <origin rpy="0 0 0" xyz="0 7.58e-3 45.25e-3"/>
      <geometry>
        <box size="17.5e-3 15.2e-3 18.5e-3"/>
      </geometry>
    </collision>
    <inertial>
      <origin rpy="0 0 0" xyz="0 0 0"/>
      <mass value="0.015"/>
      <inertia ixx="2.3749999999999997e-06" ixy="0" ixz="0" iyy="2.3749999999999997e-06" iyz="0" izz="7.5e-07"/>
    </inertial>
  </link>
  <link name="robot_3_fr3_rightfinger">
    <visual>
      <origin rpy="0 0 3.141592653589793" xyz="0 0 0"/>
      <geometry>
        <mesh filename="package://franka_description/meshes/visual/finger.dae"/>
      </geometry>
    </visual>
    <!-- screw mount -->
    <collision>
      <origin rpy="0 0 0" xyz="0 -18.5e-3 11e-3"/>
      <geometry>
        <box size="22e-3 15e-3 20e-3"/>
      </geometry>
    </collision>
    <!-- cartriage sledge -->
    <collision>
      <origin rpy="0 0 0" xyz="0 -6.8e-3 2.2e-3"/>
      <geometry>
        <box size="22e-3 8.8e-3 3.8e-3"/>
      </geometry>
    </collision>
    <!-- diagonal finger -->
    <collision>
      <origin rpy="-0.5235987755982988 0 0" xyz="0 -15.9e-3 28.35e-3"/>
      <geometry>
        <box size="17.5e-3 7e-3 23.5e-3"/>
      </geometry>
    </collision>
    <!-- rubber tip with which to grasp -->
    <collision>
      <origin rpy="0 0 0" xyz="0 -7.58e-3 45.25e-3"/>
      <geometry>
        <box size="17.5e-3 15.2e-3 18.5e-3"/>
      </geometry>
    </collision>
    <inertial>
      <origin rpy="0 0 0" xyz="0 0 0"/>
      <mass value="0.015"/>
      <inertia ixx="2.3749999999999997e-06" ixy="0" ixz="0" iyy="2.3749999999999997e-06" iyz="0" izz="7.5e-07"/>
    </inertial>
  </link>
  <joint name="robot_3_fr3_finger_joint1" type="prismatic">
    <parent link="robot_3_fr3_hand"/>
    <child link="robot_3_fr3_leftfinger"/>
    <origin rpy="0 0 0" xyz="0 0 0.0584"/>
    <axis xyz="0 1 0"/>
    <limit effort="100" lower="0.0" upper="0.04" velocity="0.2"/>
    <dynamics damping="0.3"/>
  </joint>
  <joint name="robot_3_fr3_finger_joint2" type="prismatic">
    <parent link="robot_3_fr3_hand"/>
    <child link="robot_3_fr3_rightfinger"/>
    <origin rpy="0 0 0" xyz="0 0 0.0584"/>
    <axis xyz="0 -1 0"/>
    <limit effort="100" lower="0.0" upper="0.04" velocity="0.2"/>
    <!-- <mimic joint="${arm_id}_finger_joint1" /> -->
    <dynamics damping="0.3"/>
  </joint>
  <gazebo reference="robot_3_fr3_joint1">
    <!-- Needed for ODE to output external wrenches on joints -->
    <provideFeedback>true</provideFeedback>
  </gazebo>
  <transmission name="robot_3_fr3_joint1_transmission">
    <type>transmission_interface/SimpleTransmission</type>
    <joint name="robot_3_fr3_joint1">
      <hardwareInterface>hardware_interface/EffortJointInterface</hardwareInterface>
    </joint>
    <actuator name="robot_3_fr3_joint1_motor">
      <hardwareInterface>hardware_interface/EffortJointInterface</hardwareInterface>
    </actuator>
  </transmission>
  <gazebo reference="robot_3_fr3_joint2">
    <!-- Needed for ODE to output external wrenches on joints -->
    <provideFeedback>true</provideFeedback>
  </gazebo>
  <transmission name="robot_3_fr3_joint2_transmission">
    <type>transmission_interface/SimpleTransmission</type>
    <joint name="robot_3_fr3_joint2">
      <hardwareInterface>hardware_interface/EffortJointInterface</hardwareInterface>
    </joint>
    <actuator name="robot_3_fr3_joint2_motor">
      <hardwareInterface>hardware_interface/EffortJointInterface</hardwareInterface>
    </actuator>
  </transmission>
  <gazebo reference="robot_3_fr3_joint3">
    <!-- Needed for ODE to output external wrenches on joints -->
    <provideFeedback>true</provideFeedback>
  </gazebo>
  <transmission name="robot_3_fr3_joint3_transmission">
    <type>transmission_interface/SimpleTransmission</type>
    <joint name="robot_3_fr3_joint3">
      <hardwareInterface>hardware_interface/EffortJointInterface</hardwareInterface>
    </joint>
    <actuator name="robot_3_fr3_joint3_motor">
      <hardwareInterface>hardware_interface/EffortJointInterface</hardwareInterface>
    </actuator>
  </transmission>
  <gazebo reference="robot_3_fr3_joint4">
    <!-- Needed for ODE to output external wrenches on joints -->
    <provideFeedback>true</provideFeedback>
  </gazebo>
  <transmission name="robot_3_fr3_joint4_transmission">
    <type>transmission_interface/SimpleTransmission</type>
    <joint name="robot_3_fr3_joint4">
      <hardwareInterface>hardware_interface/EffortJointInterface</hardwareInterface>
    </joint>
    <actuator name="robot_3_fr3_joint4_motor">
      <hardwareInterface>hardware_interface/EffortJointInterface</hardwareInterface>
    </actuator>
  </transmission>
  <gazebo reference="robot_3_fr3_joint5">
    <!-- Needed for ODE to output external wrenches on joints -->
    <provideFeedback>true</provideFeedback>
  </gazebo>
  <transmission name="robot_3_fr3_joint5_transmission">
    <type>transmission_interface/SimpleTransmission</type>
    <joint name="robot_3_fr3_joint5">
      <hardwareInterface>hardware_interface/EffortJointInterface</hardwareInterface>
    </joint>
    <actuator name="robot_3_fr3_joint5_motor">
      <hardwareInterface>hardware_interface/EffortJointInterface</hardwareInterface>
    </actuator>
  </transmission>
  <gazebo reference="robot_3_fr3_joint6">
    <!-- Needed for ODE to output external wrenches on joints -->
    <provideFeedback>true</provideFeedback>
  </gazebo>
  <transmission name="robot_3_fr3_joint6_transmission">
    <type>transmission_interface/SimpleTransmission</type>
    <joint name="robot_3_fr3_joint6">
      <hardwareInterface>hardware_interface/EffortJointInterface</hardwareInterface>
    </joint>
    <actuator name="robot_3_fr3_joint6_motor">
      <hardwareInterface>hardware_interface/EffortJointInterface</hardwareInterface>
    </actuator>
  </transmission>
  <gazebo reference="robot_3_fr3_joint7">
    <!-- Needed for ODE to output external wrenches on joints -->
    <provideFeedback>true</provideFeedback>
  </gazebo>
  <transmission name="robot_3_fr3_joint7_transmission">
    <type>transmission_interface/SimpleTransmission</type>
    <joint name="robot_3_fr3_joint7">
      <hardwareInterface>hardware_interface/EffortJointInterface</hardwareInterface>
    </joint>
    <actuator name="robot_3_fr3_joint7_motor">
      <hardwareInterface>hardware_interface/EffortJointInterface</hardwareInterface>
    </actuator>
  </transmission>
  <gazebo reference="robot_3_fr3_finger_joint1">
    <!-- Needed for ODE to output external wrenches on joints -->
    <provideFeedback>true</provideFeedback>
  </gazebo>
  <transmission name="robot_3_fr3_finger_joint1_transmission">
    <type>transmission_interface/SimpleTransmission</type>
    <joint name="robot_3_fr3_finger_joint1">
      <hardwareInterface>hardware_interface/EffortJointInterface</hardwareInterface>
    </joint>
    <actuator name="robot_3_fr3_finger_joint1_motor">
      <hardwareInterface>hardware_interface/EffortJointInterface</hardwareInterface>
    </actuator>
  </transmission>
  <gazebo reference="robot_3_fr3_finger_joint2">
    <!-- Needed for ODE to output external wrenches on joints -->
    <provideFeedback>true</provideFeedback>
  </gazebo>
  <transmission name="robot_3_fr3_finger_joint2_transmission">
    <type>transmission_interface/SimpleTransmission</type>
    <joint name="robot_3_fr3_finger_joint2">
      <hardwareInterface>hardware_interface/EffortJointInterface</hardwareInterface>
    </joint>
    <actuator name="robot_3_fr3_finger_joint2_motor">
      <hardwareInterface>hardware_interface/EffortJointInterface</hardwareInterface>
    </actuator>
  </transmission>
  <gazebo reference="robot_3_fr3_leftfinger">
    <collision>
      <max_contacts>10</max_contacts>
      <surface>
        <contact>
          <ode>
            <!-- These two parameter need application specific tuning. -->
            <!-- Usually you want no "snap out" velocity and a generous -->
            <!-- penetration depth to keep the grasping stable -->
            <max_vel>0</max_vel>
            <min_depth>0.001</min_depth>
          </ode>
        </contact>
        <friction>
          <ode>
            <mu>1.13</mu>
            <mu2>1.13</mu2>
          </ode>
        </friction>
        <bounce/>
      </surface>
    </collision>
  </gazebo>
  <gazebo reference="robot_3_fr3_rightfinger">
    <collision>
      <max_contacts>10</max_contacts>
      <surface>
        <contact>
          <ode>
            <!-- These two parameter need application specific tuning. -->
            <!-- Usually you want no "snap out" velocity and a generous -->
            <!-- penetration depth to keep the grasping stable -->
            <max_vel>0</max_vel>
            <min_depth>0.001</min_depth>
          </ode>
        </contact>
        <friction>
          <ode>
            <mu>1.13</mu>
            <mu2>1.13</mu2>
          </ode>
        </friction>
        <bounce/>
      </surface>
    </collision>
  </gazebo>
  <joint name="robot_3_fr3_base_joint" type="fixed">
    <origin rpy="0 0 0" xyz="0.23 0 0.66"/>
    <parent link="robot_3_top_structure"/>
    <child link="robot_3_fr3_link0"/>
  </joint>
  <link name="robot_3_ee_link"/>
  <joint name="robot_3_ee_joint" type="fixed">
    <parent link="robot_3_fr3_link8"/>
    <child link="robot_3_ee_link"/>
    <origin rpy="0 0 0" xyz="0 0 0"/>
  </joint>
  <!-- <material name="aluminum">
      <color rgba="0.5 0.5 0.5 1"/>
    </material> -->
  <!-- camera body, with origin at bottom screw mount -->
  <joint name="robot_3_camera_joint" type="fixed">
    <origin rpy="0 -1.57 3.14" xyz="0.0377 0 0.0105"/>
    <parent link="robot_3_camera_bracket"/>
    <child link="robot_3_camera_bottom_screw_frame"/>
  </joint>
  <link name="robot_3_camera_bottom_screw_frame"/>
  <joint name="robot_3_camera_link_joint" type="fixed">
    <origin rpy="0 0 0" xyz="0.010600000000000002 0.0175 0.0125"/>
    <parent link="robot_3_camera_bottom_screw_frame"/>
    <child link="robot_3_camera_link"/>
  </joint>
  <link name="robot_3_camera_link">
    <visual>
      <origin rpy="1.5707963267948966 0 1.5707963267948966" xyz="0.0043 -0.0175 0"/>
      <geometry>
        <mesh filename="package://summit_xl_description/meshes/structures/d435.dae"/>
      </geometry>
    </visual>
    <collision>
      <origin rpy="0 0 0" xyz="0 -0.0175 0"/>
      <geometry>
        <box size="0.02505 0.09 0.025"/>
      </geometry>
    </collision>
    <inertial>
      <mass value="0.564"/>
      <origin xyz="0 0 0"/>
      <inertia ixx="0.003881243" ixy="0.0" ixz="0.0" iyy="0.000498940" iyz="0.0" izz="0.003879257"/>
    </inertial>
  </link>
  <!-- Use the nominal extrinsics between camera frames if the calibrated extrinsics aren't being published. e.g. running the device in simulation  -->
  <!--xacro:if value="$(arg use_nominal_extrinsics)"-->
  <!-- camera depth joints and links -->
  <joint name="robot_3_camera_depth_joint" type="fixed">
    <origin rpy="0 0 0" xyz="0 0 0"/>
    <parent link="robot_3_camera_link"/>
    <child link="robot_3_camera_depth_frame"/>
  </joint>
  <link name="robot_3_camera_depth_frame"/>
  <joint name="robot_3_camera_depth_optical_joint" type="fixed">
    <origin rpy="-1.5707963267948966 0 -1.5707963267948966" xyz="0 0 0"/>
    <parent link="robot_3_camera_depth_frame"/>
    <child link="robot_3_camera_depth_optical_frame"/>
  </joint>
  <link name="robot_3_camera_depth_optical_frame"/>
  <!-- camera left IR joints and links -->
  <joint name="robot_3_camera_infra1_joint" type="fixed">
    <origin rpy="0 0 0" xyz="0 0.0 0"/>
    <parent link="robot_3_camera_link"/>
    <child link="robot_3_camera_infra1_frame"/>
  </joint>
  <link name="robot_3_camera_infra1_frame"/>
  <joint name="robot_3_camera_infra1_optical_joint" type="fixed">
    <origin rpy="-1.5707963267948966 0 -1.5707963267948966" xyz="0 0 0"/>
    <parent link="robot_3_camera_infra1_frame"/>
    <child link="robot_3_camera_infra1_optical_frame"/>
  </joint>
  <link name="robot_3_camera_infra1_optical_frame"/>
  <!-- camera right IR joints and links -->
  <joint name="robot_3_camera_infra2_joint" type="fixed">
    <origin rpy="0 0 0" xyz="0 -0.05 0"/>
    <parent link="robot_3_camera_link"/>
    <child link="robot_3_camera_infra2_frame"/>
  </joint>
  <link name="robot_3_camera_infra2_frame"/>
  <joint name="robot_3_camera_infra2_optical_joint" type="fixed">
    <origin rpy="-1.5707963267948966 0 -1.5707963267948966" xyz="0 0 0"/>
    <parent link="robot_3_camera_infra2_frame"/>
    <child link="robot_3_camera_infra2_optical_frame"/>
  </joint>
  <link name="robot_3_camera_infra2_optical_frame"/>
  <!-- camera color joints and links -->
  <joint name="robot_3_camera_color_joint" type="fixed">
    <origin rpy="0 0 0" xyz="0 0.015 0"/>
    <parent link="robot_3_camera_link"/>
    <child link="robot_3_camera_color_frame"/>
  </joint>
  <link name="robot_3_camera_color_frame"/>
  <joint name="robot_3_camera_color_optical_joint" type="fixed">
    <origin rpy="-1.5707963267948966 0 -1.5707963267948966" xyz="0 0 0"/>
    <parent link="robot_3_camera_color_frame"/>
    <child link="robot_3_camera_color_optical_frame"/>
  </joint>
  <link name="robot_3_camera_color_optical_frame"/>
  <!--/xacro:if-->
  <!-- Gazebo part -->
  <!-- D435 Gazebo -->
  <gazebo reference="robot_3_camera_link">
    <sensor name="robot_3_camera" type="depth">
      <update_rate>30</update_rate>
      <visualize>true</visualize>
      <camera>
        <horizontal_fov>1.047198</horizontal_fov>
        <image>
          <width>640</width>
          <height>480</height>
          <format>R8G8B8</format>
        </image>
        <clip>
          <near>0.05</near>
          <far>3</far>
        </clip>
      </camera>
      <plugin filename="libgazebo_ros_openni_kinect.so" name="camera_controller">
        <baseline>0.2</baseline>
        <alwaysOn>true</alwaysOn>
        <updateRate>1.0</updateRate>
        <cameraName>camera</cameraName>
        <imageTopicName>/camera/color/image_raw</imageTopicName>
        <cameraInfoTopicName>/camera/color/camera_info</cameraInfoTopicName>
        <depthImageTopicName>/camera/depth/image_raw</depthImageTopicName>
        <depthImageInfoTopicName>/camera/depth/camera_info</depthImageInfoTopicName>
        <pointCloudTopicName>/camera/depth/points</pointCloudTopicName>
        <frameName>d435_link</frameName>
        <pointCloudCutoff>0.5</pointCloudCutoff>
        <pointCloudCutoffMax>3.0</pointCloudCutoffMax>
        <distortionK1>0.00000001</distortionK1>
        <distortionK2>0.00000001</distortionK2>
        <distortionK3>0.00000001</distortionK3>
        <distortionT1>0.00000001</distortionT1>
        <distortionT2>0.00000001</distortionT2>
        <CxPrime>0</CxPrime>
        <Cx>0</Cx>
        <Cy>0</Cy>
        <focalLength>0</focalLength>
        <hackBaseline>0</hackBaseline>
      </plugin>
    </sensor>
  </gazebo>
  <link name="robot_3_d435_link"/>
  <joint name="robot_3_d435_joint" type="fixed">
    <parent link="robot_3_camera_link"/>
    <child link="robot_3_d435_link"/>
    <origin rpy="-1.5707963267948966 0 -1.5707963267948966" xyz="0.0 0.0 0.0"/>
  </joint>
  <link name="robot_3_camera_bracket">
    <visual>
      <origin rpy="0 0 0" xyz="0 0 0"/>
      <geometry>
        <mesh filename="package://summit_xl_description/meshes/structures/hand_camera.STL"/>
      </geometry>
      <material name="silver">
        <color rgba="0.75 0.75 0.75 1"/>
      </material>
    </visual>
    <collision>
      <origin rpy="0 0 0" xyz="0 0 0"/>
      <geometry>
        <mesh filename="package://summit_xl_description/meshes/structures/hand_camera.STL"/>
      </geometry>
      <material name="silver">
        <color rgba="0.75 0.75 0.75 1"/>
      </material>
    </collision>
  </link>
  <joint name="robot_3_camera_bracket_joint" type="fixed">
    <parent link="robot_3_ee_link"/>
    <child link="robot_3_camera_bracket"/>
    <origin rpy="0 0 -0.785" xyz="0 0 0.003"/>
  </joint>
  <joint name="robot_3_top_structure_joint" type="fixed">
    <origin rpy="0 0 0" xyz="0 0 0"/>
    <parent link="robot_3_base_footprint"/>
    <child link="robot_3_top_structure"/>
  </joint>
  <joint name="robot_3_front_right_wheel_joint" type="continuous">
    <parent link="robot_3_base_link"/>
    <child link="robot_3_front_right_wheel_link"/>
    <origin rpy="0 0 0" xyz="0.2225 -0.2045 0.0"/>
    <axis rpy="0 0 0" xyz="0 1 0"/>
    <limit effort="100" velocity="100"/>
    <joint_properties damping="0.0" friction="0.0"/>
  </joint>
  <link name="robot_3_front_right_wheel_link">
    <visual>
      <origin rpy="0 0 0" xyz="0 0 0"/>
      <geometry>
        <mesh filename="package://summit_xl_description/meshes/wheels/omni_wheel_2.dae"/>
      </geometry>
      <material name="darkgrey">
        <color rgba="0.2 0.2 0.2 1"/>
      </material>
    </visual>
    <collision>
      <origin rpy="1.5707963267948966 0 0" xyz="0 0 0"/>
      <geometry>
        <!--sphere radius="${omni_wheel_radius}" /-->
        <!--
          <xacro:if value="${reflect}">
              <mesh filename="package://summit_xl_description/meshes/wheels/omni_wheel_1.dae" />
          </xacro:if>
          <xacro:unless value="${reflect}">
              <mesh filename="package://summit_xl_description/meshes/wheels/omni_wheel_2.dae" />
					</xacro:unless>
-->
        <cylinder length="0.087" radius="0.127"/>
        <!-- sphere radius="${omni_wheel_radius}"/-->
      </geometry>
    </collision>
    <inertial>
      <mass value="6.5"/>
      <origin xyz="0 0 0"/>
      <inertia ixx="0.0303095" ixy="0" ixz="0" iyy="0.05241925" iyz="0" izz="0.0303095"/>
    </inertial>
  </link>
  <!-- Transmission is important to link the joints and the controller (see summit_xl_control/config/summit_xl_control.yaml)-->
  <transmission name="robot_3_front_right_wheel_joint_trans">
    <type>transmission_interface/SimpleTransmission</type>
    <joint name="robot_3_front_right_wheel_joint">
      <hardwareInterface>hardware_interface/VelocityJointInterface</hardwareInterface>
    </joint>
    <actuator name="robot_3_front_right_wheel_joint_motor">
      <mechanicalReduction>1</mechanicalReduction>
      <motorTorqueConstant>20</motorTorqueConstant>
    </actuator>
  </transmission>
  <gazebo reference="robot_3_front_right_wheel_link">
    <mu1 value="0.01"/>
    <mu2 value="0.01"/>
    <kp value="10000000.0"/>
    <kd value="1.0"/>
    <fdir1 value="1 0 0"/>
    <turnGravityOff>false</turnGravityOff>
  </gazebo>
  <joint name="robot_3_front_left_wheel_joint" type="continuous">
    <parent link="robot_3_base_link"/>
    <child link="robot_3_front_left_wheel_link"/>
    <origin rpy="0 0 0" xyz="0.2225 0.2045 0.0"/>
    <axis rpy="0 0 0" xyz="0 1 0"/>
    <limit effort="100" velocity="100"/>
    <joint_properties damping="0.0" friction="0.0"/>
  </joint>
  <link name="robot_3_front_left_wheel_link">
    <visual>
      <origin rpy="0 0 0" xyz="0 0 0"/>
      <geometry>
        <mesh filename="package://summit_xl_description/meshes/wheels/omni_wheel_1.dae"/>
      </geometry>
      <material name="darkgrey">
        <color rgba="0.2 0.2 0.2 1"/>
      </material>
    </visual>
    <collision>
      <origin rpy="1.5707963267948966 0 0" xyz="0 0 0"/>
      <geometry>
        <!--sphere radius="${omni_wheel_radius}" /-->
        <!--
          <xacro:if value="${reflect}">
              <mesh filename="package://summit_xl_description/meshes/wheels/omni_wheel_1.dae" />
          </xacro:if>
          <xacro:unless value="${reflect}">
              <mesh filename="package://summit_xl_description/meshes/wheels/omni_wheel_2.dae" />
					</xacro:unless>
-->
        <cylinder length="0.087" radius="0.127"/>
        <!-- sphere radius="${omni_wheel_radius}"/-->
      </geometry>
    </collision>
    <inertial>
      <mass value="6.5"/>
      <origin xyz="0 0 0"/>
      <inertia ixx="0.0303095" ixy="0" ixz="0" iyy="0.05241925" iyz="0" izz="0.0303095"/>
    </inertial>
  </link>
  <!-- Transmission is important to link the joints and the controller (see summit_xl_control/config/summit_xl_control.yaml)-->
  <transmission name="robot_3_front_left_wheel_joint_trans">
    <type>transmission_interface/SimpleTransmission</type>
    <joint name="robot_3_front_left_wheel_joint">
      <hardwareInterface>hardware_interface/VelocityJointInterface</hardwareInterface>
    </joint>
    <actuator name="robot_3_front_left_wheel_joint_motor">
      <mechanicalReduction>1</mechanicalReduction>
      <motorTorqueConstant>20</motorTorqueConstant>
    </actuator>
  </transmission>
  <gazebo reference="robot_3_front_left_wheel_link">
    <mu1 value="0.01"/>
    <mu2 value="0.01"/>
    <kp value="10000000.0"/>
    <kd value="1.0"/>
    <fdir1 value="1 0 0"/>
    <turnGravityOff>false</turnGravityOff>
  </gazebo>
  <joint name="robot_3_back_left_wheel_joint" type="continuous">
    <parent link="robot_3_base_link"/>
    <child link="robot_3_back_left_wheel_link"/>
    <origin rpy="0 0 0" xyz="-0.2225 0.2045 0.0"/>
    <axis rpy="0 0 0" xyz="0 1 0"/>
    <limit effort="100" velocity="100"/>
    <joint_properties damping="0.0" friction="0.0"/>
  </joint>
  <link name="robot_3_back_left_wheel_link">
    <visual>
      <origin rpy="0 0 0" xyz="0 0 0"/>
      <geometry>
        <mesh filename="package://summit_xl_description/meshes/wheels/omni_wheel_1.dae"/>
      </geometry>
      <material name="darkgrey">
        <color rgba="0.2 0.2 0.2 1"/>
      </material>
    </visual>
    <collision>
      <origin rpy="1.5707963267948966 0 0" xyz="0 0 0"/>
      <geometry>
        <!--sphere radius="${omni_wheel_radius}" /-->
        <!--
          <xacro:if value="${reflect}">
              <mesh filename="package://summit_xl_description/meshes/wheels/omni_wheel_1.dae" />
          </xacro:if>
          <xacro:unless value="${reflect}">
              <mesh filename="package://summit_xl_description/meshes/wheels/omni_wheel_2.dae" />
					</xacro:unless>
-->
        <cylinder length="0.087" radius="0.127"/>
        <!-- sphere radius="${omni_wheel_radius}"/-->
      </geometry>
    </collision>
    <inertial>
      <mass value="6.5"/>
      <origin xyz="0 0 0"/>
      <inertia ixx="0.0303095" ixy="0" ixz="0" iyy="0.05241925" iyz="0" izz="0.0303095"/>
    </inertial>
  </link>
  <!-- Transmission is important to link the joints and the controller (see summit_xl_control/config/summit_xl_control.yaml)-->
  <transmission name="robot_3_back_left_wheel_joint_trans">
    <type>transmission_interface/SimpleTransmission</type>
    <joint name="robot_3_back_left_wheel_joint">
      <hardwareInterface>hardware_interface/VelocityJointInterface</hardwareInterface>
    </joint>
    <actuator name="robot_3_back_left_wheel_joint_motor">
      <mechanicalReduction>1</mechanicalReduction>
      <motorTorqueConstant>20</motorTorqueConstant>
    </actuator>
  </transmission>
  <gazebo reference="robot_3_back_left_wheel_link">
    <mu1 value="0.01"/>
    <mu2 value="0.01"/>
    <kp value="10000000.0"/>
    <kd value="1.0"/>
    <fdir1 value="1 0 0"/>
    <turnGravityOff>false</turnGravityOff>
  </gazebo>
  <joint name="robot_3_back_right_wheel_joint" type="continuous">
    <parent link="robot_3_base_link"/>
    <child link="robot_3_back_right_wheel_link"/>
    <origin rpy="0 0 0" xyz="-0.2225 -0.2045 0.0"/>
    <axis rpy="0 0 0" xyz="0 1 0"/>
    <limit effort="100" velocity="100"/>
    <joint_properties damping="0.0" friction="0.0"/>
  </joint>
  <link name="robot_3_back_right_wheel_link">
    <visual>
      <origin rpy="0 0 0" xyz="0 0 0"/>
      <geometry>
        <mesh filename="package://summit_xl_description/meshes/wheels/omni_wheel_2.dae"/>
      </geometry>
      <material name="darkgrey">
        <color rgba="0.2 0.2 0.2 1"/>
      </material>
    </visual>
    <collision>
      <origin rpy="1.5707963267948966 0 0" xyz="0 0 0"/>
      <geometry>
        <!--sphere radius="${omni_wheel_radius}" /-->
        <!--
          <xacro:if value="${reflect}">
              <mesh filename="package://summit_xl_description/meshes/wheels/omni_wheel_1.dae" />
          </xacro:if>
          <xacro:unless value="${reflect}">
              <mesh filename="package://summit_xl_description/meshes/wheels/omni_wheel_2.dae" />
					</xacro:unless>
-->
        <cylinder length="0.087" radius="0.127"/>
        <!-- sphere radius="${omni_wheel_radius}"/-->
      </geometry>
    </collision>
    <inertial>
      <mass value="6.5"/>
      <origin xyz="0 0 0"/>
      <inertia ixx="0.0303095" ixy="0" ixz="0" iyy="0.05241925" iyz="0" izz="0.0303095"/>
    </inertial>
  </link>
  <!-- Transmission is important to link the joints and the controller (see summit_xl_control/config/summit_xl_control.yaml)-->
  <transmission name="robot_3_back_right_wheel_joint_trans">
    <type>transmission_interface/SimpleTransmission</type>
    <joint name="robot_3_back_right_wheel_joint">
      <hardwareInterface>hardware_interface/VelocityJointInterface</hardwareInterface>
    </joint>
    <actuator name="robot_3_back_right_wheel_joint_motor">
      <mechanicalReduction>1</mechanicalReduction>
      <motorTorqueConstant>20</motorTorqueConstant>
    </actuator>
  </transmission>
  <gazebo reference="robot_3_back_right_wheel_link">
    <mu1 value="0.01"/>
    <mu2 value="0.01"/>
    <kp value="10000000.0"/>
    <kd value="1.0"/>
    <fdir1 value="1 0 0"/>
    <turnGravityOff>false</turnGravityOff>
  </gazebo>
  <!-- IMU -->
  <!-- <xacro:sensor_imu prefix="${prefix}_imu" parent="${prefix}_base_link" topic="imu/data_raw">
			<origin xyz="${imu_offset_x} ${imu_offset_y} ${imu_offset_z}" rpy="0 0 0"/>
		</xacro:sensor_imu> -->
  <!-- SENSORS -->
  <!-- <xacro:sensor_sick_tim571 prefix="${prefix}_front_laser" parent="${prefix}_base_link" prefix_topic="front_laser" gpu="$(arg gpu)">
			<origin xyz="${front_laser_offset_x} ${front_laser_offset_y} ${front_laser_offset_z}" rpy="0 ${-PI} ${3/4*PI}" />
		</xacro:sensor_sick_tim571>
		<xacro:sensor_sick_tim571 prefix="${prefix}_rear_laser" parent="${prefix}_base_link" prefix_topic="rear_laser" gpu="$(arg gpu)">
			<origin xyz="${rear_laser_offset_x} ${rear_laser_offset_y} ${rear_laser_offset_z}" rpy="0 ${-PI} ${-1/4*PI}" />
		</xacro:sensor_sick_tim571> -->
  <!--xacro:sensor_axis_m5013 prefix="${prefix}_front_ptz_camera" parent="${prefix}_base_link">
			<origin xyz="${front_ptz_camera_offset_x} ${front_ptz_camera_offset_y} ${front_ptz_camera_offset_z}" rpy="${-PI/2} 0 0"/>
		</xacro:sensor_axis_m5013-->
  <!--xacro:sensor_axis_m5013 prefix="${prefix}_rear_ptz_camera" parent="${prefix}_base_link">
			<origin xyz="${rear_ptz_camera_offset_x} ${rear_ptz_camera_offset_y} ${rear_ptz_camera_offset_z}" rpy="${-PI/2} 0 ${PI}"/>
		</xacro:sensor_axis_m5013-->
  <!-- <xacro:sensor_orbbec_astra prefix="${prefix}_front_rgbd_camera" parent="${prefix}_base_link" prefix_topic="front_rgbd_camera">
			<origin xyz="${front_rgbd_camera_offset_x} ${front_rgbd_camera_offset_y} ${front_rgbd_camera_offset_z}" rpy="0 0 0"/>
		</xacro:sensor_orbbec_astra> -->
  <gazebo>
    <plugin filename="libgazebo_ros_control.so" name="ros_control">
      <controlPeriod>0.001</controlPeriod>
      <robotSimType>gazebo_ros_control/DefaultRobotHWSim</robotSimType>
      <legacyModeNS>true</legacyModeNS>
    </plugin>
  </gazebo>
</robot>

