<?xml version="1.0" ?>
<!-- =================================================================================== -->
<!-- |    This document was autogenerated by xacro from /home/lee/summit_ws/src/summit_xl_common/summit_xl_description/robots/summit_xls_std.urdf.xacro | -->
<!-- |    EDITING THIS FILE BY HAND IS NOT RECOMMENDED                                 | -->
<!-- =================================================================================== -->
<robot name="summit_xl">
    <!-- ***************** -->
    <!-- Imported elements -->
    <!-- ***************** -->
    <!-- First we import all posible elements defined in the urdf.xacro files. All these elements are defined as macro:xacros -->
    <gazebo reference="base_footprint">
        <material>Gazebo/Green</material>
        <plugin name="gazebo_ros_control">
            <robotNamespace>/</robotNamespace>
        </plugin>
    </gazebo>
    <!-- in kg-->
    <!-- in kg-->
    <!-- source en.wikipedia.org/wiki/List_of_moments_of_inertia-->
    <!-- This file unifies all sensors that can be used on simulation, defined as xacro:macros -->
    <!-- Includes -->
    <gazebo>
        <plugin filename="libgazebo_ros_control.so" name="ros_control">
            <robotParam>robot_description</robotParam>
            <controlPeriod>0.001</controlPeriod>
            <robotSimType>gazebo_ros_control/DefaultRobotHWSim</robotSimType>
            <legacyModeNS>true</legacyModeNS>
        </plugin>
    </gazebo>
    <!-- *************** -->
    <!-- Robots Elements -->
    <!-- *************** -->
    <!-- Here we create the robot elements using the xacro:macros imported at the beggining of this file -->
    <link name="robot_base_footprint">
        <visual>
            <origin rpy="0 0 0" xyz="0 0 0" />
            <geometry>
                <box size="0.001 0.001 0.001" />
            </geometry>
        </visual>
    </link>
    <joint name="robot_base_footprint_joint" type="fixed">
        <origin rpy="0 0 0" xyz="0 0 0.127" />
        <!-- ${wheel_radius} property must be defined inside wheel description -->
        <parent link="robot_base_footprint" />
        <child link="robot_base_link" />
    </joint>
    <!-- BASE_LINK -->
    <link name="robot_base_link">
        <inertial>
            <mass value="125.0" />
            <origin xyz="0 0 0" rpy="0 0 0" />
            <inertia ixx="1.391" ixy="0.004" ixz="0.0" iyy="6.853" iyz="0.0" izz="6.125" />
        </inertial>
        <visual>
            <origin rpy="0 0 0" xyz="0 0 0" />
            <geometry>
                <mesh filename="package://summit_xl_description/meshes/bases/xls/summit_xls_chassis.stl" />
            </geometry>
            <material name="black">
                <color rgba="0.0 0.0 0.0 1" />
            </material>
        </visual>
        <collision>
            <origin rpy="0 0 0 " xyz="0 0 0" />
            <geometry>
                <mesh filename="package://summit_xl_description/meshes/bases/xls/summit_xls_chassis.dae" />
            </geometry>
        </collision>
    </link>
    <gazebo reference="robot_base_link">
        <material>Gazebo/Black</material>
    </gazebo>
    <!-- CHAPAS INOX TAPAS -->
    <link name="robot_base_chapa">
        <visual>
            <origin rpy="0 0 0" xyz="0 0 0" />
            <geometry>
                <mesh filename="package://summit_xl_description/meshes/bases/xls/summit_xls_chapas_inox_tapas.stl" />
            </geometry>
            <material name="darkgrey">
                <color rgba="0.5 0.5 0.5 1" />
            </material>
        </visual>
    </link>
    <joint name="robot_base_tapa_joint" type="fixed">
        <origin rpy="0 0 0" xyz="0.0 0 0.38062" />
        <parent link="robot_base_link" />
        <child link="robot_base_chapa" />
    </joint>
    <!-- LOGO ROBOTNIK IZQUIERDO -->
    <link name="robot_base_logo_left">
        <visual>
            <origin rpy="0 0 0" xyz="0 0 0" />
            <geometry>
                <mesh filename="package://summit_xl_description/meshes/bases/xls/robotnik_logo_chasis.stl" />
            </geometry>
            <material name="darkgrey">
                <color rgba="0.5 0.5 0.5 1" />
            </material>
        </visual>
    </link>
    <joint name="robot_base_logo_left_joint" type="fixed">
        <origin rpy="0 0 0" xyz="0.0 0.28931 0.29062" />
        <parent link="robot_base_link" />
        <child link="robot_base_logo_left" />
    </joint>
    <!-- LOGO ROBOTNIK DERECHO -->
    <link name="robot_base_logo_right">
        <visual>
            <origin rpy="0 0 0" xyz="0 0 0" />
            <geometry>
                <mesh filename="package://summit_xl_description/meshes/bases/xls/robotnik_logo_chasis.stl" />
            </geometry>
            <material name="darkgrey">
                <color rgba="0.5 0.5 0.5 1" />
            </material>
        </visual>
    </link>
    <joint name="robot_base_logo_right_joint" type="fixed">
        <origin rpy="0 0 3.141592653589793" xyz="0.0 -0.28931 0.29062" />
        <parent link="robot_base_link" />
        <child link="robot_base_logo_right" />
    </joint>
    <!-- LOGO ROBOTNIK FRONTAL -->
    <link name="robot_base_logo_front">
        <visual>
            <origin rpy="0 0 0" xyz="0 0 0" />
            <geometry>
                <mesh filename="package://summit_xl_description/meshes/bases/xls/robotnik_logo_chasis.stl" />
            </geometry>
            <material name="darkgrey">
                <color rgba="0.5 0.5 0.5 1" />
            </material>
        </visual>
    </link>
    <joint name="robot_base_logo_front_joint" type="fixed">
        <origin rpy="0 0 -1.5707963267948966" xyz="0.345 0.0 0.0" />
        <parent link="robot_base_link" />
        <child link="robot_base_logo_front" />
    </joint>
    <!-- LOGO ROBOTNIK TRASERO -->
    <link name="robot_base_logo_rear">
        <visual>
            <origin rpy="0 0 0" xyz="0 0 0" />
            <geometry>
                <mesh filename="package://summit_xl_description/meshes/bases/xls/robotnik_logo_chasis.stl" />
            </geometry>
            <material name="darkgrey">
                <color rgba="0.5 0.5 0.5 1" />
            </material>
        </visual>
    </link>
    <joint name="robot_base_logo_rear_joint" type="fixed">
        <origin rpy="0 0 1.5707963267948966" xyz="-0.345 0.0 0.0" />
        <parent link="robot_base_link" />
        <child link="robot_base_logo_rear" />
    </joint>
    <!-- DOCKING CONTACT -->
    <link name="robot_base_docking_contact" />
    <joint name="robot_base_docking_joint" type="fixed">
        <origin rpy="0 0 0" xyz="0.35 0 0.09" />
        <parent link="robot_base_link" />
        <child link="robot_base_docking_contact" />
    </joint>
    <link name="top_structure">
        <visual>
            <origin rpy="0 0 0" xyz="0 0 0" />
            <geometry>
                <mesh filename="package://summit_xl_description/meshes/structures/top_structure_roas.STL" />
            </geometry>
            <material name="silver">
                <color rgba="0.75 0.75 0.75 1" />
            </material>
        </visual>
        <collision>
            <origin rpy="0 0 0" xyz="0 0 0.142" />
            <geometry>
                <mesh filename="package://summit_xl_description/meshes/structures/top_structure_roas.STL" />
            </geometry>
        </collision>
        <inertial>
            <mass value="0.1" />
            <origin xyz="0 0 0" rpy="0 0 0" />
            <inertia ixx="0.03" iyy="0.03" izz="0.03" ixy="0.0" ixz="0.0" iyz="0.0" />
        </inertial>
    </link>
    <!-- sub-link defining detailed meshes for collision with environment -->
    <link name="fr3_link0">
        <visual>
            <geometry>
                <mesh filename="package://franka_description/meshes/visual/link0.dae" />
            </geometry>
        </visual>
        <collision>
            <geometry>
                <mesh filename="package://franka_description/meshes/collision/link0.stl" />
            </geometry>
        </collision>
        <inertial>
            <origin rpy="0 0 0" xyz="0 0 0" />
            <mass value="0.629769" />
            <inertia ixx="0.00315" ixy="8.2904e-07" ixz="0.00015" iyy="0.00388" iyz="8.2299e-06" izz="0.004285" />
        </inertial>
    </link>
    <!-- sub-link defining coarse geometries of real robot's internal self-collision -->
    <link name="fr3_link0_sc" />
    <!-- fixed joint between both sub-links -->
    <joint name="fr3_link0_sc_joint" type="fixed">
        <origin rpy="0 0 0" />
        <parent link="fr3_link0" />
        <child link="fr3_link0_sc" />
    </joint>
    <!-- sub-link defining detailed meshes for collision with environment -->
    <link name="fr3_link1">
        <visual>
            <geometry>
                <mesh filename="package://franka_description/meshes/visual/link1.dae" />
            </geometry>
        </visual>
        <collision>
            <geometry>
                <mesh filename="package://franka_description/meshes/collision/link1.stl" />
            </geometry>
        </collision>
        <inertial>
            <origin rpy="0 0 0" xyz="0 0 0" />
            <mass value="4.970684" />
            <inertia ixx="0.70337" ixy="-0.000139" ixz="0.006772" iyy="0.70661" iyz="0.019169" izz="0.009117" />
        </inertial>
    </link>
    <!-- sub-link defining coarse geometries of real robot's internal self-collision -->
    <link name="fr3_link1_sc" />
    <!-- fixed joint between both sub-links -->
    <joint name="fr3_link1_sc_joint" type="fixed">
        <origin rpy="0 0 0" />
        <parent link="fr3_link1" />
        <child link="fr3_link1_sc" />
    </joint>
    <joint name="fr3_joint1" type="revolute">
        <origin rpy="0 0 0" xyz="0 0 0.333" />
        <parent link="fr3_link0" />
        <child link="fr3_link1" />
        <axis xyz="0 0 1" />
        <limit effort="87.0" lower="-2.3093" upper="2.3093" velocity="2.0" />
        <safety_controller k_position="100.0" k_velocity="40.0" soft_lower_limit="-2.3093" soft_upper_limit="2.3093" />
        <dynamics D="1" K="7000" damping="0.003" friction="0.0" mu_coulomb="0" mu_viscous="16" />
    </joint>
    <!-- sub-link defining detailed meshes for collision with environment -->
    <link name="fr3_link2">
        <visual>
            <geometry>
                <mesh filename="package://franka_description/meshes/visual/link2.dae" />
            </geometry>
        </visual>
        <collision>
            <geometry>
                <mesh filename="package://franka_description/meshes/collision/link2.stl" />
            </geometry>
        </collision>
        <inertial>
            <origin rpy="0 0 0" xyz="0 0 0" />
            <mass value="0.646926" />
            <inertia ixx="0.007962" ixy="-0.003925" ixz="0.010254" iyy="0.02811" iyz="0.000704" izz="0.025995" />
        </inertial>
    </link>
    <!-- sub-link defining coarse geometries of real robot's internal self-collision -->
    <link name="fr3_link2_sc" />
    <!-- fixed joint between both sub-links -->
    <joint name="fr3_link2_sc_joint" type="fixed">
        <origin rpy="0 0 0" />
        <parent link="fr3_link2" />
        <child link="fr3_link2_sc" />
    </joint>
    <joint name="fr3_joint2" type="revolute">
        <origin rpy="-1.5707963267948966 0 0" xyz="0 0 0" />
        <parent link="fr3_link1" />
        <child link="fr3_link2" />
        <axis xyz="0 0 1" />
        <limit effort="87.0" lower="-1.5133" upper="1.5133" velocity="1.0" />
        <safety_controller k_position="100.0" k_velocity="40.0" soft_lower_limit="-1.5133" soft_upper_limit="1.5133" />
        <dynamics D="1" K="7000" damping="0.003" friction="0.0" mu_coulomb="0" mu_viscous="16" />
    </joint>
    <!-- sub-link defining detailed meshes for collision with environment -->
    <link name="fr3_link3">
        <visual>
            <geometry>
                <mesh filename="package://franka_description/meshes/visual/link3.dae" />
            </geometry>
        </visual>
        <collision>
            <geometry>
                <mesh filename="package://franka_description/meshes/collision/link3.stl" />
            </geometry>
        </collision>
        <inertial>
            <origin rpy="0 0 0" xyz="0 0 0" />
            <mass value="3.228604" />
            <inertia ixx="0.037242" ixy="-0.004761" ixz="-0.011396" iyy="0.036155" iyz="-0.012805" izz="0.01083" />
        </inertial>
    </link>
    <!-- sub-link defining coarse geometries of real robot's internal self-collision -->
    <link name="fr3_link3_sc" />
    <!-- fixed joint between both sub-links -->
    <joint name="fr3_link3_sc_joint" type="fixed">
        <origin rpy="0 0 0" />
        <parent link="fr3_link3" />
        <child link="fr3_link3_sc" />
    </joint>
    <joint name="fr3_joint3" type="revolute">
        <origin rpy="1.5707963267948966 0 0" xyz="0 -0.316 0" />
        <parent link="fr3_link2" />
        <child link="fr3_link3" />
        <axis xyz="0 0 1" />
        <limit effort="87.0" lower="-2.4937" upper="2.4937" velocity="1.5" />
        <safety_controller k_position="100.0" k_velocity="40.0" soft_lower_limit="-2.4937" soft_upper_limit="2.4937" />
        <dynamics D="1" K="7000" damping="0.003" friction="0.0" mu_coulomb="0" mu_viscous="16" />
    </joint>
    <!-- sub-link defining detailed meshes for collision with environment -->
    <link name="fr3_link4">
        <visual>
            <geometry>
                <mesh filename="package://franka_description/meshes/visual/link4.dae" />
            </geometry>
        </visual>
        <collision>
            <geometry>
                <mesh filename="package://franka_description/meshes/collision/link4.stl" />
            </geometry>
        </collision>
        <inertial>
            <origin rpy="0 0 0" xyz="0 0 0" />
            <mass value="3.587895" />
            <inertia ixx="0.025853" ixy="0.007796" ixz="-0.001332" iyy="0.019552" iyz="0.008641" izz="0.028323" />
        </inertial>
    </link>
    <!-- sub-link defining coarse geometries of real robot's internal self-collision -->
    <link name="fr3_link4_sc" />
    <!-- fixed joint between both sub-links -->
    <joint name="fr3_link4_sc_joint" type="fixed">
        <origin rpy="0 0 0" />
        <parent link="fr3_link4" />
        <child link="fr3_link4_sc" />
    </joint>
    <joint name="fr3_joint4" type="revolute">
        <origin rpy="1.5707963267948966 0 0" xyz="0.0825 0 0" />
        <parent link="fr3_link3" />
        <child link="fr3_link4" />
        <axis xyz="0 0 1" />
        <limit effort="87.0" lower="-2.7478" upper="-0.4461" velocity="1.25" />
        <safety_controller k_position="100.0" k_velocity="40.0" soft_lower_limit="-2.7478" soft_upper_limit="-0.4461" />
        <dynamics D="1" K="7000" damping="0.003" friction="0.0" mu_coulomb="0" mu_viscous="16" />
    </joint>
    <!-- sub-link defining detailed meshes for collision with environment -->
    <link name="fr3_link5">
        <visual>
            <geometry>
                <mesh filename="package://franka_description/meshes/visual/link5.dae" />
            </geometry>
        </visual>
        <collision>
            <geometry>
                <mesh filename="package://franka_description/meshes/collision/link5.stl" />
            </geometry>
        </collision>
        <inertial>
            <origin rpy="0 0 0" xyz="0 0 0" />
            <mass value="1.225946" />
            <inertia ixx="0.035549" ixy="-0.002117" ixz="-0.004037" iyy="0.029474" iyz="0.000229" izz="0.008627" />
        </inertial>
    </link>
    <!-- sub-link defining coarse geometries of real robot's internal self-collision -->
    <link name="fr3_link5_sc" />
    <!-- fixed joint between both sub-links -->
    <joint name="fr3_link5_sc_joint" type="fixed">
        <origin rpy="0 0 0" />
        <parent link="fr3_link5" />
        <child link="fr3_link5_sc" />
    </joint>
    <joint name="fr3_joint5" type="revolute">
        <origin rpy="-1.5707963267948966 0 0" xyz="-0.0825 0.384 0" />
        <parent link="fr3_link4" />
        <child link="fr3_link5" />
        <axis xyz="0 0 1" />
        <limit effort="12.0" lower="-2.48" upper="2.48" velocity="3.0" />
        <safety_controller k_position="100.0" k_velocity="40.0" soft_lower_limit="-2.48" soft_upper_limit="2.48" />
        <dynamics D="1" K="7000" damping="0.003" friction="0.0" mu_coulomb="0" mu_viscous="16" />
    </joint>
    <!-- sub-link defining detailed meshes for collision with environment -->
    <link name="fr3_link6">
        <visual>
            <geometry>
                <mesh filename="package://franka_description/meshes/visual/link6.dae" />
            </geometry>
        </visual>
        <collision>
            <geometry>
                <mesh filename="package://franka_description/meshes/collision/link6.stl" />
            </geometry>
        </collision>
        <inertial>
            <origin rpy="0 0 0" xyz="0 0 0" />
            <mass value="1.666555" />
            <inertia ixx="0.001964" ixy="0.000109" ixz="-0.001158" iyy="0.004354" iyz="0.000341" izz="0.005433" />
        </inertial>
    </link>
    <!-- sub-link defining coarse geometries of real robot's internal self-collision -->
    <link name="fr3_link6_sc" />
    <!-- fixed joint between both sub-links -->
    <joint name="fr3_link6_sc_joint" type="fixed">
        <origin rpy="0 0 0" />
        <parent link="fr3_link6" />
        <child link="fr3_link6_sc" />
    </joint>
    <joint name="fr3_joint6" type="revolute">
        <origin rpy="1.5707963267948966 0 0" xyz="0 0 0" />
        <parent link="fr3_link5" />
        <child link="fr3_link6" />
        <axis xyz="0 0 1" />
        <limit effort="12.0" lower="0.8521" upper="4.2094" velocity="1.5" />
        <safety_controller k_position="100.0" k_velocity="40.0" soft_lower_limit="0.8521" soft_upper_limit="4.2094" />
        <dynamics D="1" K="7000" damping="0.003" friction="0.0" mu_coulomb="0" mu_viscous="16" />
    </joint>
    <!-- sub-link defining detailed meshes for collision with environment -->
    <link name="fr3_link7">
        <visual>
            <geometry>
                <mesh filename="package://franka_description/meshes/visual/link7.dae" />
            </geometry>
        </visual>
        <collision>
            <geometry>
                <mesh filename="package://franka_description/meshes/collision/link7.stl" />
            </geometry>
        </collision>
        <inertial>
            <origin rpy="0 0 0" xyz="0 0 0" />
            <mass value="0.735522" />
            <inertia ixx="0.012516" ixy="-0.000428" ixz="-0.001196" iyy="0.010027" iyz="-0.000741" izz="0.004815" />
        </inertial>
    </link>
    <!-- sub-link defining coarse geometries of real robot's internal self-collision -->
    <link name="fr3_link7_sc" />
    <!-- fixed joint between both sub-links -->
    <joint name="fr3_link7_sc_joint" type="fixed">
        <origin rpy="0 0 0.7853981633974483" />
        <parent link="fr3_link7" />
        <child link="fr3_link7_sc" />
    </joint>
    <joint name="fr3_joint7" type="revolute">
        <origin rpy="1.5707963267948966 0 0" xyz="0.088 0 0" />
        <parent link="fr3_link6" />
        <child link="fr3_link7" />
        <axis xyz="0 0 1" />
        <limit effort="12.0" lower="-2.6895" upper="2.6895" velocity="3.0" />
        <safety_controller k_position="100.0" k_velocity="40.0" soft_lower_limit="-2.6895" soft_upper_limit="2.6895" />
        <dynamics D="1" K="7000" damping="0.003" friction="0.0" mu_coulomb="0" mu_viscous="16" />
    </joint>
    <link name="fr3_link8" />
    <joint name="fr3_joint8" type="fixed">
        <origin rpy="0 0 0" xyz="0 0 0.107" />
        <parent link="fr3_link7" />
        <child link="fr3_link8" />
    </joint>
    <joint name="fr3_hand_joint" type="fixed">
        <parent link="fr3_link8" />
        <child link="fr3_hand" />
        <origin rpy="0 0 -0.7853981633974483" xyz="0 0 0.003" />
    </joint>
    <!-- sub-link defining detailed meshes for collision with environment -->
    <link name="fr3_hand">
        <visual>
            <geometry>
                <mesh filename="package://franka_description/meshes/visual/hand.dae" />
            </geometry>
        </visual>
        <collision>
            <geometry>
                <mesh filename="package://franka_description/meshes/collision/hand.stl" />
            </geometry>
        </collision>
        <inertial>
            <origin rpy="0 0 0" xyz="0 0 0" />
            <mass value="0.73" />
            <inertia ixx="0.001" ixy="0" ixz="0" iyy="0.0025" iyz="0" izz="0.0017" />
        </inertial>
    </link>
    <!-- sub-link defining coarse geometries of real robot's internal self-collision -->
    <link name="fr3_hand_sc" />
    <!-- fixed joint between both sub-links -->
    <joint name="fr3_hand_sc_joint" type="fixed">
        <origin rpy="0 0 0" />
        <parent link="fr3_hand" />
        <child link="fr3_hand_sc" />
    </joint>
    <!-- Define the hand_tcp frame -->
    <link name="fr3_hand_tcp" />
    <joint name="fr3_hand_tcp_joint" type="fixed">
        <origin rpy="0 0 0" xyz="0 0 0.1034" />
        <parent link="fr3_hand" />
        <child link="fr3_hand_tcp" />
    </joint>
    <link name="fr3_leftfinger">
        <visual>
            <geometry>
                <mesh filename="package://franka_description/meshes/visual/finger.dae" />
            </geometry>
        </visual>
        <!-- screw mount -->
        <collision>
            <origin rpy="0 0 0" xyz="0 18.5e-3 11e-3" />
            <geometry>
                <box size="22e-3 15e-3 20e-3" />
            </geometry>
        </collision>
        <!-- cartriage sledge -->
        <collision>
            <origin rpy="0 0 0" xyz="0 6.8e-3 2.2e-3" />
            <geometry>
                <box size="22e-3 8.8e-3 3.8e-3" />
            </geometry>
        </collision>
        <!-- diagonal finger -->
        <collision>
            <origin rpy="0.5235987755982988 0 0" xyz="0 15.9e-3 28.35e-3" />
            <geometry>
                <box size="17.5e-3 7e-3 23.5e-3" />
            </geometry>
        </collision>
        <!-- rubber tip with which to grasp -->
        <collision>
            <origin rpy="0 0 0" xyz="0 7.58e-3 45.25e-3" />
            <geometry>
                <box size="17.5e-3 15.2e-3 18.5e-3" />
            </geometry>
        </collision>
        <inertial>
            <origin rpy="0 0 0" xyz="0 0 0" />
            <mass value="0.015" />
            <inertia ixx="2.3749999999999997e-06" ixy="0" ixz="0" iyy="2.3749999999999997e-06" iyz="0" izz="7.5e-07" />
        </inertial>
    </link>
    <link name="fr3_rightfinger">
        <visual>
            <origin rpy="0 0 3.141592653589793" xyz="0 0 0" />
            <geometry>
                <mesh filename="package://franka_description/meshes/visual/finger.dae" />
            </geometry>
        </visual>
        <!-- screw mount -->
        <collision>
            <origin rpy="0 0 0" xyz="0 -18.5e-3 11e-3" />
            <geometry>
                <box size="22e-3 15e-3 20e-3" />
            </geometry>
        </collision>
        <!-- cartriage sledge -->
        <collision>
            <origin rpy="0 0 0" xyz="0 -6.8e-3 2.2e-3" />
            <geometry>
                <box size="22e-3 8.8e-3 3.8e-3" />
            </geometry>
        </collision>
        <!-- diagonal finger -->
        <collision>
            <origin rpy="-0.5235987755982988 0 0" xyz="0 -15.9e-3 28.35e-3" />
            <geometry>
                <box size="17.5e-3 7e-3 23.5e-3" />
            </geometry>
        </collision>
        <!-- rubber tip with which to grasp -->
        <collision>
            <origin rpy="0 0 0" xyz="0 -7.58e-3 45.25e-3" />
            <geometry>
                <box size="17.5e-3 15.2e-3 18.5e-3" />
            </geometry>
        </collision>
        <inertial>
            <origin rpy="0 0 0" xyz="0 0 0" />
            <mass value="0.015" />
            <inertia ixx="2.3749999999999997e-06" ixy="0" ixz="0" iyy="2.3749999999999997e-06" iyz="0" izz="7.5e-07" />
        </inertial>
    </link>
    <joint name="fr3_finger_joint1" type="prismatic">
        <parent link="fr3_hand" />
        <child link="fr3_leftfinger" />
        <origin rpy="0 0 0" xyz="0 0 0.0584" />
        <axis xyz="0 1 0" />
        <limit effort="100" lower="0.0" upper="0.04" velocity="0.2" />
        <dynamics damping="0.3" />
    </joint>
    <joint name="fr3_finger_joint2" type="prismatic">
        <parent link="fr3_hand" />
        <child link="fr3_rightfinger" />
        <origin rpy="0 0 0" xyz="0 0 0.0584" />
        <axis xyz="0 -1 0" />
        <limit effort="100" lower="0.0" upper="0.04" velocity="0.2" />
        <!-- <mimic joint="fr3_finger_joint1" /> -->
        <dynamics damping="0.3" />
    </joint>
    <!-- Gazebo requires a joint to a link called "world" for statically mounted robots -->
    <!--link name="world" />
      <joint name="world_joint" type="fixed">
        <origin xyz="$(arg xyz)" rpy="$(arg rpy)" />
        <parent link="world" />
        <child  link="$(arg arm_id)_link0" />
      </joint-->
    <gazebo reference="fr3_joint1">
        <!-- Needed for ODE to output external wrenches on joints -->
        <provideFeedback>true</provideFeedback>
    </gazebo>
    <transmission name="fr3_joint1_transmission">
        <type>transmission_interface/SimpleTransmission</type>
        <joint name="fr3_joint1">
            <hardwareInterface>hardware_interface/EffortJointInterface</hardwareInterface>
        </joint>
        <actuator name="fr3_joint1_motor">
            <hardwareInterface>hardware_interface/EffortJointInterface</hardwareInterface>
        </actuator>
    </transmission>
    <gazebo reference="fr3_joint2">
        <!-- Needed for ODE to output external wrenches on joints -->
        <provideFeedback>true</provideFeedback>
    </gazebo>
    <transmission name="fr3_joint2_transmission">
        <type>transmission_interface/SimpleTransmission</type>
        <joint name="fr3_joint2">
            <hardwareInterface>hardware_interface/EffortJointInterface</hardwareInterface>
        </joint>
        <actuator name="fr3_joint2_motor">
            <hardwareInterface>hardware_interface/EffortJointInterface</hardwareInterface>
        </actuator>
    </transmission>
    <gazebo reference="fr3_joint3">
        <!-- Needed for ODE to output external wrenches on joints -->
        <provideFeedback>true</provideFeedback>
    </gazebo>
    <transmission name="fr3_joint3_transmission">
        <type>transmission_interface/SimpleTransmission</type>
        <joint name="fr3_joint3">
            <hardwareInterface>hardware_interface/EffortJointInterface</hardwareInterface>
        </joint>
        <actuator name="fr3_joint3_motor">
            <hardwareInterface>hardware_interface/EffortJointInterface</hardwareInterface>
        </actuator>
    </transmission>
    <gazebo reference="fr3_joint4">
        <!-- Needed for ODE to output external wrenches on joints -->
        <provideFeedback>true</provideFeedback>
    </gazebo>
    <transmission name="fr3_joint4_transmission">
        <type>transmission_interface/SimpleTransmission</type>
        <joint name="fr3_joint4">
            <hardwareInterface>hardware_interface/EffortJointInterface</hardwareInterface>
        </joint>
        <actuator name="fr3_joint4_motor">
            <hardwareInterface>hardware_interface/EffortJointInterface</hardwareInterface>
        </actuator>
    </transmission>
    <gazebo reference="fr3_joint5">
        <!-- Needed for ODE to output external wrenches on joints -->
        <provideFeedback>true</provideFeedback>
    </gazebo>
    <transmission name="fr3_joint5_transmission">
        <type>transmission_interface/SimpleTransmission</type>
        <joint name="fr3_joint5">
            <hardwareInterface>hardware_interface/EffortJointInterface</hardwareInterface>
        </joint>
        <actuator name="fr3_joint5_motor">
            <hardwareInterface>hardware_interface/EffortJointInterface</hardwareInterface>
        </actuator>
    </transmission>
    <gazebo reference="fr3_joint6">
        <!-- Needed for ODE to output external wrenches on joints -->
        <provideFeedback>true</provideFeedback>
    </gazebo>
    <transmission name="fr3_joint6_transmission">
        <type>transmission_interface/SimpleTransmission</type>
        <joint name="fr3_joint6">
            <hardwareInterface>hardware_interface/EffortJointInterface</hardwareInterface>
        </joint>
        <actuator name="fr3_joint6_motor">
            <hardwareInterface>hardware_interface/EffortJointInterface</hardwareInterface>
        </actuator>
    </transmission>
    <gazebo reference="fr3_joint7">
        <!-- Needed for ODE to output external wrenches on joints -->
        <provideFeedback>true</provideFeedback>
    </gazebo>
    <transmission name="fr3_joint7_transmission">
        <type>transmission_interface/SimpleTransmission</type>
        <joint name="fr3_joint7">
            <hardwareInterface>hardware_interface/EffortJointInterface</hardwareInterface>
        </joint>
        <actuator name="fr3_joint7_motor">
            <hardwareInterface>hardware_interface/EffortJointInterface</hardwareInterface>
        </actuator>
    </transmission>
  
    <!-- <xacro:transmission-franka-state arm_id="${arm_id}" />
      <xacro:transmission-franka-model arm_id="${arm_id}"
         root="${arm_id}_joint1"
         tip="${arm_id}_joint8"
       /> -->
    <gazebo reference="fr3_finger_joint1">
        <!-- Needed for ODE to output external wrenches on joints -->
        <provideFeedback>true</provideFeedback>
    </gazebo>
    <transmission name="fr3_finger_joint1_transmission">
        <type>transmission_interface/SimpleTransmission</type>
        <joint name="fr3_finger_joint1">
            <hardwareInterface>hardware_interface/EffortJointInterface</hardwareInterface>
        </joint>
        <actuator name="fr3_finger_joint1_motor">
            <hardwareInterface>hardware_interface/EffortJointInterface</hardwareInterface>
            <mechanicalReduction>1</mechanicalReduction>
        </actuator>
    </transmission>
    <gazebo reference="fr3_finger_joint2">
        <!-- Needed for ODE to output external wrenches on joints -->
        <provideFeedback>true</provideFeedback>
    </gazebo>
    <transmission name="fr3_finger_joint2_transmission">
        <type>transmission_interface/SimpleTransmission</type>
        <joint name="fr3_finger_joint2">
            <hardwareInterface>hardware_interface/EffortJointInterface</hardwareInterface>
        </joint>
        <actuator name="fr3_finger_joint2_motor">
            <hardwareInterface>hardware_interface/EffortJointInterface</hardwareInterface>
            <mechanicalReduction>1</mechanicalReduction>
        </actuator>
    </transmission>
    <gazebo reference="fr3_leftfinger">
        <collision>
            <max_contacts>10</max_contacts>
            <surface>
                <contact>
                    <ode>
                        <!-- These two parameter need application specific tuning. -->
                        <!-- Usually you want no "snap out" velocity and a generous -->
                        <!-- penetration depth to keep the grasping stable -->
                        <max_vel>0</max_vel>
                        <min_depth>0.001</min_depth>
                    </ode>
                </contact>
                <friction>
                    <ode>
                        <mu>1.13</mu>
                        <mu2>1.13</mu2>
                    </ode>
                </friction>
                <bounce />
            </surface>
        </collision>
    </gazebo>
    <gazebo reference="fr3_rightfinger">
        <collision>
            <max_contacts>10</max_contacts>
            <surface>
                <contact>
                    <ode>
                        <!-- These two parameter need application specific tuning. -->
                        <!-- Usually you want no "snap out" velocity and a generous -->
                        <!-- penetration depth to keep the grasping stable -->
                        <max_vel>0</max_vel>
                        <min_depth>0.001</min_depth>
                    </ode>
                </contact>
                <friction>
                    <ode>
                        <mu>1.13</mu>
                        <mu2>1.13</mu2>
                    </ode>
                </friction>
                <bounce />
            </surface>
        </collision>
    </gazebo>
    <!-- <gazebo>
        <plugin name="gazebo_ros_control" filename="libgazebo_ros_control.so">
          <controlPeriod>0.001</controlPeriod>
          <robotSimType>franka_gazebo/FrankaHWSim</robotSimType>
        </plugin>
        <self_collide>true</self_collide>
      </gazebo> -->
    <joint name="fr3_base_joint" type="fixed">
        <origin rpy="0 0 0" xyz="0.23 0 0.66" />
        <parent link="top_structure" />
        <child link="fr3_link0" />
    </joint>
    <link name="ee_link" />
    <joint name="ee_joint" type="fixed">
        <parent link="fr3_link8" />
        <child link="ee_link" />
        <origin rpy="0 0 0" xyz="0 0 0" />
    </joint>
    <material name="aluminum">
        <color rgba="0.5 0.5 0.5 1" />
    </material>
    <!-- camera body, with origin at bottom screw mount -->
    <joint name="camera_joint" type="fixed">
        <origin rpy="0 -1.57 3.14" xyz="0.0377 0 0.0105" />
        <parent link="camera_bracket" />
        <child link="camera_bottom_screw_frame" />
    </joint>
    <link name="camera_bottom_screw_frame" />
    <joint name="camera_link_joint" type="fixed">
        <origin rpy="0 0 0" xyz="0.010600000000000002 0.0175 0.0125" />
        <parent link="camera_bottom_screw_frame" />
        <child link="camera_link" />
    </joint>
    <link name="camera_link">
        <visual>
            <origin rpy="1.5707963267948966 0 1.5707963267948966" xyz="0.0043 -0.0175 0" />
            <geometry>
                <mesh filename="package://summit_xl_description/meshes/structures/d435.dae" />
            </geometry>
        </visual>
        <collision>
            <origin rpy="0 0 0" xyz="0 -0.0175 0" />
            <geometry>
                <box size="0.02505 0.09 0.025" />
            </geometry>
        </collision>
        <inertial>
            <mass value="0.564" />
            <origin xyz="0 0 0" rpy="0 0 0" />
            <inertia ixx="0.003881243" ixy="0.0" ixz="0.0" iyy="0.000498940" iyz="0.0" izz="0.003879257" />
        </inertial>
    </link>
    <!-- Use the nominal extrinsics between camera frames if the calibrated extrinsics aren't being published. e.g. running the device in simulation  -->
    <!--xacro:if value="$(arg use_nominal_extrinsics)"-->
    <!-- camera depth joints and links -->
    <joint name="camera_depth_joint" type="fixed">
        <origin rpy="0 0 0" xyz="0 0 0" />
        <parent link="camera_link" />
        <child link="camera_depth_frame" />
    </joint>
    <link name="camera_depth_frame" />
    <joint name="camera_depth_optical_joint" type="fixed">
        <origin rpy="-1.5707963267948966 0 -1.5707963267948966" xyz="0 0 0" />
        <parent link="camera_depth_frame" />
        <child link="camera_depth_optical_frame" />
    </joint>
    <link name="camera_depth_optical_frame" />
    <!-- camera left IR joints and links -->
    <joint name="camera_infra1_joint" type="fixed">
        <origin rpy="0 0 0" xyz="0 0.0 0" />
        <parent link="camera_link" />
        <child link="camera_infra1_frame" />
    </joint>
    <link name="camera_infra1_frame" />
    <joint name="camera_infra1_optical_joint" type="fixed">
        <origin rpy="-1.5707963267948966 0 -1.5707963267948966" xyz="0 0 0" />
        <parent link="camera_infra1_frame" />
        <child link="camera_infra1_optical_frame" />
    </joint>
    <link name="camera_infra1_optical_frame" />
    <!-- camera right IR joints and links -->
    <joint name="camera_infra2_joint" type="fixed">
        <origin rpy="0 0 0" xyz="0 -0.05 0" />
        <parent link="camera_link" />
        <child link="camera_infra2_frame" />
    </joint>
    <link name="camera_infra2_frame" />
    <joint name="camera_infra2_optical_joint" type="fixed">
        <origin rpy="-1.5707963267948966 0 -1.5707963267948966" xyz="0 0 0" />
        <parent link="camera_infra2_frame" />
        <child link="camera_infra2_optical_frame" />
    </joint>
    <link name="camera_infra2_optical_frame" />
    <!-- camera color joints and links -->
    <joint name="camera_color_joint" type="fixed">
        <origin rpy="0 0 0" xyz="0 0.015 0" />
        <parent link="camera_link" />
        <child link="camera_color_frame" />
    </joint>
    <link name="camera_color_frame" />
    <joint name="camera_color_optical_joint" type="fixed">
        <origin rpy="-1.5707963267948966 0 -1.5707963267948966" xyz="0 0 0" />
        <parent link="camera_color_frame" />
        <child link="camera_color_optical_frame" />
    </joint>
    <link name="camera_color_optical_frame" />
    <!--/xacro:if-->
    <link name="camera_bracket">
        <visual>
            <origin rpy="0 0 0" xyz="0 0 0" />
            <geometry>
                <mesh filename="package://summit_xl_description/meshes/structures/hand_camera.STL" />
            </geometry>
            <material name="silver">
                <color rgba="0.75 0.75 0.75 1" />
            </material>
        </visual>
        <collision>
            <origin rpy="0 0 0" xyz="0 0 0" />
            <geometry>
                <mesh filename="package://summit_xl_description/meshes/structures/hand_camera.STL" />
            </geometry>
            <material name="silver">
                <color rgba="0.75 0.75 0.75 1" />
            </material>
        </collision>
        <inertial>
            <mass value="0.1" />
            <origin xyz="0 0 0" rpy="0 0 0" />
            <inertia ixx="0.03" iyy="0.03" izz="0.03" ixy="0.0" ixz="0.0" iyz="0.0" />
        </inertial>
    </link>
    <joint name="camera_bracket_joint" type="fixed">
        <parent link="ee_link" />
        <child link="camera_bracket" />
        <origin rpy="0 0 -0.785" xyz="0 0 0.003" />
    </joint>
    <!--link name="hand_camera_link" type="fixed"/>
  <joint name="hand_camera_joint" type="fixed">
    <parent link="camera_bracket" />
    <child link = "hand_camera_link" />
    <origin xyz="0.007 0 0.0375" rpy="0 0 0" />
  </joint-->
    <joint name="top_structure_joint" type="fixed">
        <origin rpy="0 0 0" xyz="0 0 0" />
        <parent link="robot_base_footprint" />
        <child link="top_structure" />
    </joint>
    <joint name="robot_front_right_wheel_joint" type="continuous">
        <parent link="robot_base_link" />
        <child link="robot_front_right_wheel_link" />
        <origin rpy="0 0 0" xyz="0.2225 -0.2045 0.0" />
        <axis rpy="0 0 0" xyz="0 1 0" />
        <limit effort="100" velocity="100" />
        <joint_properties damping="0.0" friction="0.0" />
    </joint>
    <link name="robot_front_right_wheel_link">
        <visual>
            <origin rpy="0 0 0" xyz="0 0 0" />
            <geometry>
                <mesh filename="package://summit_xl_description/meshes/wheels/omni_wheel_2.dae" />
            </geometry>
            <material name="darkgrey">
                <color rgba="0.2 0.2 0.2 1" />
            </material>
        </visual>
        <collision>
            <origin rpy="1.5707963267948966 0 0" xyz="0 0 0" />
            <geometry>
                <!--sphere radius="${omni_wheel_radius}" /-->
                <!--
          <xacro:if value="${reflect}">
              <mesh filename="package://summit_xl_description/meshes/wheels/omni_wheel_1.dae" />
          </xacro:if>
          <xacro:unless value="${reflect}">
              <mesh filename="package://summit_xl_description/meshes/wheels/omni_wheel_2.dae" />
					</xacro:unless>
-->
                <cylinder length="0.087" radius="0.127" />
                <!-- sphere radius="${omni_wheel_radius}"/-->
            </geometry>
        </collision>
        <inertial>
            <mass value="6.5" />
            <origin xyz="0 0 0" rpy="0 0 0" />
            <inertia ixx="0.0303095" ixy="0" ixz="0" iyy="0.05241925" iyz="0" izz="0.0303095" />
        </inertial>
    </link>
    <!-- Transmission is important to link the joints and the controller (see summit_xl_control/config/summit_xl_control.yaml)-->
    <transmission name="robot_front_right_wheel_joint_trans">
        <type>transmission_interface/SimpleTransmission</type>
        <joint name="robot_front_right_wheel_joint">
            <hardwareInterface>hardware_interface/VelocityJointInterface</hardwareInterface>
        </joint>
        <actuator name="robot_front_right_wheel_joint_motor">
            <mechanicalReduction>1</mechanicalReduction>
            <hardwareInterface>hardware_interface/EffortJointInterface</hardwareInterface>
        </actuator>
    </transmission>
    <gazebo reference="robot_front_right_wheel_link">
        <mu1 value="1.0" />
        <mu2 value="1.0" />
        <kp value="10000000.0" />
        <kd value="1.0" />
        <fdir1 value="1 0 0" />
        <turnGravityOff>false</turnGravityOff>
    </gazebo>
    <joint name="robot_front_left_wheel_joint" type="continuous">
        <parent link="robot_base_link" />
        <child link="robot_front_left_wheel_link" />
        <origin rpy="0 0 0" xyz="0.2225 0.2045 0.0" />
        <axis rpy="0 0 0" xyz="0 1 0" />
        <limit effort="100" velocity="100" />
        <joint_properties damping="0.0" friction="0.0" />
    </joint>
    <link name="robot_front_left_wheel_link">
        <visual>
            <origin rpy="0 0 0" xyz="0 0 0" />
            <geometry>
                <mesh filename="package://summit_xl_description/meshes/wheels/omni_wheel_1.dae" />
            </geometry>
            <material name="darkgrey">
                <color rgba="0.2 0.2 0.2 1" />
            </material>
        </visual>
        <collision>
            <origin rpy="1.5707963267948966 0 0" xyz="0 0 0" />
            <geometry>
                <!--sphere radius="${omni_wheel_radius}" /-->
                <!--
          <xacro:if value="${reflect}">
              <mesh filename="package://summit_xl_description/meshes/wheels/omni_wheel_1.dae" />
          </xacro:if>
          <xacro:unless value="${reflect}">
              <mesh filename="package://summit_xl_description/meshes/wheels/omni_wheel_2.dae" />
					</xacro:unless>
-->
                <cylinder length="0.087" radius="0.127" />
                <!-- sphere radius="${omni_wheel_radius}"/-->
            </geometry>
        </collision>
        <inertial>
            <mass value="6.5" />
            <origin xyz="0 0 0" rpy="0 0 0" />
            <inertia ixx="0.0303095" ixy="0" ixz="0" iyy="0.05241925" iyz="0" izz="0.0303095" />
        </inertial>
    </link>
    <!-- Transmission is important to link the joints and the controller (see summit_xl_control/config/summit_xl_control.yaml)-->
    <transmission name="robot_front_left_wheel_joint_trans">
        <type>transmission_interface/SimpleTransmission</type>
        <joint name="robot_front_left_wheel_joint">
            <hardwareInterface>hardware_interface/VelocityJointInterface</hardwareInterface>
        </joint>
        <actuator name="robot_front_left_wheel_joint_motor">
            <mechanicalReduction>1</mechanicalReduction>
            <hardwareInterface>hardware_interface/EffortJointInterface</hardwareInterface>
        </actuator>
    </transmission>
    <gazebo reference="robot_front_left_wheel_link">
        <mu1 value="1.0" />
        <mu2 value="1.0" />
        <kp value="10000000.0" />
        <kd value="1.0" />
        <fdir1 value="1 0 0" />
        <turnGravityOff>false</turnGravityOff>
    </gazebo>
    <joint name="robot_back_left_wheel_joint" type="continuous">
        <parent link="robot_base_link" />
        <child link="robot_back_left_wheel_link" />
        <origin rpy="0 0 0" xyz="-0.2225 0.2045 0.0" />
        <axis rpy="0 0 0" xyz="0 1 0" />
        <limit effort="100" velocity="100" />
        <joint_properties damping="0.0" friction="0.0" />
    </joint>
    <link name="robot_back_left_wheel_link">
        <visual>
            <origin rpy="0 0 0" xyz="0 0 0" />
            <geometry>
                <mesh filename="package://summit_xl_description/meshes/wheels/omni_wheel_1.dae" />
            </geometry>
            <material name="darkgrey">
                <color rgba="0.2 0.2 0.2 1" />
            </material>
        </visual>
        <collision>
            <origin rpy="1.5707963267948966 0 0" xyz="0 0 0" />
            <geometry>
                <!--sphere radius="${omni_wheel_radius}" /-->
                <!--
          <xacro:if value="${reflect}">
              <mesh filename="package://summit_xl_description/meshes/wheels/omni_wheel_1.dae" />
          </xacro:if>
          <xacro:unless value="${reflect}">
              <mesh filename="package://summit_xl_description/meshes/wheels/omni_wheel_2.dae" />
					</xacro:unless>
-->
                <cylinder length="0.087" radius="0.127" />
                <!-- sphere radius="${omni_wheel_radius}"/-->
            </geometry>
        </collision>
        <inertial>
            <mass value="6.5" />
            <origin xyz="0 0 0" rpy="0 0 0" />
            <inertia ixx="0.0303095" ixy="0" ixz="0" iyy="0.05241925" iyz="0" izz="0.0303095" />
        </inertial>
    </link>
    <!-- Transmission is important to link the joints and the controller (see summit_xl_control/config/summit_xl_control.yaml)-->
    <transmission name="robot_back_left_wheel_joint_trans">
        <type>transmission_interface/SimpleTransmission</type>
        <joint name="robot_back_left_wheel_joint">
            <hardwareInterface>hardware_interface/VelocityJointInterface</hardwareInterface>
        </joint>
        <actuator name="robot_back_left_wheel_joint_motor">
            <mechanicalReduction>1</mechanicalReduction>
            <hardwareInterface>hardware_interface/EffortJointInterface</hardwareInterface>
        </actuator>
    </transmission>
    <gazebo reference="robot_back_left_wheel_link">
        <mu1 value="1.0" />
        <mu2 value="1.0" />
        <kp value="10000000.0" />
        <kd value="1.0" />
        <fdir1 value="1 0 0" />
        <turnGravityOff>false</turnGravityOff>
    </gazebo>
    <joint name="robot_back_right_wheel_joint" type="continuous">
        <parent link="robot_base_link" />
        <child link="robot_back_right_wheel_link" />
        <origin rpy="0 0 0" xyz="-0.2225 -0.2045 0.0" />
        <axis rpy="0 0 0" xyz="0 1 0" />
        <limit effort="100" velocity="100" />
        <joint_properties damping="0.0" friction="0.0" />
    </joint>
    <link name="robot_back_right_wheel_link">
        <visual>
            <origin rpy="0 0 0" xyz="0 0 0" />
            <geometry>
                <mesh filename="package://summit_xl_description/meshes/wheels/omni_wheel_2.dae" />
            </geometry>
            <material name="darkgrey">
                <color rgba="0.2 0.2 0.2 1" />
            </material>
        </visual>
        <collision>
            <origin rpy="1.5707963267948966 0 0" xyz="0 0 0" />
            <geometry>
                <!--sphere radius="${omni_wheel_radius}" /-->
                <!--
          <xacro:if value="${reflect}">
              <mesh filename="package://summit_xl_description/meshes/wheels/omni_wheel_1.dae" />
          </xacro:if>
          <xacro:unless value="${reflect}">
              <mesh filename="package://summit_xl_description/meshes/wheels/omni_wheel_2.dae" />
					</xacro:unless>
-->
                <cylinder length="0.087" radius="0.127" />
                <!-- sphere radius="${omni_wheel_radius}"/-->
            </geometry>
        </collision>
        <inertial>
            <mass value="6.5" />
            <origin xyz="0 0 0" rpy="0 0 0" />
            <inertia ixx="0.0303095" ixy="0" ixz="0" iyy="0.05241925" iyz="0" izz="0.0303095" />
        </inertial>
    </link>
    <!-- Transmission is important to link the joints and the controller (see summit_xl_control/config/summit_xl_control.yaml)-->
    <transmission name="robot_back_right_wheel_joint_trans">
        <type>transmission_interface/SimpleTransmission</type>
        <joint name="robot_back_right_wheel_joint">
            <hardwareInterface>hardware_interface/VelocityJointInterface</hardwareInterface>
        </joint>
        <actuator name="robot_back_right_wheel_joint_motor">
            <mechanicalReduction>1</mechanicalReduction>
            <hardwareInterface>hardware_interface/EffortJointInterface</hardwareInterface>
        </actuator>
    </transmission>
    <gazebo reference="robot_back_right_wheel_link">
        <mu1 value="1.0" />
        <mu2 value="1.0" />
        <kp value="10000000.0" />
        <kd value="1.0" />
        <fdir1 value="1 0 0" />
        <turnGravityOff>false</turnGravityOff>
    </gazebo>
    <joint name="robot_imu_joint" type="fixed">
        <axis xyz="1 0 0" />
        <!--origin xyz="0 0 0.2825"/-->
        <origin rpy="0 0 0" xyz="0.127 -0.129 0.212" />
        <parent link="robot_base_link" />
        <child link="robot_imu_link" />
    </joint>
    <link name="robot_imu_link">
        <inertial>
            <origin rpy="0 0 0" xyz="0.0 0 0.01" />
            <mass value="0.005" />
            <inertia ixx="8.333333333333334e-10" ixy="0" ixz="0" iyy="8.333333333333334e-10" iyz="0" izz="8.333333333333334e-10" />
        </inertial>
        <visual>
            <origin rpy="0 0 0" xyz="0 0 0" />
            <geometry>
                <box size="0.001 0.001 0.001" />
            </geometry>
        </visual>
        <!--collision>
	        <origin rpy="0 0 0" xyz="0 0 0"/>
	        <geometry>
	          <box size="0.001 0.001 0.001"/>
	        </geometry>
	      </collision-->
    </link>
    <!--<gazebo>-->
    <!--<plugin name="${prefix}_controller" filename="libgazebo_ros_imu.so">-->
    <!--<topicName>${ns}imu/data</topicName>-->
    <!--<serviceName>imu/service</serviceName>-->
    <!--<bodyName>${prefix}_link</bodyName>-->
    <!--<updateRateHZ>50.0</updateRateHZ>-->
    <!--<gaussianNoise>0.0</gaussianNoise>-->
    <!--</plugin>-->
    <!--</gazebo>-->
    <gazebo reference="robot_imu_link">
        <gravity>true</gravity>
        <sensor name="robot_imu_imu_sensor" type="imu">
            <always_on>true</always_on>
            <update_rate>100</update_rate>
            <visualize>true</visualize>
            <topic>__default_topic__</topic>
            <plugin filename="libgazebo_ros_imu_sensor.so" name="robot_imu_imu_plugin">
                <topicName>imu/data_raw</topicName>
                <bodyName>robot_imu_link</bodyName>
                <updateRateHZ>100.0</updateRateHZ>
                <gaussianNoise>0.0</gaussianNoise>
                <xyzOffset>0 0 0</xyzOffset>
                <rpyOffset>0 0 0</rpyOffset>
                <frameName>robot_imu_link</frameName>
            </plugin>
            <pose>0 0 0 0 0 0</pose>
        </sensor>
    </gazebo>
    <joint name="robot_front_laser_base_joint" type="fixed">
        <origin rpy="0 -3.141592653589793 2.356194490192345" xyz="0.29278 -0.22739 0.22912" />
        <parent link="robot_base_link" />
        <child link="robot_front_laser_base_link" />
    </joint>
    <link name="robot_front_laser_base_link">
        <collision>
            <origin rpy="0 0 0" xyz="0 0 0" />
            <geometry>
                <mesh filename="package://robotnik_sensors/meshes/sick_tim571.dae" />
            </geometry>
        </collision>
        <visual>
            <origin rpy="0 0 0" xyz="0 0 0" />
            <geometry>
                <mesh filename="package://robotnik_sensors/meshes/sick_tim571.dae" />
            </geometry>
        </visual>
        <inertial>
            <mass value="0.25" />
            <origin rpy="0 0 0" xyz="-0.0017 0 0.042875" />
            <inertia ixx="0.00022818880208333336" ixy="0" ixz="0" iyy="0.0002307096354166667" iyz="0" izz="0.0001525208333333333" />
        </inertial>
    </link>
    <joint name="robot_front_laser_joint" type="fixed">
        <origin rpy="0 0 0" xyz="0 0 0.06246" />
        <parent link="robot_front_laser_base_link" />
        <child link="robot_front_laser_link" />
    </joint>
    <link name="robot_front_laser_link" />
    <gazebo reference="robot_front_laser_link">
        <sensor name="robot_front_laser_sensor" type="ray">
            <pose>0 0 0 0 0 0</pose>
            <visualize>false</visualize>
            <update_rate>15</update_rate>
            <ray>
                <scan>
                    <horizontal>
                        <samples>819</samples>
                        <resolution>1</resolution>
                        <min_angle>-2.36</min_angle>
                        <max_angle>2.36</max_angle>
                    </horizontal>
                </scan>
                <range>
                    <min>0.05</min>
                    <max>25.0</max>
                    <resolution>0.00575</resolution>
                </range>
                <noise>
                    <type>gaussian</type>
                    <mean>0.0</mean>
                    <stddev>0.01</stddev>
                </noise>
            </ray>
            <plugin filename="libgazebo_ros_laser.so" name="robot_front_laser_controller">
                <topicName>front_laser/scan</topicName>
                <frameName>/robot_front_laser_link</frameName>
            </plugin>
        </sensor>
    </gazebo>
    <joint name="robot_rear_laser_base_joint" type="fixed">
        <origin rpy="0 -3.141592653589793 -0.7853981633974483" xyz="-0.29278 0.22739 0.22912" />
        <parent link="robot_base_link" />
        <child link="robot_rear_laser_base_link" />
    </joint>
    <link name="robot_rear_laser_base_link">
        <collision>
            <origin rpy="0 0 0" xyz="0 0 0" />
            <geometry>
                <mesh filename="package://robotnik_sensors/meshes/sick_tim571.dae" />
            </geometry>
        </collision>
        <visual>
            <origin rpy="0 0 0" xyz="0 0 0" />
            <geometry>
                <mesh filename="package://robotnik_sensors/meshes/sick_tim571.dae" />
            </geometry>
        </visual>
        <inertial>
            <mass value="0.25" />
            <origin rpy="0 0 0" xyz="-0.0017 0 0.042875" />
            <inertia ixx="0.00022818880208333336" ixy="0" ixz="0" iyy="0.0002307096354166667" iyz="0" izz="0.0001525208333333333" />
        </inertial>
    </link>
    <joint name="robot_rear_laser_joint" type="fixed">
        <origin rpy="0 0 0" xyz="0 0 0.06246" />
        <parent link="robot_rear_laser_base_link" />
        <child link="robot_rear_laser_link" />
    </joint>
    <link name="robot_rear_laser_link" />
    <gazebo reference="robot_rear_laser_link">
        <sensor name="robot_rear_laser_sensor" type="ray">
            <pose>0 0 0 0 0 0</pose>
            <visualize>false</visualize>
            <update_rate>15</update_rate>
            <ray>
                <scan>
                    <horizontal>
                        <samples>819</samples>
                        <resolution>1</resolution>
                        <min_angle>-2.36</min_angle>
                        <max_angle>2.36</max_angle>
                    </horizontal>
                </scan>
                <range>
                    <min>0.05</min>
                    <max>25.0</max>
                    <resolution>0.00575</resolution>
                </range>
                <noise>
                    <type>gaussian</type>
                    <mean>0.0</mean>
                    <stddev>0.01</stddev>
                </noise>
            </ray>
            <plugin filename="libgazebo_ros_laser.so" name="robot_rear_laser_controller">
                <topicName>rear_laser/scan</topicName>
                <frameName>/robot_rear_laser_link</frameName>
            </plugin>
        </sensor>
    </gazebo>
    <!--xacro:sensor_axis_m5013 prefix="$(arg prefix)front_ptz_camera" parent="$(arg prefix)base_link">
			<origin xyz="${front_ptz_camera_offset_x} ${front_ptz_camera_offset_y} ${front_ptz_camera_offset_z}" rpy="${-PI/2} 0 0"/>
		</xacro:sensor_axis_m5013-->
    <!--xacro:sensor_axis_m5013 prefix="$(arg prefix)rear_ptz_camera" parent="$(arg prefix)base_link">
			<origin xyz="${rear_ptz_camera_offset_x} ${rear_ptz_camera_offset_y} ${rear_ptz_camera_offset_z}" rpy="${-PI/2} 0 ${PI}"/>
		</xacro:sensor_axis_m5013-->
    <joint name="robot_front_rgbd_camera_joint" type="fixed">
        <origin rpy="0 0 0" xyz="0.3585 0.0 0.25062" />
        <parent link="robot_base_link" />
        <child link="robot_front_rgbd_camera_link" />
    </joint>
    <link name="robot_front_rgbd_camera_link">
        <visual>
            <origin rpy="0 0 0" xyz="0 0 0" />
            <geometry>
                <mesh filename="package://robotnik_sensors/meshes/orbbec_astra.dae" />
            </geometry>
        </visual>
        <collision>
            <geometry>
                <mesh filename="package://robotnik_sensors/meshes/orbbec_astra.dae" />
            </geometry>
        </collision>
        <inertial>
            <mass value="0.001" />
            <origin xyz="0.0 0.0 0.0" rpy="0 0 0" />
            <inertia ixx="2.3437500000000006e-06" ixy="0" ixz="0" iyy="2.0833333333333336e-07" iyz="0" izz="2.4020833333333336e-06" />
        </inertial>
    </link>
    <joint name="robot_front_rgbd_camera_rgb_joint" type="fixed">
        <origin rpy="0.0 0.0 0.0" xyz="0.0 0.0125 0.0150" />
        <parent link="robot_front_rgbd_camera_link" />
        <child link="robot_front_rgbd_camera_rgb_frame" />
    </joint>
    <link name="robot_front_rgbd_camera_rgb_frame">
        <inertial>
            <mass value="0.297" />
            <origin xyz="-0.02 -0.0125 0.0" />
            <inertia ixx="0.0006960937500000001" ixy="0" ixz="0" iyy="6.1875e-05" iyz="0" izz="0.00071341875" />
        </inertial>
    </link>
    <joint name="robot_front_rgbd_camera_rgb_optical_joint" type="fixed">
        <origin rpy="-1.5707963267948966 0 -1.5707963267948966" xyz="0.0 0.0 0.0" />
        <parent link="robot_front_rgbd_camera_rgb_frame" />
        <child link="robot_front_rgbd_camera_rgb_optical_frame" />
    </joint>
    <link name="robot_front_rgbd_camera_rgb_optical_frame">
        <inertial>
            <mass value="0.001" />
            <origin rpy="1.5707963267948966 0 1.5707963267948966" xyz="0 0 0" />
            <inertia ixx="2.3437500000000006e-06" ixy="0" ixz="0" iyy="2.0833333333333336e-07" iyz="0" izz="2.4020833333333336e-06" />
        </inertial>
    </link>
    <joint name="robot_front_rgbd_camera_depth_joint" type="fixed">
        <origin rpy="0 0 0" xyz="0.0 0.0375 0.0150" />
        <parent link="robot_front_rgbd_camera_link" />
        <child link="robot_front_rgbd_camera_depth_frame" />
    </joint>
    <link name="robot_front_rgbd_camera_depth_frame">
        <inertial>
            <mass value="0.001" />
            <origin xyz="0 0 0" />
            <inertia ixx="2.3437500000000006e-06" ixy="0" ixz="0" iyy="2.0833333333333336e-07" iyz="0" izz="2.4020833333333336e-06" />
        </inertial>
    </link>
    <joint name="robot_front_rgbd_camera_depth_optical_joint" type="fixed">
        <origin rpy="-1.5707963267948966 0 -1.5707963267948966" xyz="0 0 0" />
        <parent link="robot_front_rgbd_camera_depth_frame" />
        <child link="robot_front_rgbd_camera_depth_optical_frame" />
    </joint>
    <link name="robot_front_rgbd_camera_depth_optical_frame">
        <inertial>
            <mass value="0.001" />
            <origin xyz="0 0 0" />
            <inertia ixx="2.3437500000000006e-06" ixy="0" ixz="0" iyy="2.0833333333333336e-07" iyz="0" izz="2.4020833333333336e-06" />
        </inertial>
    </link>
    <gazebo reference="robot_front_rgbd_camera_link">
        <sensor name="robot_front_rgbd_camera_depth_sensor" type="depth">
            <always_on>true</always_on>
            <update_rate>20.0</update_rate>
            <camera>
                <horizontal_fov>1.0471975511965976</horizontal_fov>
                <image>
                    <format>R8G8B8</format>
                    <width>640</width>
                    <height>480</height>
                </image>
                <clip>
                    <near>0.05</near>
                    <far>3.5</far>
                </clip>
            </camera>
            <plugin filename="libgazebo_ros_openni_kinect.so" name="robot_front_rgbd_camera_controller">
                <cameraName>front_rgbd_camera</cameraName>
                <alwaysOn>true</alwaysOn>
                <updateRate>10</updateRate>
                <imageTopicName>rgb/image_raw</imageTopicName>
                <depthImageTopicName>depth/image_raw</depthImageTopicName>
                <pointCloudTopicName>depth/points</pointCloudTopicName>
                <cameraInfoTopicName>rgb/camera_info</cameraInfoTopicName>
                <depthImageCameraInfoTopicName>depth/camera_info</depthImageCameraInfoTopicName>
                <frameName>/robot_front_rgbd_camera_depth_optical_frame</frameName>
                <baseline>0.1</baseline>
                <distortion_k1>0.0</distortion_k1>
                <distortion_k2>0.0</distortion_k2>
                <distortion_k3>0.0</distortion_k3>
                <distortion_t1>0.0</distortion_t1>
                <distortion_t2>0.0</distortion_t2>
                <pointCloudCutoff>0.4</pointCloudCutoff>
            </plugin>
        </sensor>
    </gazebo>
    <!--xacro:sensor_gps prefix="$(arg prefix)gps" parent="$(arg prefix)base_link">
			<origin xyz="${gps_offset_x} ${gps_offset_y} ${gps_offset_z}" rpy="0 0 0"/>
		</xacro:sensor_gps-->
</robot>
